Workbook
Name PERFORMANCETASKS: #REF!
Name PT: #REF!
Name QA: #REF!
Name QUARTERLYASSESSMENT: #REF!
Name SUBJECTS: '[1]INPUT DATA'!$A$1002:$A$1005
Name Transmu_Table: #REF!
Name WRITTENWORKS: #REF!
Name WW: #REF!

Sheet INSTRUCTIONS
B3: Instructions: Accomplishing the Electronic Class Record (ECR) for SSHS
B7: 1 | C7: Input the correct data for the following sections. Any details entered here are used throughout the e-Class Record
C10: INPUT DATA
C12: A. | D12: SCHOOL INFO
D13: 1 | E13: REGION | I13: : | J13: Select the Region where the school is located
D14: 2 | E14: DIVISION | I14: : | J14: Input the respective Schools Division Office
D15: 3 | E15: SCHOOL ID | I15: : | J15: Enter the six (6) digit school ID
D16: 4 | E16: SCHOOL NAME | I16: : | J16: Enter the name of the school
D17: 5 | E17: SCHOOL YEAR | I17: : | J17: Enter the current school year
C19: B. | D19: TEACHER, GRADE LEVEL, AND SUBJECT AREA INFO
D20: 1 | E20: TEACHER | J20: Enter the name of teacher's name
D21: 2 | E21: GRADE LEVEL | J21: Input the grade level taught. This field only accepts 11 or 12.
D22: 3 | E22: SECTION NAME | J22: Enter section name.
D23: 4 | E23: SUBJECT TYPE | J23: Select the subject type.
D24: 5 | E24: SUBJECT | J24: The selection for the subjects is dependent on the subject type selected.
E25: 5.1 | F25: Other Elective and Special Curricular Program | J25: If applicable, select “Other Elective and Special Curricular Program”, then enter the new elective or subject in the field provided.
D28: As an additional guide, a note regarding where the computation of the final grade can be found will be displayed, depending on the selected subject type and grade level.
C32: C. | D32: LEARNERS' NAMES
D33: Either manually type learners' names or copy from SF1 and copy onto their respective column (Male or Female).
D37: TIP: Press Control + Shift + V to paste values only. | M37: shift ↑ | P37: Z | Q37: X | R37: C | S37: V
M39: ctrl
B43: 2 | C43: Input the raw scores per quarter to compute for the quarterly grades and the semestral or annual final grades.
C46: QUARTERLY GRADES
U54: Color fills are for visualization purposes only and do not represent the actual sheet layouts.
C55: INSTRUCTIONS | G55: DATA INPUT | I55: Q1 | J55: Q2 | K55: Q3 | L55: Q4 | M55: 1st SEMESTRAL GRADE | P55: 2nd SEMESTRAL GRADE | S55: QUARTERLY
D57: HIGHEST POSSIBLE SCORE | J57: Input the highest possible score for each grading component.
D58: ACTUAL SCORE | J58: For each learner, input the actual score accordingly.
D60: The INITIAL GRADE and QUARTERLY GRADE will be computed when all required grading components have been completed.
C64: ! | D64: The weights of the grading components differ depending on the selected Subject type.
K66: CORE | M66: Academic Electives | Q66: TechPro Electives
M67: All Other Electives | O67: Field Experience / Exposure Sports and Arts | Q67: All Other Electives | S67: Work Immersion
E68: WRITTEN WORK | K68: 0.25 | M68: 0.25 | O68: 0.2 | Q68: 0.15 | S68: 0.2
E69: PERFORMANCE TASK | K69: 0.5 | M69: 0.45 | O69: 0.6 | Q69: 0.65 | S69: 0.8
E70: QUARTERLY ASSESSMENT | K70: 0.25 | M70: 0.3 | O70: 0.2 | Q70: 0.2
K71: =SUM(K68:K70) -> 1 | M71: =SUM(M68:M70) -> 1 | O71: =SUM(O68:O70) -> 1 | Q71: =SUM(Q68:Q70) -> 1 | S71: =SUM(S68:S70) -> 1
B74: 3 | C74: Review final grades. The computation of final grades depends on the selected subject type and grade level.
C77: SUMMARY OF FINAL GRADES SHEETS
C79: Subject Type | H79: Duration | K79: Final Grade Computation | O79: Semester Grade | R79: Summary of Grades
C80: Core Subject (All Tracks) | H80: 4 quarters across 2 semesters | K80: Average of 4 quarterly grades | O80: Not Computed | R80: QUARTERLY AVERAGE
C82: Academic Electives (Grades 11 and 12) | H82: 2 quarters per semester | K82: Average of 2 quarterly grades | O82: Computed per semester | R82: 1st SEMESTRAL GRADE
...

Sheet INPUT DATA
D3: Input Data Sheet for Electronic-Class Record (ECR) for SSHS
B7: SCHOOL INFO | J7: LEARNERS' NAMES
C10: REGION | E10: : | K10: MALE | N10: FEMALE
C11: DIVISION | E11: : | K11: 1 | N11: 1
K12: 2 | N12: 2
C13: SCHOOL ID | E13: : | K13: 3 | N13: 3
C14: SCHOOL NAME | E14: : | K14: 4 | N14: 4
K15: 5 | N15: 5
C16: SCHOOL YEAR | E16: : | K16: 6 | N16: 6
K17: 7 | N17: 7
K18: 8 | N18: 8
B19: TEACHER, GRADE LEVEL, AND SUBJECT AREA INFO | K19: 9 | N19: 9
K20: 10 | N20: 10
K21: 11 | N21: 11
C22: TEACHER | E22: : | K22: 12 | N22: 12
K23: 13 | N23: 13
C24: GRADE LEVEL | E24: : | G24: ← Accepts 11 or 12 only. | K24: 14 | N24: 14
C25: SECTION NAME | E25: : | K25: 15 | N25: 15
C26: SUBJECT TYPE | E26: : | K26: 16 | N26: 16
K27: 17 | N27: 17
C28: SUBJECT | E28: : | K28: 18 | N28: 18
K29: 19 | N29: 19
C30: Other Elective & Special Curricular Program / Subject | E30: : | K30: 20 | N30: 20
K31: 21 | N31: 21
K32: 22 | N32: 22
C33: =_xlfn.IFNA("NOTE: Find the Final Grade Computation in the "&INDEX('Helper(IMPORTANT!)'!DE1:DF6, MATCH(F26,'Helper(IMPORTANT!)'!DD1:DD6, 0), MATCH(F24, 'Helper(IMPORTANT!)'!DE1:DF1, 0))&" sheet/s.","") | K33: 23 | N33: 23
K34: 24 | N34: 24
C35: =_xlfn.IFNA(IF(INDEX('Helper(IMPORTANT!)'!DE1:DF6, MATCH(F26,'Helper(IMPORTANT!)'!DD1:DD6, 0), MATCH(F24, 'Helper(IMPORTANT!)'!DE1:DF1, 0))="QUARTERLY AVERAGE","QUARTERLY AVERAGE","1st SEMESTRAL GRADE"),"") | G35: =_xlfn.IFNA(IF(INDEX('Helper(IMPORTANT!)'!DE1:DF6, MATCH(F26,'Helper(IMPORTANT!)'!DD1:DD6, 0), MATCH(F24, 'Helper(IMPORTANT!)'!DE1:DF1, 0))="QUARTERLY AVERAGE","QUARTERLY AVERAGE","2nd SEMESTRAL GRADE"),"") | K35: 25 | N35: 25
K36: 26 | N36: 26
K37: 27 | N37: 27
K38: 28 | N38: 28
K39: 29 | N39: 29
K40: 30 | N40: 30
K41: 31 | N41: 31
K42: 32 | N42: 32
K43: 33 | N43: 33
K44: 34 | N44: 34
K45: 35 | N45: 35
K46: 36 | N46: 36
K47: 37 | N47: 37
...

Sheet Q1
A1: Strengthened Senior High School Class Record
A3: (Pursuant to Deped Order 8 series of 2015)
F4: REGION | G4: ='INPUT DATA'!F10 -> 0 | L4: DIVISION | O4: ='INPUT DATA'!F11 -> 0
F5: SCHOOL NAME | G5: ='INPUT DATA'!F14 -> 0 | T5: SCHOOL ID | X5: ='INPUT DATA'!F13 -> 0 | AD5: SCHOOL YEAR | AG5: ='INPUT DATA'!F16 -> 0
A7: FIRST QUARTER | F7: GRADE & SECTION: | K7: ='INPUT DATA'!F24&" - "&'INPUT DATA'!F25 -> - | Q7: TEACHER: | S7: ='INPUT DATA'!F22 -> 0 | AC7: SUBJECT: | AE7: =IF('INPUT DATA'!F30<>"",'INPUT DATA'!F30,'INPUT DATA'!F28) -> 0
Q8: SEMESTER: | S8: - - | AC8: SUBJECT TYPE: | AE8: ='INPUT DATA'!F26 -> 0
A9: LEARNERS' NAMES | F9: =IF('INPUT DATA'!$F$26="","",INDEX('Helper(IMPORTANT!)'!$CI$2:$CI$6,MATCH(AE8,'Helper(IMPORTANT!)'!$CH$2:$CH$6,0))) | S9: =IF('INPUT DATA'!$F$26="","",INDEX('Helper(IMPORTANT!)'!$CJ$2:$CJ$6,MATCH(AE8,'Helper(IMPORTANT!)'!$CH$2:$CH$6,0))) | AF9: =IF('INPUT DATA'!$F$26="","",INDEX('Helper(IMPORTANT!)'!$CK$2:$CK$6,MATCH(AE8,'Helper(IMPORTANT!)'!$CH$2:$CH$6,0))) | AI9: Initial Grade | AJ9: Quarterly Grade
F10: 1 | G10: 2 | H10: 3 | I10: 4 | J10: 5 | K10: 6 | L10: 7 | M10: 8 | N10: 9 | O10: 10 | P10: Total | Q10: PS | R10: WS | S10: 1 | T10: 2 | U10: 3 | V10: 4 | W10: 5 | X10: 6 | Y10: 7 | Z10: 8 | AA10: 9 | AB10: 10 | AC10: Total | AD10: PS | AE10: WS | AF10: 1 | AG10: PS | AH10: WS
A11: HIGHEST POSSIBLE SCORE | P11: =IF(COUNT($F11:$O11)=0,"",SUM($F11:$O11)) | Q11: 100 | R11: =IF('INPUT DATA'!$F$26="","",INDEX('Helper(IMPORTANT!)'!$CL$2:$CL$6,MATCH(AE8,'Helper(IMPORTANT!)'!$CH$2:$CH$6,0))) | AC11: =IF(COUNT($S11:$AB11)=0,"",SUM($S11:$AB11)) | AD11: 100 | AE11: =IF('INPUT DATA'!$F$26="","",INDEX('Helper(IMPORTANT!)'!$CM$2:$CM$6,MATCH(AE8,'Helper(IMPORTANT!)'!$CH$2:$CH$6,0))) | AG11: 100 | AH11: =IF('INPUT DATA'!$F$26="","",INDEX('Helper(IMPORTANT!)'!$CN$2:$CN$6,MATCH(AE8,'Helper(IMPORTANT!)'!$CH$2:$CH$6,0)))
A12: MALE
A13: 1 | B13: ='INPUT DATA'!L11 -> 0 | P13: =IF(COUNT($F13:$O13)=0,"",SUM($F13:$O13)) | Q13: =IFERROR(IF(P13="","",ROUND(P13/$P$11*100,2)),"") | R13: =IFERROR(IF(Q13="","",ROUND(Q13*$R$11,2)),"") | AC13: =IF(COUNT($S13:$AB13)=0,"",SUM($S13:$AB13)) | AD13: =IFERROR(IF(AC13="","",ROUND(AC13/$AC$11*100,2)),"") | AE13: =IFERROR(IF(AD13="","",ROUND(AD13*$AE$11,2)),"") | AG13: =IFERROR(IF(AF13="","",ROUND(AF13/$AF$11*100,2)),"") | AH13: =IFERROR(IF(AG13="","",ROUND(AG13*$AH$11,2)),"") | AI13: =IFERROR(R13+AE13+AH13,"") | AJ13: =IFERROR(VLOOKUP(AI13,'Helper(IMPORTANT!)'!$CQ$1:$CR$41,2,TRUE),"")
A14: 2 | B14: ='INPUT DATA'!L12 -> 0 | P14: =IF(COUNT($F14:$O14)=0,"",SUM($F14:$O14)) | Q14: =IFERROR(IF(P14="","",ROUND(P14/$P$11*100,2)),"") | R14: =IFERROR(IF(Q14="","",ROUND(Q14*$R$11,2)),"") | AC14: =IF(COUNT($S14:$AB14)=0,"",SUM($S14:$AB14)) | AD14: =IFERROR(IF(AC14="","",ROUND(AC14/$AC$11*100,2)),"") | AE14: =IFERROR(IF(AD14="","",ROUND(AD14*$AE$11,2)),"") | AG14: =IFERROR(IF(AF14="","",ROUND(AF14/$AF$11*100,2)),"") | AH14: =IFERROR(IF(AG14="","",ROUND(AG14*$AH$11,2)),"") | AI14: =IFERROR(R14+AE14+AH14,"") | AJ14: =IFERROR(VLOOKUP(AI14,'Helper(IMPORTANT!)'!$CQ$1:$CR$41,2,TRUE),"")
A15: 3 | B15: ='INPUT DATA'!L13 -> 0 | P15: =IF(COUNT($F15:$O15)=0,"",SUM($F15:$O15)) | Q15: =IFERROR(IF(P15="","",ROUND(P15/$P$11*100,2)),"") | R15: =IFERROR(IF(Q15="","",ROUND(Q15*$R$11,2)),"") | AC15: =IF(COUNT($S15:$AB15)=0,"",SUM($S15:$AB15)) | AD15: =IFERROR(IF(AC15="","",ROUND(AC15/$AC$11*100,2)),"") | AE15: =IFERROR(IF(AD15="","",ROUND(AD15*$AE$11,2)),"") | AG15: =IFERROR(IF(AF15="","",ROUND(AF15/$AF$11*100,2)),"") | AH15: =IFERROR(IF(AG15="","",ROUND(AG15*$AH$11,2)),"") | AI15: =IFERROR(R15+AE15+AH15,"") | AJ15: =IFERROR(VLOOKUP(AI15,'Helper(IMPORTANT!)'!$CQ$1:$CR$41,2,TRUE),"")
A16: 4 | B16: ='INPUT DATA'!L14 -> 0 | P16: =IF(COUNT($F16:$O16)=0,"",SUM($F16:$O16)) | Q16: =IFERROR(IF(P16="","",ROUND(P16/$P$11*100,2)),"") | R16: =IFERROR(IF(Q16="","",ROUND(Q16*$R$11,2)),"") | AC16: =IF(COUNT($S16:$AB16)=0,"",SUM($S16:$AB16)) | AD16: =IFERROR(IF(AC16="","",ROUND(AC16/$AC$11*100,2)),"") | AE16: =IFERROR(IF(AD16="","",ROUND(AD16*$AE$11,2)),"") | AG16: =IFERROR(IF(AF16="","",ROUND(AF16/$AF$11*100,2)),"") | AH16: =IFERROR(IF(AG16="","",ROUND(AG16*$AH$11,2)),"") | AI16: =IFERROR(R16+AE16+AH16,"") | AJ16: =IFERROR(VLOOKUP(AI16,'Helper(IMPORTANT!)'!$CQ$1:$CR$41,2,TRUE),"")
A17: 5 | B17: ='INPUT DATA'!L15 -> 0 | P17: =IF(COUNT($F17:$O17)=0,"",SUM($F17:$O17)) | Q17: =IFERROR(IF(P17="","",ROUND(P17/$P$11*100,2)),"") | R17: =IFERROR(IF(Q17="","",ROUND(Q17*$R$11,2)),"") | AC17: =IF(COUNT($S17:$AB17)=0,"",SUM($S17:$AB17)) | AD17: =IFERROR(IF(AC17="","",ROUND(AC17/$AC$11*100,2)),"") | AE17: =IFERROR(IF(AD17="","",ROUND(AD17*$AE$11,2)),"") | AG17: =IFERROR(IF(AF17="","",ROUND(AF17/$AF$11*100,2)),"") | AH17: =IFERROR(IF(AG17="","",ROUND(AG17*$AH$11,2)),"") | AI17: =IFERROR(R17+AE17+AH17,"") | AJ17: =IFERROR(VLOOKUP(AI17,'Helper(IMPORTANT!)'!$CQ$1:$CR$41,2,TRUE),"")
A18: 6 | B18: ='INPUT DATA'!L16 -> 0 | P18: =IF(COUNT($F18:$O18)=0,"",SUM($F18:$O18)) | Q18: =IFERROR(IF(P18="","",ROUND(P18/$P$11*100,2)),"") | R18: =IFERROR(IF(Q18="","",ROUND(Q18*$R$11,2)),"") | AC18: =IF(COUNT($S18:$AB18)=0,"",SUM($S18:$AB18)) | AD18: =IFERROR(IF(AC18="","",ROUND(AC18/$AC$11*100,2)),"") | AE18: =IFERROR(IF(AD18="","",ROUND(AD18*$AE$11,2)),"") | AG18: =IFERROR(IF(AF18="","",ROUND(AF18/$AF$11*100,2)),"") | AH18: =IFERROR(IF(AG18="","",ROUND(AG18*$AH$11,2)),"") | AI18: =IFERROR(R18+AE18+AH18,"") | AJ18: =IFERROR(VLOOKUP(AI18,'Helper(IMPORTANT!)'!$CQ$1:$CR$41,2,TRUE),"")
A19: 7 | B19: ='INPUT DATA'!L17 -> 0 | P19: =IF(COUNT($F19:$O19)=0,"",SUM($F19:$O19)) | Q19: =IFERROR(IF(P19="","",ROUND(P19/$P$11*100,2)),"") | R19: =IFERROR(IF(Q19="","",ROUND(Q19*$R$11,2)),"") | AC19: =IF(COUNT($S19:$AB19)=0,"",SUM($S19:$AB19)) | AD19: =IFERROR(IF(AC19="","",ROUND(AC19/$AC$11*100,2)),"") | AE19: =IFERROR(IF(AD19="","",ROUND(AD19*$AE$11,2)),"") | AG19: =IFERROR(IF(AF19="","",ROUND(AF19/$AF$11*100,2)),"") | AH19: =IFERROR(IF(AG19="","",ROUND(AG19*$AH$11,2)),"") | AI19: =IFERROR(R19+AE19+AH19,"") | AJ19: =IFERROR(VLOOKUP(AI19,'Helper(IMPORTANT!)'!$CQ$1:$CR$41,2,TRUE),"")
A20: 8 | B20: ='INPUT DATA'!L18 -> 0 | P20: =IF(COUNT($F20:$O20)=0,"",SUM($F20:$O20)) | Q20: =IFERROR(IF(P20="","",ROUND(P20/$P$11*100,2)),"") | R20: =IFERROR(IF(Q20="","",ROUND(Q20*$R$11,2)),"") | AC20: =IF(COUNT($S20:$AB20)=0,"",SUM($S20:$AB20)) | AD20: =IFERROR(IF(AC20="","",ROUND(AC20/$AC$11*100,2)),"") | AE20: =IFERROR(IF(AD20="","",ROUND(AD20*$AE$11,2)),"") | AG20: =IFERROR(IF(AF20="","",ROUND(AF20/$AF$11*100,2)),"") | AH20: =IFERROR(IF(AG20="","",ROUND(AG20*$AH$11,2)),"") | AI20: =IFERROR(R20+AE20+AH20,"") | AJ20: =IFERROR(VLOOKUP(AI20,'Helper(IMPORTANT!)'!$CQ$1:$CR$41,2,TRUE),"")
A21: 9 | B21: ='INPUT DATA'!L19 -> 0 | P21: =IF(COUNT($F21:$O21)=0,"",SUM($F21:$O21)) | Q21: =IFERROR(IF(P21="","",ROUND(P21/$P$11*100,2)),"") | R21: =IFERROR(IF(Q21="","",ROUND(Q21*$R$11,2)),"") | AC21: =IF(COUNT($S21:$AB21)=0,"",SUM($S21:$AB21)) | AD21: =IFERROR(IF(AC21="","",ROUND(AC21/$AC$11*100,2)),"") | AE21: =IFERROR(IF(AD21="","",ROUND(AD21*$AE$11,2)),"") | AG21: =IFERROR(IF(AF21="","",ROUND(AF21/$AF$11*100,2)),"") | AH21: =IFERROR(IF(AG21="","",ROUND(AG21*$AH$11,2)),"") | AI21: =IFERROR(R21+AE21+AH21,"") | AJ21: =IFERROR(VLOOKUP(AI21,'Helper(IMPORTANT!)'!$CQ$1:$CR$41,2,TRUE),"")
A22: 10 | B22: ='INPUT DATA'!L20 -> 0 | P22: =IF(COUNT($F22:$O22)=0,"",SUM($F22:$O22)) | Q22: =IFERROR(IF(P22="","",ROUND(P22/$P$11*100,2)),"") | R22: =IFERROR(IF(Q22="","",ROUND(Q22*$R$11,2)),"") | AC22: =IF(COUNT($S22:$AB22)=0,"",SUM($S22:$AB22)) | AD22: =IFERROR(IF(AC22="","",ROUND(AC22/$AC$11*100,2)),"") | AE22: =IFERROR(IF(AD22="","",ROUND(AD22*$AE$11,2)),"") | AG22: =IFERROR(IF(AF22="","",ROUND(AF22/$AF$11*100,2)),"") | AH22: =IFERROR(IF(AG22="","",ROUND(AG22*$AH$11,2)),"") | AI22: =IFERROR(R22+AE22+AH22,"") | AJ22: =IFERROR(VLOOKUP(AI22,'Helper(IMPORTANT!)'!$CQ$1:$CR$41,2,TRUE),"")
A23: 11 | B23: ='INPUT DATA'!L21 -> 0 | P23: =IF(COUNT($F23:$O23)=0,"",SUM($F23:$O23)) | Q23: =IFERROR(IF(P23="","",ROUND(P23/$P$11*100,2)),"") | R23: =IFERROR(IF(Q23="","",ROUND(Q23*$R$11,2)),"") | AC23: =IF(COUNT($S23:$AB23)=0,"",SUM($S23:$AB23)) | AD23: =IFERROR(IF(AC23="","",ROUND(AC23/$AC$11*100,2)),"") | AE23: =IFERROR(IF(AD23="","",ROUND(AD23*$AE$11,2)),"") | AG23: =IFERROR(IF(AF23="","",ROUND(AF23/$AF$11*100,2)),"") | AH23: =IFERROR(IF(AG23="","",ROUND(AG23*$AH$11,2)),"") | AI23: =IFERROR(R23+AE23+AH23,"") | AJ23: =IFERROR(VLOOKUP(AI23,'Helper(IMPORTANT!)'!$CQ$1:$CR$41,2,TRUE),"")
A24: 12 | B24: ='INPUT DATA'!L22 -> 0 | P24: =IF(COUNT($F24:$O24)=0,"",SUM($F24:$O24)) | Q24: =IFERROR(IF(P24="","",ROUND(P24/$P$11*100,2)),"") | R24: =IFERROR(IF(Q24="","",ROUND(Q24*$R$11,2)),"") | AC24: =IF(COUNT($S24:$AB24)=0,"",SUM($S24:$AB24)) | AD24: =IFERROR(IF(AC24="","",ROUND(AC24/$AC$11*100,2)),"") | AE24: =IFERROR(IF(AD24="","",ROUND(AD24*$AE$11,2)),"") | AG24: =IFERROR(IF(AF24="","",ROUND(AF24/$AF$11*100,2)),"") | AH24: =IFERROR(IF(AG24="","",ROUND(AG24*$AH$11,2)),"") | AI24: =IFERROR(R24+AE24+AH24,"") | AJ24: =IFERROR(VLOOKUP(AI24,'Helper(IMPORTANT!)'!$CQ$1:$CR$41,2,TRUE),"")
... A62: 50 | B62: ='INPUT DATA'!L60 -> 0 | P62: =IF(COUNT($F62:$O62)=0,"",SUM($F62:$O62)) | Q62: =IFERROR(IF(P62="","",ROUND(P62/$P$11*100,2)),"") | R62: =IFERROR(IF(Q62="","",ROUND(Q62*$R$11,2)),"") | AC62: =IF(COUNT($S62:$AB62)=0,"",SUM($S62:$AB62)) | AD62: =IFERROR(IF(AC62="","",ROUND(AC62/$AC$11*100,2)),"") | AE62: =IFERROR(IF(AD62="","",ROUND(AD62*$AE$11,2)),"") | AG62: =IFERROR(IF(AF62="","",ROUND(AF62/$AF$11*100,2)),"") | AH62: =IFERROR(IF(AG62="","",ROUND(AG62*$AH$11,2)),"") | AI62: =IFERROR(R62+AE62+AH62,"") | AJ62: =IFERROR(VLOOKUP(AI62,'Helper(IMPORTANT!)'!$CQ$1:$CR$41,2,TRUE),"")
A63: FEMALE
A64: 1 | B64: ='INPUT DATA'!O11 -> 0 | P64: =IF(COUNT($F64:$O64)=0,"",SUM($F64:$O64)) | Q64: =IFERROR(IF(P64="","",ROUND(P64/$P$11*100,2)),"") | R64: =IFERROR(IF(Q64="","",ROUND(Q64*$R$11,2)),"") | AC64: =IF(COUNT($S64:$AB64)=0,"",SUM($S64:$AB64)) | AD64: =IFERROR(IF(AC64="","",ROUND(AC64/$AC$11*100,2)),"") | AE64: =IFERROR(IF(AD64="","",ROUND(AD64*$AE$11,2)),"") | AG64: =IFERROR(IF(AF64="","",ROUND(AF64/$AF$11*100,2)),"") | AH64: =IFERROR(IF(AG64="","",ROUND(AG64*$AH$11,2)),"") | AI64: =IFERROR(R64+AE64+AH64,"") | AJ64: =IFERROR(VLOOKUP(AI64,'Helper(IMPORTANT!)'!$CQ$1:$CR$41,2,TRUE),"")
A65: 2 | B65: ='INPUT DATA'!O12 -> 0 | P65: =IF(COUNT($F65:$O65)=0,"",SUM($F65:$O65)) | Q65: =IFERROR(IF(P65="","",ROUND(P65/$P$11*100,2)),"") | R65: =IFERROR(IF(Q65="","",ROUND(Q65*$R$11,2)),"") | AC65: =IF(COUNT($S65:$AB65)=0,"",SUM($S65:$AB65)) | AD65: =IFERROR(IF(AC65="","",ROUND(AC65/$AC$11*100,2)),"") | AE65: =IFERROR(IF(AD65="","",ROUND(AD65*$AE$11,2)),"") | AG65: =IFERROR(IF(AF65="","",ROUND(AF65/$AF$11*100,2)),"") | AH65: =IFERROR(IF(AG65="","",ROUND(AG65*$AH$11,2)),"") | AI65: =IFERROR(R65+AE65+AH65,"") | AJ65: =IFERROR(VLOOKUP(AI65,'Helper(IMPORTANT!)'!$CQ$1:$CR$41,2,TRUE),"")
A66: 3 | B66: ='INPUT DATA'!O13 -> 0 | P66: =IF(COUNT($F66:$O66)=0,"",SUM($F66:$O66)) | Q66: =IFERROR(IF(P66="","",ROUND(P66/$P$11*100,2)),"") | R66: =IFERROR(IF(Q66="","",ROUND(Q66*$R$11,2)),"") | AC66: =IF(COUNT($S66:$AB66)=0,"",SUM($S66:$AB66)) | AD66: =IFERROR(IF(AC66="","",ROUND(AC66/$AC$11*100,2)),"") | AE66: =IFERROR(IF(AD66="","",ROUND(AD66*$AE$11,2)),"") | AG66: =IFERROR(IF(AF66="","",ROUND(AF66/$AF$11*100,2)),"") | AH66: =IFERROR(IF(AG66="","",ROUND(AG66*$AH$11,2)),"") | AI66: =IFERROR(R66+AE66+AH66,"") | AJ66: =IFERROR(VLOOKUP(AI66,'Helper(IMPORTANT!)'!$CQ$1:$CR$41,2,TRUE),"")
A67: 4 | B67: ='INPUT DATA'!O14 -> 0 | P67: =IF(COUNT($F67:$O67)=0,"",SUM($F67:$O67)) | Q67: =IFERROR(IF(P67="","",ROUND(P67/$P$11*100,2)),"") | R67: =IFERROR(IF(Q67="","",ROUND(Q67*$R$11,2)),"") | AC67: =IF(COUNT($S67:$AB67)=0,"",SUM($S67:$AB67)) | AD67: =IFERROR(IF(AC67="","",ROUND(AC67/$AC$11*100,2)),"") | AE67: =IFERROR(IF(AD67="","",ROUND(AD67*$AE$11,2)),"") | AG67: =IFERROR(IF(AF67="","",ROUND(AF67/$AF$11*100,2)),"") | AH67: =IFERROR(IF(AG67="","",ROUND(AG67*$AH$11,2)),"") | AI67: =IFERROR(R67+AE67+AH67,"") | AJ67: =IFERROR(VLOOKUP(AI67,'Helper(IMPORTANT!)'!$CQ$1:$CR$41,2,TRUE),"")
A68: 5 | B68: ='INPUT DATA'!O15 -> 0 | P68: =IF(COUNT($F68:$O68)=0,"",SUM($F68:$O68)) | Q68: =IFERROR(IF(P68="","",ROUND(P68/$P$11*100,2)),"") | R68: =IFERROR(IF(Q68="","",ROUND(Q68*$R$11,2)),"") | AC68: =IF(COUNT($S68:$AB68)=0,"",SUM($S68:$AB68)) | AD68: =IFERROR(IF(AC68="","",ROUND(AC68/$AC$11*100,2)),"") | AE68: =IFERROR(IF(AD68="","",ROUND(AD68*$AE$11,2)),"") | AG68: =IFERROR(IF(AF68="","",ROUND(AF68/$AF$11*100,2)),"") | AH68: =IFERROR(IF(AG68="","",ROUND(AG68*$AH$11,2)),"") | AI68: =IFERROR(R68+AE68+AH68,"") | AJ68: =IFERROR(VLOOKUP(AI68,'Helper(IMPORTANT!)'!$CQ$1:$CR$41,2,TRUE),"")
A69: 6 | B69: ='INPUT DATA'!O16 -> 0 | P69: =IF(COUNT($F69:$O69)=0,"",SUM($F69:$O69)) | Q69: =IFERROR(IF(P69="","",ROUND(P69/$P$11*100,2)),"") | R69: =IFERROR(IF(Q69="","",ROUND(Q69*$R$11,2)),"") | AC69: =IF(COUNT($S69:$AB69)=0,"",SUM($S69:$AB69)) | AD69: =IFERROR(IF(AC69="","",ROUND(AC69/$AC$11*100,2)),"") | AE69: =IFERROR(IF(AD69="","",ROUND(AD69*$AE$11,2)),"") | AG69: =IFERROR(IF(AF69="","",ROUND(AF69/$AF$11*100,2)),"") | AH69: =IFERROR(IF(AG69="","",ROUND(AG69*$AH$11,2)),"") | AI69: =IFERROR(R69+AE69+AH69,"") | AJ69: =IFERROR(VLOOKUP(AI69,'Helper(IMPORTANT!)'!$CQ$1:$CR$41,2,TRUE),"")
A70: 7 | B70: ='INPUT DATA'!O17 -> 0 | P70: =IF(COUNT($F70:$O70)=0,"",SUM($F70:$O70)) | Q70: =IFERROR(IF(P70="","",ROUND(P70/$P$11*100,2)),"") | R70: =IFERROR(IF(Q70="","",ROUND(Q70*$R$11,2)),"") | AC70: =IF(COUNT($S70:$AB70)=0,"",SUM($S70:$AB70)) | AD70: =IFERROR(IF(AC70="","",ROUND(AC70/$AC$11*100,2)),"") | AE70: =IFERROR(IF(AD70="","",ROUND(AD70*$AE$11,2)),"") | AG70: =IFERROR(IF(AF70="","",ROUND(AF70/$AF$11*100,2)),"") | AH70: =IFERROR(IF(AG70="","",ROUND(AG70*$AH$11,2)),"") | AI70: =IFERROR(R70+AE70+AH70,"") | AJ70: =IFERROR(VLOOKUP(AI70,'Helper(IMPORTANT!)'!$CQ$1:$CR$41,2,TRUE),"")
A71: 8 | B71: ='INPUT DATA'!O18 -> 0 | P71: =IF(COUNT($F71:$O71)=0,"",SUM($F71:$O71)) | Q71: =IFERROR(IF(P71="","",ROUND(P71/$P$11*100,2)),"") | R71: =IFERROR(IF(Q71="","",ROUND(Q71*$R$11,2)),"") | AC71: =IF(COUNT($S71:$AB71)=0,"",SUM($S71:$AB71)) | AD71: =IFERROR(IF(AC71="","",ROUND(AC71/$AC$11*100,2)),"") | AE71: =IFERROR(IF(AD71="","",ROUND(AD71*$AE$11,2)),"") | AG71: =IFERROR(IF(AF71="","",ROUND(AF71/$AF$11*100,2)),"") | AH71: =IFERROR(IF(AG71="","",ROUND(AG71*$AH$11,2)),"") | AI71: =IFERROR(R71+AE71+AH71,"") | AJ71: =IFERROR(VLOOKUP(AI71,'Helper(IMPORTANT!)'!$CQ$1:$CR$41,2,TRUE),"")
A72: 9 | B72: ='INPUT DATA'!O19 -> 0 | P72: =IF(COUNT($F72:$O72)=0,"",SUM($F72:$O72)) | Q72: =IFERROR(IF(P72="","",ROUND(P72/$P$11*100,2)),"") | R72: =IFERROR(IF(Q72="","",ROUND(Q72*$R$11,2)),"") | AC72: =IF(COUNT($S72:$AB72)=0,"",SUM($S72:$AB72)) | AD72: =IFERROR(IF(AC72="","",ROUND(AC72/$AC$11*100,2)),"") | AE72: =IFERROR(IF(AD72="","",ROUND(AD72*$AE$11,2)),"") | AG72: =IFERROR(IF(AF72="","",ROUND(AF72/$AF$11*100,2)),"") | AH72: =IFERROR(IF(AG72="","",ROUND(AG72*$AH$11,2)),"") | AI72: =IFERROR(R72+AE72+AH72,"") | AJ72: =IFERROR(VLOOKUP(AI72,'Helper(IMPORTANT!)'!$CQ$1:$CR$41,2,TRUE),"")
A73: 10 | B73: ='INPUT DATA'!O20 -> 0 | P73: =IF(COUNT($F73:$O73)=0,"",SUM($F73:$O73)) | Q73: =IFERROR(IF(P73="","",ROUND(P73/$P$11*100,2)),"") | R73: =IFERROR(IF(Q73="","",ROUND(Q73*$R$11,2)),"") | AC73: =IF(COUNT($S73:$AB73)=0,"",SUM($S73:$AB73)) | AD73: =IFERROR(IF(AC73="","",ROUND(AC73/$AC$11*100,2)),"") | AE73: =IFERROR(IF(AD73="","",ROUND(AD73*$AE$11,2)),"") | AG73: =IFERROR(IF(AF73="","",ROUND(AF73/$AF$11*100,2)),"") | AH73: =IFERROR(IF(AG73="","",ROUND(AG73*$AH$11,2)),"") | AI73: =IFERROR(R73+AE73+AH73,"") | AJ73: =IFERROR(VLOOKUP(AI73,'Helper(IMPORTANT!)'!$CQ$1:$CR$41,2,TRUE),"")
A74: 11 | B74: ='INPUT DATA'!O21 -> 0 | P74: =IF(COUNT($F74:$O74)=0,"",SUM($F74:$O74)) | Q74: =IFERROR(IF(P74="","",ROUND(P74/$P$11*100,2)),"") | R74: =IFERROR(IF(Q74="","",ROUND(Q74*$R$11,2)),"") | AC74: =IF(COUNT($S74:$AB74)=0,"",SUM($S74:$AB74)) | AD74: =IFERROR(IF(AC74="","",ROUND(AC74/$AC$11*100,2)),"") | AE74: =IFERROR(IF(AD74="","",ROUND(AD74*$AE$11,2)),"") | AG74: =IFERROR(IF(AF74="","",ROUND(AF74/$AF$11*100,2)),"") | AH74: =IFERROR(IF(AG74="","",ROUND(AG74*$AH$11,2)),"") | AI74: =IFERROR(R74+AE74+AH74,"") | AJ74: =IFERROR(VLOOKUP(AI74,'Helper(IMPORTANT!)'!$CQ$1:$CR$41,2,TRUE),"")
A75: 12 | B75: ='INPUT DATA'!O22 -> 0 | P75: =IF(COUNT($F75:$O75)=0,"",SUM($F75:$O75)) | Q75: =IFERROR(IF(P75="","",ROUND(P75/$P$11*100,2)),"") | R75: =IFERROR(IF(Q75="","",ROUND(Q75*$R$11,2)),"") | AC75: =IF(COUNT($S75:$AB75)=0,"",SUM($S75:$AB75)) | AD75: =IFERROR(IF(AC75="","",ROUND(AC75/$AC$11*100,2)),"") | AE75: =IFERROR(IF(AD75="","",ROUND(AD75*$AE$11,2)),"") | AG75: =IFERROR(IF(AF75="","",ROUND(AF75/$AF$11*100,2)),"") | AH75: =IFERROR(IF(AG75="","",ROUND(AG75*$AH$11,2)),"") | AI75: =IFERROR(R75+AE75+AH75,"") | AJ75: =IFERROR(VLOOKUP(AI75,'Helper(IMPORTANT!)'!$CQ$1:$CR$41,2,TRUE),"")
... A113: 50 | B113: ='INPUT DATA'!O60 -> 0 | P113: =IF(COUNT($F113:$O113)=0,"",SUM($F113:$O113)) | Q113: =IFERROR(IF(P113="","",ROUND(P113/$P$11*100,2)),"") | R113: =IFERROR(IF(Q113="","",ROUND(Q113*$R$11,2)),"") | AC113: =IF(COUNT($S113:$AB113)=0,"",SUM($S113:$AB113)) | AD113: =IFERROR(IF(AC113="","",ROUND(AC113/$AC$11*100,2)),"") | AE113: =IFERROR(IF(AD113="","",ROUND(AD113*$AE$11,2)),"") | AG113: =IFERROR(IF(AF113="","",ROUND(AF113/$AF$11*100,2)),"") | AH113: =IFERROR(IF(AG113="","",ROUND(AG113*$AH$11,2)),"") | AI113: =IFERROR(R113+AE113+AH113,"") | AJ113: =IFERROR(VLOOKUP(AI113,'Helper(IMPORTANT!)'!$CQ$1:$CR$41,2,TRUE),"")

Sheet Q2
A1: Strengthened Senior High School Class Record
A3: (Pursuant to Deped Order 8 series of 2015)
F4: REGION | G4: ='INPUT DATA'!F10 -> 0 | L4: DIVISION | O4: ='INPUT DATA'!F11 -> 0
F5: SCHOOL NAME | G5: ='INPUT DATA'!F14 -> 0 | T5: SCHOOL ID | X5: ='INPUT DATA'!F13 -> 0 | AD5: SCHOOL YEAR | AG5: ='INPUT DATA'!F16 -> 0
A7: SECOND QUARTER | F7: GRADE & SECTION: | K7: ='INPUT DATA'!F24&" - "&'INPUT DATA'!F25 -> - | Q7: TEACHER: | S7: ='INPUT DATA'!F22 -> 0 | AC7: SUBJECT: | AE7: =IF('INPUT DATA'!F30<>"",'INPUT DATA'!F30,'INPUT DATA'!F28) -> 0
Q8: SEMESTER: | S8: - - | AC8: SUBJECT TYPE: | AE8: ='INPUT DATA'!F26 -> 0
A9: LEARNERS' NAMES | F9: =IF('INPUT DATA'!$F$26="","",INDEX('Helper(IMPORTANT!)'!$CI$2:$CI$6,MATCH(AE8,'Helper(IMPORTANT!)'!$CH$2:$CH$6,0))) | S9: =IF('INPUT DATA'!$F$26="","",INDEX('Helper(IMPORTANT!)'!$CJ$2:$CJ$6,MATCH(AE8,'Helper(IMPORTANT!)'!$CH$2:$CH$6,0))) | AF9: =IF('INPUT DATA'!$F$26="","",INDEX('Helper(IMPORTANT!)'!$CK$2:$CK$6,MATCH(AE8,'Helper(IMPORTANT!)'!$CH$2:$CH$6,0))) | AI9: Initial Grade | AJ9: Quarterly Grade
F10: 1 | G10: 2 | H10: 3 | I10: 4 | J10: 5 | K10: 6 | L10: 7 | M10: 8 | N10: 9 | O10: 10 | P10: Total | Q10: PS | R10: WS | S10: 1 | T10: 2 | U10: 3 | V10: 4 | W10: 5 | X10: 6 | Y10: 7 | Z10: 8 | AA10: 9 | AB10: 10 | AC10: Total | AD10: PS | AE10: WS | AF10: 1 | AG10: PS | AH10: WS
A11: HIGHEST POSSIBLE SCORE | P11: =IF(COUNT($F11:$O11)=0,"",SUM($F11:$O11)) | Q11: 100 | R11: =IF('INPUT DATA'!$F$26="","",INDEX('Helper(IMPORTANT!)'!$CL$2:$CL$6,MATCH(AE8,'Helper(IMPORTANT!)'!$CH$2:$CH$6,0))) | AC11: =IF(COUNT($S11:$AB11)=0,"",SUM($S11:$AB11)) | AD11: 100 | AE11: =IF('INPUT DATA'!$F$26="","",INDEX('Helper(IMPORTANT!)'!$CM$2:$CM$6,MATCH(AE8,'Helper(IMPORTANT!)'!$CH$2:$CH$6,0))) | AG11: 100 | AH11: =IF('INPUT DATA'!$F$26="","",INDEX('Helper(IMPORTANT!)'!$CN$2:$CN$6,MATCH(AE8,'Helper(IMPORTANT!)'!$CH$2:$CH$6,0)))
A12: MALE
A13: 1 | B13: ='INPUT DATA'!L11 -> 0 | P13: =IF(COUNT($F13:$O13)=0,"",SUM($F13:$O13)) | Q13: =IFERROR(IF(P13="","",ROUND(P13/$P$11*100,2)),"") | R13: =IFERROR(IF(Q13="","",ROUND(Q13*$R$11,2)),"") | AC13: =IF(COUNT($S13:$AB13)=0,"",SUM($S13:$AB13)) | AD13: =IFERROR(IF(AC13="","",ROUND(AC13/$AC$11*100,2)),"") | AE13: =IFERROR(IF(AD13="","",ROUND(AD13*$AE$11,2)),"") | AG13: =IFERROR(IF(AF13="","",ROUND(AF13/$AF$11*100,2)),"") | AH13: =IFERROR(IF(AG13="","",ROUND(AG13*$AH$11,2)),"") | AI13: =IFERROR(R13+AE13+AH13,"") | AJ13: =IFERROR(VLOOKUP(AI13,'Helper(IMPORTANT!)'!$CQ$1:$CR$41,2,TRUE),"")
A14: 2 | B14: ='INPUT DATA'!L12 -> 0 | P14: =IF(COUNT($F14:$O14)=0,"",SUM($F14:$O14)) | Q14: =IFERROR(IF(P14="","",ROUND(P14/$P$11*100,2)),"") | R14: =IFERROR(IF(Q14="","",ROUND(Q14*$R$11,2)),"") | AC14: =IF(COUNT($S14:$AB14)=0,"",SUM($S14:$AB14)) | AD14: =IFERROR(IF(AC14="","",ROUND(AC14/$AC$11*100,2)),"") | AE14: =IFERROR(IF(AD14="","",ROUND(AD14*$AE$11,2)),"") | AG14: =IFERROR(IF(AF14="","",ROUND(AF14/$AF$11*100,2)),"") | AH14: =IFERROR(IF(AG14="","",ROUND(AG14*$AH$11,2)),"") | AI14: =IFERROR(R14+AE14+AH14,"") | AJ14: =IFERROR(VLOOKUP(AI14,'Helper(IMPORTANT!)'!$CQ$1:$CR$41,2,TRUE),"")
A15: 3 | B15: ='INPUT DATA'!L13 -> 0 | P15: =IF(COUNT($F15:$O15)=0,"",SUM($F15:$O15)) | Q15: =IFERROR(IF(P15="","",ROUND(P15/$P$11*100,2)),"") | R15: =IFERROR(IF(Q15="","",ROUND(Q15*$R$11,2)),"") | AC15: =IF(COUNT($S15:$AB15)=0,"",SUM($S15:$AB15)) | AD15: =IFERROR(IF(AC15="","",ROUND(AC15/$AC$11*100,2)),"") | AE15: =IFERROR(IF(AD15="","",ROUND(AD15*$AE$11,2)),"") | AG15: =IFERROR(IF(AF15="","",ROUND(AF15/$AF$11*100,2)),"") | AH15: =IFERROR(IF(AG15="","",ROUND(AG15*$AH$11,2)),"") | AI15: =IFERROR(R15+AE15+AH15,"") | AJ15: =IFERROR(VLOOKUP(AI15,'Helper(IMPORTANT!)'!$CQ$1:$CR$41,2,TRUE),"")
A16: 4 | B16: ='INPUT DATA'!L14 -> 0 | P16: =IF(COUNT($F16:$O16)=0,"",SUM($F16:$O16)) | Q16: =IFERROR(IF(P16="","",ROUND(P16/$P$11*100,2)),"") | R16: =IFERROR(IF(Q16="","",ROUND(Q16*$R$11,2)),"") | AC16: =IF(COUNT($S16:$AB16)=0,"",SUM($S16:$AB16)) | AD16: =IFERROR(IF(AC16="","",ROUND(AC16/$AC$11*100,2)),"") | AE16: =IFERROR(IF(AD16="","",ROUND(AD16*$AE$11,2)),"") | AG16: =IFERROR(IF(AF16="","",ROUND(AF16/$AF$11*100,2)),"") | AH16: =IFERROR(IF(AG16="","",ROUND(AG16*$AH$11,2)),"") | AI16: =IFERROR(R16+AE16+AH16,"") | AJ16: =IFERROR(VLOOKUP(AI16,'Helper(IMPORTANT!)'!$CQ$1:$CR$41,2,TRUE),"")
A17: 5 | B17: ='INPUT DATA'!L15 -> 0 | P17: =IF(COUNT($F17:$O17)=0,"",SUM($F17:$O17)) | Q17: =IFERROR(IF(P17="","",ROUND(P17/$P$11*100,2)),"") | R17: =IFERROR(IF(Q17="","",ROUND(Q17*$R$11,2)),"") | AC17: =IF(COUNT($S17:$AB17)=0,"",SUM($S17:$AB17)) | AD17: =IFERROR(IF(AC17="","",ROUND(AC17/$AC$11*100,2)),"") | AE17: =IFERROR(IF(AD17="","",ROUND(AD17*$AE$11,2)),"") | AG17: =IFERROR(IF(AF17="","",ROUND(AF17/$AF$11*100,2)),"") | AH17: =IFERROR(IF(AG17="","",ROUND(AG17*$AH$11,2)),"") | AI17: =IFERROR(R17+AE17+AH17,"") | AJ17: =IFERROR(VLOOKUP(AI17,'Helper(IMPORTANT!)'!$CQ$1:$CR$41,2,TRUE),"")
A18: 6 | B18: ='INPUT DATA'!L16 -> 0 | P18: =IF(COUNT($F18:$O18)=0,"",SUM($F18:$O18)) | Q18: =IFERROR(IF(P18="","",ROUND(P18/$P$11*100,2)),"") | R18: =IFERROR(IF(Q18="","",ROUND(Q18*$R$11,2)),"") | AC18: =IF(COUNT($S18:$AB18)=0,"",SUM($S18:$AB18)) | AD18: =IFERROR(IF(AC18="","",ROUND(AC18/$AC$11*100,2)),"") | AE18: =IFERROR(IF(AD18="","",ROUND(AD18*$AE$11,2)),"") | AG18: =IFERROR(IF(AF18="","",ROUND(AF18/$AF$11*100,2)),"") | AH18: =IFERROR(IF(AG18="","",ROUND(AG18*$AH$11,2)),"") | AI18: =IFERROR(R18+AE18+AH18,"") | AJ18: =IFERROR(VLOOKUP(AI18,'Helper(IMPORTANT!)'!$CQ$1:$CR$41,2,TRUE),"")
A19: 7 | B19: ='INPUT DATA'!L17 -> 0 | P19: =IF(COUNT($F19:$O19)=0,"",SUM($F19:$O19)) | Q19: =IFERROR(IF(P19="","",ROUND(P19/$P$11*100,2)),"") | R19: =IFERROR(IF(Q19="","",ROUND(Q19*$R$11,2)),"") | AC19: =IF(COUNT($S19:$AB19)=0,"",SUM($S19:$AB19)) | AD19: =IFERROR(IF(AC19="","",ROUND(AC19/$AC$11*100,2)),"") | AE19: =IFERROR(IF(AD19="","",ROUND(AD19*$AE$11,2)),"") | AG19: =IFERROR(IF(AF19="","",ROUND(AF19/$AF$11*100,2)),"") | AH19: =IFERROR(IF(AG19="","",ROUND(AG19*$AH$11,2)),"") | AI19: =IFERROR(R19+AE19+AH19,"") | AJ19: =IFERROR(VLOOKUP(AI19,'Helper(IMPORTANT!)'!$CQ$1:$CR$41,2,TRUE),"")
A20: 8 | B20: ='INPUT DATA'!L18 -> 0 | P20: =IF(COUNT($F20:$O20)=0,"",SUM($F20:$O20)) | Q20: =IFERROR(IF(P20="","",ROUND(P20/$P$11*100,2)),"") | R20: =IFERROR(IF(Q20="","",ROUND(Q20*$R$11,2)),"") | AC20: =IF(COUNT($S20:$AB20)=0,"",SUM($S20:$AB20)) | AD20: =IFERROR(IF(AC20="","",ROUND(AC20/$AC$11*100,2)),"") | AE20: =IFERROR(IF(AD20="","",ROUND(AD20*$AE$11,2)),"") | AG20: =IFERROR(IF(AF20="","",ROUND(AF20/$AF$11*100,2)),"") | AH20: =IFERROR(IF(AG20="","",ROUND(AG20*$AH$11,2)),"") | AI20: =IFERROR(R20+AE20+AH20,"") | AJ20: =IFERROR(VLOOKUP(AI20,'Helper(IMPORTANT!)'!$CQ$1:$CR$41,2,TRUE),"")
A21: 9 | B21: ='INPUT DATA'!L19 -> 0 | P21: =IF(COUNT($F21:$O21)=0,"",SUM($F21:$O21)) | Q21: =IFERROR(IF(P21="","",ROUND(P21/$P$11*100,2)),"") | R21: =IFERROR(IF(Q21="","",ROUND(Q21*$R$11,2)),"") | AC21: =IF(COUNT($S21:$AB21)=0,"",SUM($S21:$AB21)) | AD21: =IFERROR(IF(AC21="","",ROUND(AC21/$AC$11*100,2)),"") | AE21: =IFERROR(IF(AD21="","",ROUND(AD21*$AE$11,2)),"") | AG21: =IFERROR(IF(AF21="","",ROUND(AF21/$AF$11*100,2)),"") | AH21: =IFERROR(IF(AG21="","",ROUND(AG21*$AH$11,2)),"") | AI21: =IFERROR(R21+AE21+AH21,"") | AJ21: =IFERROR(VLOOKUP(AI21,'Helper(IMPORTANT!)'!$CQ$1:$CR$41,2,TRUE),"")
A22: 10 | B22: ='INPUT DATA'!L20 -> 0 | P22: =IF(COUNT($F22:$O22)=0,"",SUM($F22:$O22)) | Q22: =IFERROR(IF(P22="","",ROUND(P22/$P$11*100,2)),"") | R22: =IFERROR(IF(Q22="","",ROUND(Q22*$R$11,2)),"") | AC22: =IF(COUNT($S22:$AB22)=0,"",SUM($S22:$AB22)) | AD22: =IFERROR(IF(AC22="","",ROUND(AC22/$AC$11*100,2)),"") | AE22: =IFERROR(IF(AD22="","",ROUND(AD22*$AE$11,2)),"") | AG22: =IFERROR(IF(AF22="","",ROUND(AF22/$AF$11*100,2)),"") | AH22: =IFERROR(IF(AG22="","",ROUND(AG22*$AH$11,2)),"") | AI22: =IFERROR(R22+AE22+AH22,"") | AJ22: =IFERROR(VLOOKUP(AI22,'Helper(IMPORTANT!)'!$CQ$1:$CR$41,2,TRUE),"")
A23: 11 | B23: ='INPUT DATA'!L21 -> 0 | P23: =IF(COUNT($F23:$O23)=0,"",SUM($F23:$O23)) | Q23: =IFERROR(IF(P23="","",ROUND(P23/$P$11*100,2)),"") | R23: =IFERROR(IF(Q23="","",ROUND(Q23*$R$11,2)),"") | AC23: =IF(COUNT($S23:$AB23)=0,"",SUM($S23:$AB23)) | AD23: =IFERROR(IF(AC23="","",ROUND(AC23/$AC$11*100,2)),"") | AE23: =IFERROR(IF(AD23="","",ROUND(AD23*$AE$11,2)),"") | AG23: =IFERROR(IF(AF23="","",ROUND(AF23/$AF$11*100,2)),"") | AH23: =IFERROR(IF(AG23="","",ROUND(AG23*$AH$11,2)),"") | AI23: =IFERROR(R23+AE23+AH23,"") | AJ23: =IFERROR(VLOOKUP(AI23,'Helper(IMPORTANT!)'!$CQ$1:$CR$41,2,TRUE),"")
A24: 12 | B24: ='INPUT DATA'!L22 -> 0 | P24: =IF(COUNT($F24:$O24)=0,"",SUM($F24:$O24)) | Q24: =IFERROR(IF(P24="","",ROUND(P24/$P$11*100,2)),"") | R24: =IFERROR(IF(Q24="","",ROUND(Q24*$R$11,2)),"") | AC24: =IF(COUNT($S24:$AB24)=0,"",SUM($S24:$AB24)) | AD24: =IFERROR(IF(AC24="","",ROUND(AC24/$AC$11*100,2)),"") | AE24: =IFERROR(IF(AD24="","",ROUND(AD24*$AE$11,2)),"") | AG24: =IFERROR(IF(AF24="","",ROUND(AF24/$AF$11*100,2)),"") | AH24: =IFERROR(IF(AG24="","",ROUND(AG24*$AH$11,2)),"") | AI24: =IFERROR(R24+AE24+AH24,"") | AJ24: =IFERROR(VLOOKUP(AI24,'Helper(IMPORTANT!)'!$CQ$1:$CR$41,2,TRUE),"")
... A62: 50 | B62: ='INPUT DATA'!L60 -> 0 | P62: =IF(COUNT($F62:$O62)=0,"",SUM($F62:$O62)) | Q62: =IFERROR(IF(P62="","",ROUND(P62/$P$11*100,2)),"") | R62: =IFERROR(IF(Q62="","",ROUND(Q62*$R$11,2)),"") | AC62: =IF(COUNT($S62:$AB62)=0,"",SUM($S62:$AB62)) | AD62: =IFERROR(IF(AC62="","",ROUND(AC62/$AC$11*100,2)),"") | AE62: =IFERROR(IF(AD62="","",ROUND(AD62*$AE$11,2)),"") | AG62: =IFERROR(IF(AF62="","",ROUND(AF62/$AF$11*100,2)),"") | AH62: =IFERROR(IF(AG62="","",ROUND(AG62*$AH$11,2)),"") | AI62: =IFERROR(R62+AE62+AH62,"") | AJ62: =IFERROR(VLOOKUP(AI62,'Helper(IMPORTANT!)'!$CQ$1:$CR$41,2,TRUE),"")
A63: FEMALE
A64: 1 | B64: ='INPUT DATA'!O11 -> 0 | P64: =IF(COUNT($F64:$O64)=0,"",SUM($F64:$O64)) | Q64: =IFERROR(IF(P64="","",ROUND(P64/$P$11*100,2)),"") | R64: =IFERROR(IF(Q64="","",ROUND(Q64*$R$11,2)),"") | AC64: =IF(COUNT($S64:$AB64)=0,"",SUM($S64:$AB64)) | AD64: =IFERROR(IF(AC64="","",ROUND(AC64/$AC$11*100,2)),"") | AE64: =IFERROR(IF(AD64="","",ROUND(AD64*$AE$11,2)),"") | AG64: =IFERROR(IF(AF64="","",ROUND(AF64/$AF$11*100,2)),"") | AH64: =IFERROR(IF(AG64="","",ROUND(AG64*$AH$11,2)),"") | AI64: =IFERROR(R64+AE64+AH64,"") | AJ64: =IFERROR(VLOOKUP(AI64,'Helper(IMPORTANT!)'!$CQ$1:$CR$41,2,TRUE),"")
A65: 2 | B65: ='INPUT DATA'!O12 -> 0 | P65: =IF(COUNT($F65:$O65)=0,"",SUM($F65:$O65)) | Q65: =IFERROR(IF(P65="","",ROUND(P65/$P$11*100,2)),"") | R65: =IFERROR(IF(Q65="","",ROUND(Q65*$R$11,2)),"") | AC65: =IF(COUNT($S65:$AB65)=0,"",SUM($S65:$AB65)) | AD65: =IFERROR(IF(AC65="","",ROUND(AC65/$AC$11*100,2)),"") | AE65: =IFERROR(IF(AD65="","",ROUND(AD65*$AE$11,2)),"") | AG65: =IFERROR(IF(AF65="","",ROUND(AF65/$AF$11*100,2)),"") | AH65: =IFERROR(IF(AG65="","",ROUND(AG65*$AH$11,2)),"") | AI65: =IFERROR(R65+AE65+AH65,"") | AJ65: =IFERROR(VLOOKUP(AI65,'Helper(IMPORTANT!)'!$CQ$1:$CR$41,2,TRUE),"")
A66: 3 | B66: ='INPUT DATA'!O13 -> 0 | P66: =IF(COUNT($F66:$O66)=0,"",SUM($F66:$O66)) | Q66: =IFERROR(IF(P66="","",ROUND(P66/$P$11*100,2)),"") | R66: =IFERROR(IF(Q66="","",ROUND(Q66*$R$11,2)),"") | AC66: =IF(COUNT($S66:$AB66)=0,"",SUM($S66:$AB66)) | AD66: =IFERROR(IF(AC66="","",ROUND(AC66/$AC$11*100,2)),"") | AE66: =IFERROR(IF(AD66="","",ROUND(AD66*$AE$11,2)),"") | AG66: =IFERROR(IF(AF66="","",ROUND(AF66/$AF$11*100,2)),"") | AH66: =IFERROR(IF(AG66="","",ROUND(AG66*$AH$11,2)),"") | AI66: =IFERROR(R66+AE66+AH66,"") | AJ66: =IFERROR(VLOOKUP(AI66,'Helper(IMPORTANT!)'!$CQ$1:$CR$41,2,TRUE),"")
A67: 4 | B67: ='INPUT DATA'!O14 -> 0 | P67: =IF(COUNT($F67:$O67)=0,"",SUM($F67:$O67)) | Q67: =IFERROR(IF(P67="","",ROUND(P67/$P$11*100,2)),"") | R67: =IFERROR(IF(Q67="","",ROUND(Q67*$R$11,2)),"") | AC67: =IF(COUNT($S67:$AB67)=0,"",SUM($S67:$AB67)) | AD67: =IFERROR(IF(AC67="","",ROUND(AC67/$AC$11*100,2)),"") | AE67: =IFERROR(IF(AD67="","",ROUND(AD67*$AE$11,2)),"") | AG67: =IFERROR(IF(AF67="","",ROUND(AF67/$AF$11*100,2)),"") | AH67: =IFERROR(IF(AG67="","",ROUND(AG67*$AH$11,2)),"") | AI67: =IFERROR(R67+AE67+AH67,"") | AJ67: =IFERROR(VLOOKUP(AI67,'Helper(IMPORTANT!)'!$CQ$1:$CR$41,2,TRUE),"")
A68: 5 | B68: ='INPUT DATA'!O15 -> 0 | P68: =IF(COUNT($F68:$O68)=0,"",SUM($F68:$O68)) | Q68: =IFERROR(IF(P68="","",ROUND(P68/$P$11*100,2)),"") | R68: =IFERROR(IF(Q68="","",ROUND(Q68*$R$11,2)),"") | AC68: =IF(COUNT($S68:$AB68)=0,"",SUM($S68:$AB68)) | AD68: =IFERROR(IF(AC68="","",ROUND(AC68/$AC$11*100,2)),"") | AE68: =IFERROR(IF(AD68="","",ROUND(AD68*$AE$11,2)),"") | AG68: =IFERROR(IF(AF68="","",ROUND(AF68/$AF$11*100,2)),"") | AH68: =IFERROR(IF(AG68="","",ROUND(AG68*$AH$11,2)),"") | AI68: =IFERROR(R68+AE68+AH68,"") | AJ68: =IFERROR(VLOOKUP(AI68,'Helper(IMPORTANT!)'!$CQ$1:$CR$41,2,TRUE),"")
A69: 6 | B69: ='INPUT DATA'!O16 -> 0 | P69: =IF(COUNT($F69:$O69)=0,"",SUM($F69:$O69)) | Q69: =IFERROR(IF(P69="","",ROUND(P69/$P$11*100,2)),"") | R69: =IFERROR(IF(Q69="","",ROUND(Q69*$R$11,2)),"") | AC69: =IF(COUNT($S69:$AB69)=0,"",SUM($S69:$AB69)) | AD69: =IFERROR(IF(AC69="","",ROUND(AC69/$AC$11*100,2)),"") | AE69: =IFERROR(IF(AD69="","",ROUND(AD69*$AE$11,2)),"") | AG69: =IFERROR(IF(AF69="","",ROUND(AF69/$AF$11*100,2)),"") | AH69: =IFERROR(IF(AG69="","",ROUND(AG69*$AH$11,2)),"") | AI69: =IFERROR(R69+AE69+AH69,"") | AJ69: =IFERROR(VLOOKUP(AI69,'Helper(IMPORTANT!)'!$CQ$1:$CR$41,2,TRUE),"")
A70: 7 | B70: ='INPUT DATA'!O17 -> 0 | P70: =IF(COUNT($F70:$O70)=0,"",SUM($F70:$O70)) | Q70: =IFERROR(IF(P70="","",ROUND(P70/$P$11*100,2)),"") | R70: =IFERROR(IF(Q70="","",ROUND(Q70*$R$11,2)),"") | AC70: =IF(COUNT($S70:$AB70)=0,"",SUM($S70:$AB70)) | AD70: =IFERROR(IF(AC70="","",ROUND(AC70/$AC$11*100,2)),"") | AE70: =IFERROR(IF(AD70="","",ROUND(AD70*$AE$11,2)),"") | AG70: =IFERROR(IF(AF70="","",ROUND(AF70/$AF$11*100,2)),"") | AH70: =IFERROR(IF(AG70="","",ROUND(AG70*$AH$11,2)),"") | AI70: =IFERROR(R70+AE70+AH70,"") | AJ70: =IFERROR(VLOOKUP(AI70,'Helper(IMPORTANT!)'!$CQ$1:$CR$41,2,TRUE),"")
A71: 8 | B71: ='INPUT DATA'!O18 -> 0 | P71: =IF(COUNT($F71:$O71)=0,"",SUM($F71:$O71)) | Q71: =IFERROR(IF(P71="","",ROUND(P71/$P$11*100,2)),"") | R71: =IFERROR(IF(Q71="","",ROUND(Q71*$R$11,2)),"") | AC71: =IF(COUNT($S71:$AB71)=0,"",SUM($S71:$AB71)) | AD71: =IFERROR(IF(AC71="","",ROUND(AC71/$AC$11*100,2)),"") | AE71: =IFERROR(IF(AD71="","",ROUND(AD71*$AE$11,2)),"") | AG71: =IFERROR(IF(AF71="","",ROUND(AF71/$AF$11*100,2)),"") | AH71: =IFERROR(IF(AG71="","",ROUND(AG71*$AH$11,2)),"") | AI71: =IFERROR(R71+AE71+AH71,"") | AJ71: =IFERROR(VLOOKUP(AI71,'Helper(IMPORTANT!)'!$CQ$1:$CR$41,2,TRUE),"")
A72: 9 | B72: ='INPUT DATA'!O19 -> 0 | P72: =IF(COUNT($F72:$O72)=0,"",SUM($F72:$O72)) | Q72: =IFERROR(IF(P72="","",ROUND(P72/$P$11*100,2)),"") | R72: =IFERROR(IF(Q72="","",ROUND(Q72*$R$11,2)),"") | AC72: =IF(COUNT($S72:$AB72)=0,"",SUM($S72:$AB72)) | AD72: =IFERROR(IF(AC72="","",ROUND(AC72/$AC$11*100,2)),"") | AE72: =IFERROR(IF(AD72="","",ROUND(AD72*$AE$11,2)),"") | AG72: =IFERROR(IF(AF72="","",ROUND(AF72/$AF$11*100,2)),"") | AH72: =IFERROR(IF(AG72="","",ROUND(AG72*$AH$11,2)),"") | AI72: =IFERROR(R72+AE72+AH72,"") | AJ72: =IFERROR(VLOOKUP(AI72,'Helper(IMPORTANT!)'!$CQ$1:$CR$41,2,TRUE),"")
A73: 10 | B73: ='INPUT DATA'!O20 -> 0 | P73: =IF(COUNT($F73:$O73)=0,"",SUM($F73:$O73)) | Q73: =IFERROR(IF(P73="","",ROUND(P73/$P$11*100,2)),"") | R73: =IFERROR(IF(Q73="","",ROUND(Q73*$R$11,2)),"") | AC73: =IF(COUNT($S73:$AB73)=0,"",SUM($S73:$AB73)) | AD73: =IFERROR(IF(AC73="","",ROUND(AC73/$AC$11*100,2)),"") | AE73: =IFERROR(IF(AD73="","",ROUND(AD73*$AE$11,2)),"") | AG73: =IFERROR(IF(AF73="","",ROUND(AF73/$AF$11*100,2)),"") | AH73: =IFERROR(IF(AG73="","",ROUND(AG73*$AH$11,2)),"") | AI73: =IFERROR(R73+AE73+AH73,"") | AJ73: =IFERROR(VLOOKUP(AI73,'Helper(IMPORTANT!)'!$CQ$1:$CR$41,2,TRUE),"")
A74: 11 | B74: ='INPUT DATA'!O21 -> 0 | P74: =IF(COUNT($F74:$O74)=0,"",SUM($F74:$O74)) | Q74: =IFERROR(IF(P74="","",ROUND(P74/$P$11*100,2)),"") | R74: =IFERROR(IF(Q74="","",ROUND(Q74*$R$11,2)),"") | AC74: =IF(COUNT($S74:$AB74)=0,"",SUM($S74:$AB74)) | AD74: =IFERROR(IF(AC74="","",ROUND(AC74/$AC$11*100,2)),"") | AE74: =IFERROR(IF(AD74="","",ROUND(AD74*$AE$11,2)),"") | AG74: =IFERROR(IF(AF74="","",ROUND(AF74/$AF$11*100,2)),"") | AH74: =IFERROR(IF(AG74="","",ROUND(AG74*$AH$11,2)),"") | AI74: =IFERROR(R74+AE74+AH74,"") | AJ74: =IFERROR(VLOOKUP(AI74,'Helper(IMPORTANT!)'!$CQ$1:$CR$41,2,TRUE),"")
A75: 12 | B75: ='INPUT DATA'!O22 -> 0 | P75: =IF(COUNT($F75:$O75)=0,"",SUM($F75:$O75)) | Q75: =IFERROR(IF(P75="","",ROUND(P75/$P$11*100,2)),"") | R75: =IFERROR(IF(Q75="","",ROUND(Q75*$R$11,2)),"") | AC75: =IF(COUNT($S75:$AB75)=0,"",SUM($S75:$AB75)) | AD75: =IFERROR(IF(AC75="","",ROUND(AC75/$AC$11*100,2)),"") | AE75: =IFERROR(IF(AD75="","",ROUND(AD75*$AE$11,2)),"") | AG75: =IFERROR(IF(AF75="","",ROUND(AF75/$AF$11*100,2)),"") | AH75: =IFERROR(IF(AG75="","",ROUND(AG75*$AH$11,2)),"") | AI75: =IFERROR(R75+AE75+AH75,"") | AJ75: =IFERROR(VLOOKUP(AI75,'Helper(IMPORTANT!)'!$CQ$1:$CR$41,2,TRUE),"")
... A113: 50 | B113: ='INPUT DATA'!O60 -> 0 | P113: =IF(COUNT($F113:$O113)=0,"",SUM($F113:$O113)) | Q113: =IFERROR(IF(P113="","",ROUND(P113/$P$11*100,2)),"") | R113: =IFERROR(IF(Q113="","",ROUND(Q113*$R$11,2)),"") | AC113: =IF(COUNT($S113:$AB113)=0,"",SUM($S113:$AB113)) | AD113: =IFERROR(IF(AC113="","",ROUND(AC113/$AC$11*100,2)),"") | AE113: =IFERROR(IF(AD113="","",ROUND(AD113*$AE$11,2)),"") | AG113: =IFERROR(IF(AF113="","",ROUND(AF113/$AF$11*100,2)),"") | AH113: =IFERROR(IF(AG113="","",ROUND(AG113*$AH$11,2)),"") | AI113: =IFERROR(R113+AE113+AH113,"") | AJ113: =IFERROR(VLOOKUP(AI113,'Helper(IMPORTANT!)'!$CQ$1:$CR$41,2,TRUE),"")

Sheet Q3
A1: Strengthened Senior High School Class Record
A3: (Pursuant to Deped Order 8 series of 2015)
F4: REGION | G4: ='INPUT DATA'!F10 -> 0 | L4: DIVISION | O4: ='INPUT DATA'!F11 -> 0
F5: SCHOOL NAME | G5: ='INPUT DATA'!F14 -> 0 | T5: SCHOOL ID | X5: ='INPUT DATA'!F13 -> 0 | AD5: SCHOOL YEAR | AG5: ='INPUT DATA'!F16 -> 0
A7: THIRD QUARTER | F7: GRADE & SECTION: | K7: ='INPUT DATA'!F24&" - "&'INPUT DATA'!F25 -> - | Q7: TEACHER: | S7: ='INPUT DATA'!F22 -> 0 | AC7: SUBJECT: | AE7: =IF('INPUT DATA'!F30<>"",'INPUT DATA'!F30,'INPUT DATA'!F28) -> 0
Q8: SEMESTER: | S8: - - | AC8: SUBJECT TYPE: | AE8: ='INPUT DATA'!F26 -> 0
A9: LEARNERS' NAMES | F9: =IF('INPUT DATA'!$F$26="","",INDEX('Helper(IMPORTANT!)'!$CI$2:$CI$6,MATCH(AE8,'Helper(IMPORTANT!)'!$CH$2:$CH$6,0))) | S9: =IF('INPUT DATA'!$F$26="","",INDEX('Helper(IMPORTANT!)'!$CJ$2:$CJ$6,MATCH(AE8,'Helper(IMPORTANT!)'!$CH$2:$CH$6,0))) | AF9: =IF('INPUT DATA'!$F$26="","",INDEX('Helper(IMPORTANT!)'!$CK$2:$CK$6,MATCH(AE8,'Helper(IMPORTANT!)'!$CH$2:$CH$6,0))) | AI9: Initial Grade | AJ9: Quarterly Grade
F10: 1 | G10: 2 | H10: 3 | I10: 4 | J10: 5 | K10: 6 | L10: 7 | M10: 8 | N10: 9 | O10: 10 | P10: Total | Q10: PS | R10: WS | S10: 1 | T10: 2 | U10: 3 | V10: 4 | W10: 5 | X10: 6 | Y10: 7 | Z10: 8 | AA10: 9 | AB10: 10 | AC10: Total | AD10: PS | AE10: WS | AF10: 1 | AG10: PS | AH10: WS
A11: HIGHEST POSSIBLE SCORE | P11: =IF(COUNT($F11:$O11)=0,"",SUM($F11:$O11)) | Q11: 100 | R11: =IF('INPUT DATA'!$F$26="","",INDEX('Helper(IMPORTANT!)'!$CL$2:$CL$6,MATCH(AE8,'Helper(IMPORTANT!)'!$CH$2:$CH$6,0))) | AC11: =IF(COUNT($S11:$AB11)=0,"",SUM($S11:$AB11)) | AD11: 100 | AE11: =IF('INPUT DATA'!$F$26="","",INDEX('Helper(IMPORTANT!)'!$CM$2:$CM$6,MATCH(AE8,'Helper(IMPORTANT!)'!$CH$2:$CH$6,0))) | AG11: 100 | AH11: =IF('INPUT DATA'!$F$26="","",INDEX('Helper(IMPORTANT!)'!$CN$2:$CN$6,MATCH(AE8,'Helper(IMPORTANT!)'!$CH$2:$CH$6,0)))
A12: MALE
A13: 1 | B13: ='INPUT DATA'!L11 -> 0 | P13: =IF(COUNT($F13:$O13)=0,"",SUM($F13:$O13)) | Q13: =IFERROR(IF(P13="","",ROUND(P13/$P$11*100,2)),"") | R13: =IFERROR(IF(Q13="","",ROUND(Q13*$R$11,2)),"") | AC13: =IF(COUNT($S13:$AB13)=0,"",SUM($S13:$AB13)) | AD13: =IFERROR(IF(AC13="","",ROUND(AC13/$AC$11*100,2)),"") | AE13: =IFERROR(IF(AD13="","",ROUND(AD13*$AE$11,2)),"") | AG13: =IFERROR(IF(AF13="","",ROUND(AF13/$AF$11*100,2)),"") | AH13: =IFERROR(IF(AG13="","",ROUND(AG13*$AH$11,2)),"") | AI13: =IFERROR(R13+AE13+AH13,"") | AJ13: =IFERROR(VLOOKUP(AI13,'Helper(IMPORTANT!)'!$CQ$1:$CR$41,2,TRUE),"")
A14: 2 | B14: ='INPUT DATA'!L12 -> 0 | P14: =IF(COUNT($F14:$O14)=0,"",SUM($F14:$O14)) | Q14: =IFERROR(IF(P14="","",ROUND(P14/$P$11*100,2)),"") | R14: =IFERROR(IF(Q14="","",ROUND(Q14*$R$11,2)),"") | AC14: =IF(COUNT($S14:$AB14)=0,"",SUM($S14:$AB14)) | AD14: =IFERROR(IF(AC14="","",ROUND(AC14/$AC$11*100,2)),"") | AE14: =IFERROR(IF(AD14="","",ROUND(AD14*$AE$11,2)),"") | AG14: =IFERROR(IF(AF14="","",ROUND(AF14/$AF$11*100,2)),"") | AH14: =IFERROR(IF(AG14="","",ROUND(AG14*$AH$11,2)),"") | AI14: =IFERROR(R14+AE14+AH14,"") | AJ14: =IFERROR(VLOOKUP(AI14,'Helper(IMPORTANT!)'!$CQ$1:$CR$41,2,TRUE),"")
A15: 3 | B15: ='INPUT DATA'!L13 -> 0 | P15: =IF(COUNT($F15:$O15)=0,"",SUM($F15:$O15)) | Q15: =IFERROR(IF(P15="","",ROUND(P15/$P$11*100,2)),"") | R15: =IFERROR(IF(Q15="","",ROUND(Q15*$R$11,2)),"") | AC15: =IF(COUNT($S15:$AB15)=0,"",SUM($S15:$AB15)) | AD15: =IFERROR(IF(AC15="","",ROUND(AC15/$AC$11*100,2)),"") | AE15: =IFERROR(IF(AD15="","",ROUND(AD15*$AE$11,2)),"") | AG15: =IFERROR(IF(AF15="","",ROUND(AF15/$AF$11*100,2)),"") | AH15: =IFERROR(IF(AG15="","",ROUND(AG15*$AH$11,2)),"") | AI15: =IFERROR(R15+AE15+AH15,"") | AJ15: =IFERROR(VLOOKUP(AI15,'Helper(IMPORTANT!)'!$CQ$1:$CR$41,2,TRUE),"")
A16: 4 | B16: ='INPUT DATA'!L14 -> 0 | P16: =IF(COUNT($F16:$O16)=0,"",SUM($F16:$O16)) | Q16: =IFERROR(IF(P16="","",ROUND(P16/$P$11*100,2)),"") | R16: =IFERROR(IF(Q16="","",ROUND(Q16*$R$11,2)),"") | AC16: =IF(COUNT($S16:$AB16)=0,"",SUM($S16:$AB16)) | AD16: =IFERROR(IF(AC16="","",ROUND(AC16/$AC$11*100,2)),"") | AE16: =IFERROR(IF(AD16="","",ROUND(AD16*$AE$11,2)),"") | AG16: =IFERROR(IF(AF16="","",ROUND(AF16/$AF$11*100,2)),"") | AH16: =IFERROR(IF(AG16="","",ROUND(AG16*$AH$11,2)),"") | AI16: =IFERROR(R16+AE16+AH16,"") | AJ16: =IFERROR(VLOOKUP(AI16,'Helper(IMPORTANT!)'!$CQ$1:$CR$41,2,TRUE),"")
A17: 5 | B17: ='INPUT DATA'!L15 -> 0 | P17: =IF(COUNT($F17:$O17)=0,"",SUM($F17:$O17)) | Q17: =IFERROR(IF(P17="","",ROUND(P17/$P$11*100,2)),"") | R17: =IFERROR(IF(Q17="","",ROUND(Q17*$R$11,2)),"") | AC17: =IF(COUNT($S17:$AB17)=0,"",SUM($S17:$AB17)) | AD17: =IFERROR(IF(AC17="","",ROUND(AC17/$AC$11*100,2)),"") | AE17: =IFERROR(IF(AD17="","",ROUND(AD17*$AE$11,2)),"") | AG17: =IFERROR(IF(AF17="","",ROUND(AF17/$AF$11*100,2)),"") | AH17: =IFERROR(IF(AG17="","",ROUND(AG17*$AH$11,2)),"") | AI17: =IFERROR(R17+AE17+AH17,"") | AJ17: =IFERROR(VLOOKUP(AI17,'Helper(IMPORTANT!)'!$CQ$1:$CR$41,2,TRUE),"")
A18: 6 | B18: ='INPUT DATA'!L16 -> 0 | P18: =IF(COUNT($F18:$O18)=0,"",SUM($F18:$O18)) | Q18: =IFERROR(IF(P18="","",ROUND(P18/$P$11*100,2)),"") | R18: =IFERROR(IF(Q18="","",ROUND(Q18*$R$11,2)),"") | AC18: =IF(COUNT($S18:$AB18)=0,"",SUM($S18:$AB18)) | AD18: =IFERROR(IF(AC18="","",ROUND(AC18/$AC$11*100,2)),"") | AE18: =IFERROR(IF(AD18="","",ROUND(AD18*$AE$11,2)),"") | AG18: =IFERROR(IF(AF18="","",ROUND(AF18/$AF$11*100,2)),"") | AH18: =IFERROR(IF(AG18="","",ROUND(AG18*$AH$11,2)),"") | AI18: =IFERROR(R18+AE18+AH18,"") | AJ18: =IFERROR(VLOOKUP(AI18,'Helper(IMPORTANT!)'!$CQ$1:$CR$41,2,TRUE),"")
A19: 7 | B19: ='INPUT DATA'!L17 -> 0 | P19: =IF(COUNT($F19:$O19)=0,"",SUM($F19:$O19)) | Q19: =IFERROR(IF(P19="","",ROUND(P19/$P$11*100,2)),"") | R19: =IFERROR(IF(Q19="","",ROUND(Q19*$R$11,2)),"") | AC19: =IF(COUNT($S19:$AB19)=0,"",SUM($S19:$AB19)) | AD19: =IFERROR(IF(AC19="","",ROUND(AC19/$AC$11*100,2)),"") | AE19: =IFERROR(IF(AD19="","",ROUND(AD19*$AE$11,2)),"") | AG19: =IFERROR(IF(AF19="","",ROUND(AF19/$AF$11*100,2)),"") | AH19: =IFERROR(IF(AG19="","",ROUND(AG19*$AH$11,2)),"") | AI19: =IFERROR(R19+AE19+AH19,"") | AJ19: =IFERROR(VLOOKUP(AI19,'Helper(IMPORTANT!)'!$CQ$1:$CR$41,2,TRUE),"")
A20: 8 | B20: ='INPUT DATA'!L18 -> 0 | P20: =IF(COUNT($F20:$O20)=0,"",SUM($F20:$O20)) | Q20: =IFERROR(IF(P20="","",ROUND(P20/$P$11*100,2)),"") | R20: =IFERROR(IF(Q20="","",ROUND(Q20*$R$11,2)),"") | AC20: =IF(COUNT($S20:$AB20)=0,"",SUM($S20:$AB20)) | AD20: =IFERROR(IF(AC20="","",ROUND(AC20/$AC$11*100,2)),"") | AE20: =IFERROR(IF(AD20="","",ROUND(AD20*$AE$11,2)),"") | AG20: =IFERROR(IF(AF20="","",ROUND(AF20/$AF$11*100,2)),"") | AH20: =IFERROR(IF(AG20="","",ROUND(AG20*$AH$11,2)),"") | AI20: =IFERROR(R20+AE20+AH20,"") | AJ20: =IFERROR(VLOOKUP(AI20,'Helper(IMPORTANT!)'!$CQ$1:$CR$41,2,TRUE),"")
A21: 9 | B21: ='INPUT DATA'!L19 -> 0 | P21: =IF(COUNT($F21:$O21)=0,"",SUM($F21:$O21)) | Q21: =IFERROR(IF(P21="","",ROUND(P21/$P$11*100,2)),"") | R21: =IFERROR(IF(Q21="","",ROUND(Q21*$R$11,2)),"") | AC21: =IF(COUNT($S21:$AB21)=0,"",SUM($S21:$AB21)) | AD21: =IFERROR(IF(AC21="","",ROUND(AC21/$AC$11*100,2)),"") | AE21: =IFERROR(IF(AD21="","",ROUND(AD21*$AE$11,2)),"") | AG21: =IFERROR(IF(AF21="","",ROUND(AF21/$AF$11*100,2)),"") | AH21: =IFERROR(IF(AG21="","",ROUND(AG21*$AH$11,2)),"") | AI21: =IFERROR(R21+AE21+AH21,"") | AJ21: =IFERROR(VLOOKUP(AI21,'Helper(IMPORTANT!)'!$CQ$1:$CR$41,2,TRUE),"")
A22: 10 | B22: ='INPUT DATA'!L20 -> 0 | P22: =IF(COUNT($F22:$O22)=0,"",SUM($F22:$O22)) | Q22: =IFERROR(IF(P22="","",ROUND(P22/$P$11*100,2)),"") | R22: =IFERROR(IF(Q22="","",ROUND(Q22*$R$11,2)),"") | AC22: =IF(COUNT($S22:$AB22)=0,"",SUM($S22:$AB22)) | AD22: =IFERROR(IF(AC22="","",ROUND(AC22/$AC$11*100,2)),"") | AE22: =IFERROR(IF(AD22="","",ROUND(AD22*$AE$11,2)),"") | AG22: =IFERROR(IF(AF22="","",ROUND(AF22/$AF$11*100,2)),"") | AH22: =IFERROR(IF(AG22="","",ROUND(AG22*$AH$11,2)),"") | AI22: =IFERROR(R22+AE22+AH22,"") | AJ22: =IFERROR(VLOOKUP(AI22,'Helper(IMPORTANT!)'!$CQ$1:$CR$41,2,TRUE),"")
A23: 11 | B23: ='INPUT DATA'!L21 -> 0 | P23: =IF(COUNT($F23:$O23)=0,"",SUM($F23:$O23)) | Q23: =IFERROR(IF(P23="","",ROUND(P23/$P$11*100,2)),"") | R23: =IFERROR(IF(Q23="","",ROUND(Q23*$R$11,2)),"") | AC23: =IF(COUNT($S23:$AB23)=0,"",SUM($S23:$AB23)) | AD23: =IFERROR(IF(AC23="","",ROUND(AC23/$AC$11*100,2)),"") | AE23: =IFERROR(IF(AD23="","",ROUND(AD23*$AE$11,2)),"") | AG23: =IFERROR(IF(AF23="","",ROUND(AF23/$AF$11*100,2)),"") | AH23: =IFERROR(IF(AG23="","",ROUND(AG23*$AH$11,2)),"") | AI23: =IFERROR(R23+AE23+AH23,"") | AJ23: =IFERROR(VLOOKUP(AI23,'Helper(IMPORTANT!)'!$CQ$1:$CR$41,2,TRUE),"")
A24: 12 | B24: ='INPUT DATA'!L22 -> 0 | P24: =IF(COUNT($F24:$O24)=0,"",SUM($F24:$O24)) | Q24: =IFERROR(IF(P24="","",ROUND(P24/$P$11*100,2)),"") | R24: =IFERROR(IF(Q24="","",ROUND(Q24*$R$11,2)),"") | AC24: =IF(COUNT($S24:$AB24)=0,"",SUM($S24:$AB24)) | AD24: =IFERROR(IF(AC24="","",ROUND(AC24/$AC$11*100,2)),"") | AE24: =IFERROR(IF(AD24="","",ROUND(AD24*$AE$11,2)),"") | AG24: =IFERROR(IF(AF24="","",ROUND(AF24/$AF$11*100,2)),"") | AH24: =IFERROR(IF(AG24="","",ROUND(AG24*$AH$11,2)),"") | AI24: =IFERROR(R24+AE24+AH24,"") | AJ24: =IFERROR(VLOOKUP(AI24,'Helper(IMPORTANT!)'!$CQ$1:$CR$41,2,TRUE),"")
... A62: 50 | B62: ='INPUT DATA'!L60 -> 0 | P62: =IF(COUNT($F62:$O62)=0,"",SUM($F62:$O62)) | Q62: =IFERROR(IF(P62="","",ROUND(P62/$P$11*100,2)),"") | R62: =IFERROR(IF(Q62="","",ROUND(Q62*$R$11,2)),"") | AC62: =IF(COUNT($S62:$AB62)=0,"",SUM($S62:$AB62)) | AD62: =IFERROR(IF(AC62="","",ROUND(AC62/$AC$11*100,2)),"") | AE62: =IFERROR(IF(AD62="","",ROUND(AD62*$AE$11,2)),"") | AG62: =IFERROR(IF(AF62="","",ROUND(AF62/$AF$11*100,2)),"") | AH62: =IFERROR(IF(AG62="","",ROUND(AG62*$AH$11,2)),"") | AI62: =IFERROR(R62+AE62+AH62,"") | AJ62: =IFERROR(VLOOKUP(AI62,'Helper(IMPORTANT!)'!$CQ$1:$CR$41,2,TRUE),"")
A63: FEMALE
A64: 1 | B64: ='INPUT DATA'!O11 -> 0 | P64: =IF(COUNT($F64:$O64)=0,"",SUM($F64:$O64)) | Q64: =IFERROR(IF(P64="","",ROUND(P64/$P$11*100,2)),"") | R64: =IFERROR(IF(Q64="","",ROUND(Q64*$R$11,2)),"") | AC64: =IF(COUNT($S64:$AB64)=0,"",SUM($S64:$AB64)) | AD64: =IFERROR(IF(AC64="","",ROUND(AC64/$AC$11*100,2)),"") | AE64: =IFERROR(IF(AD64="","",ROUND(AD64*$AE$11,2)),"") | AG64: =IFERROR(IF(AF64="","",ROUND(AF64/$AF$11*100,2)),"") | AH64: =IFERROR(IF(AG64="","",ROUND(AG64*$AH$11,2)),"") | AI64: =IFERROR(R64+AE64+AH64,"") | AJ64: =IFERROR(VLOOKUP(AI64,'Helper(IMPORTANT!)'!$CQ$1:$CR$41,2,TRUE),"")
A65: 2 | B65: ='INPUT DATA'!O12 -> 0 | P65: =IF(COUNT($F65:$O65)=0,"",SUM($F65:$O65)) | Q65: =IFERROR(IF(P65="","",ROUND(P65/$P$11*100,2)),"") | R65: =IFERROR(IF(Q65="","",ROUND(Q65*$R$11,2)),"") | AC65: =IF(COUNT($S65:$AB65)=0,"",SUM($S65:$AB65)) | AD65: =IFERROR(IF(AC65="","",ROUND(AC65/$AC$11*100,2)),"") | AE65: =IFERROR(IF(AD65="","",ROUND(AD65*$AE$11,2)),"") | AG65: =IFERROR(IF(AF65="","",ROUND(AF65/$AF$11*100,2)),"") | AH65: =IFERROR(IF(AG65="","",ROUND(AG65*$AH$11,2)),"") | AI65: =IFERROR(R65+AE65+AH65,"") | AJ65: =IFERROR(VLOOKUP(AI65,'Helper(IMPORTANT!)'!$CQ$1:$CR$41,2,TRUE),"")
A66: 3 | B66: ='INPUT DATA'!O13 -> 0 | P66: =IF(COUNT($F66:$O66)=0,"",SUM($F66:$O66)) | Q66: =IFERROR(IF(P66="","",ROUND(P66/$P$11*100,2)),"") | R66: =IFERROR(IF(Q66="","",ROUND(Q66*$R$11,2)),"") | AC66: =IF(COUNT($S66:$AB66)=0,"",SUM($S66:$AB66)) | AD66: =IFERROR(IF(AC66="","",ROUND(AC66/$AC$11*100,2)),"") | AE66: =IFERROR(IF(AD66="","",ROUND(AD66*$AE$11,2)),"") | AG66: =IFERROR(IF(AF66="","",ROUND(AF66/$AF$11*100,2)),"") | AH66: =IFERROR(IF(AG66="","",ROUND(AG66*$AH$11,2)),"") | AI66: =IFERROR(R66+AE66+AH66,"") | AJ66: =IFERROR(VLOOKUP(AI66,'Helper(IMPORTANT!)'!$CQ$1:$CR$41,2,TRUE),"")
A67: 4 | B67: ='INPUT DATA'!O14 -> 0 | P67: =IF(COUNT($F67:$O67)=0,"",SUM($F67:$O67)) | Q67: =IFERROR(IF(P67="","",ROUND(P67/$P$11*100,2)),"") | R67: =IFERROR(IF(Q67="","",ROUND(Q67*$R$11,2)),"") | AC67: =IF(COUNT($S67:$AB67)=0,"",SUM($S67:$AB67)) | AD67: =IFERROR(IF(AC67="","",ROUND(AC67/$AC$11*100,2)),"") | AE67: =IFERROR(IF(AD67="","",ROUND(AD67*$AE$11,2)),"") | AG67: =IFERROR(IF(AF67="","",ROUND(AF67/$AF$11*100,2)),"") | AH67: =IFERROR(IF(AG67="","",ROUND(AG67*$AH$11,2)),"") | AI67: =IFERROR(R67+AE67+AH67,"") | AJ67: =IFERROR(VLOOKUP(AI67,'Helper(IMPORTANT!)'!$CQ$1:$CR$41,2,TRUE),"")
A68: 5 | B68: ='INPUT DATA'!O15 -> 0 | P68: =IF(COUNT($F68:$O68)=0,"",SUM($F68:$O68)) | Q68: =IFERROR(IF(P68="","",ROUND(P68/$P$11*100,2)),"") | R68: =IFERROR(IF(Q68="","",ROUND(Q68*$R$11,2)),"") | AC68: =IF(COUNT($S68:$AB68)=0,"",SUM($S68:$AB68)) | AD68: =IFERROR(IF(AC68="","",ROUND(AC68/$AC$11*100,2)),"") | AE68: =IFERROR(IF(AD68="","",ROUND(AD68*$AE$11,2)),"") | AG68: =IFERROR(IF(AF68="","",ROUND(AF68/$AF$11*100,2)),"") | AH68: =IFERROR(IF(AG68="","",ROUND(AG68*$AH$11,2)),"") | AI68: =IFERROR(R68+AE68+AH68,"") | AJ68: =IFERROR(VLOOKUP(AI68,'Helper(IMPORTANT!)'!$CQ$1:$CR$41,2,TRUE),"")
A69: 6 | B69: ='INPUT DATA'!O16 -> 0 | P69: =IF(COUNT($F69:$O69)=0,"",SUM($F69:$O69)) | Q69: =IFERROR(IF(P69="","",ROUND(P69/$P$11*100,2)),"") | R69: =IFERROR(IF(Q69="","",ROUND(Q69*$R$11,2)),"") | AC69: =IF(COUNT($S69:$AB69)=0,"",SUM($S69:$AB69)) | AD69: =IFERROR(IF(AC69="","",ROUND(AC69/$AC$11*100,2)),"") | AE69: =IFERROR(IF(AD69="","",ROUND(AD69*$AE$11,2)),"") | AG69: =IFERROR(IF(AF69="","",ROUND(AF69/$AF$11*100,2)),"") | AH69: =IFERROR(IF(AG69="","",ROUND(AG69*$AH$11,2)),"") | AI69: =IFERROR(R69+AE69+AH69,"") | AJ69: =IFERROR(VLOOKUP(AI69,'Helper(IMPORTANT!)'!$CQ$1:$CR$41,2,TRUE),"")
A70: 7 | B70: ='INPUT DATA'!O17 -> 0 | P70: =IF(COUNT($F70:$O70)=0,"",SUM($F70:$O70)) | Q70: =IFERROR(IF(P70="","",ROUND(P70/$P$11*100,2)),"") | R70: =IFERROR(IF(Q70="","",ROUND(Q70*$R$11,2)),"") | AC70: =IF(COUNT($S70:$AB70)=0,"",SUM($S70:$AB70)) | AD70: =IFERROR(IF(AC70="","",ROUND(AC70/$AC$11*100,2)),"") | AE70: =IFERROR(IF(AD70="","",ROUND(AD70*$AE$11,2)),"") | AG70: =IFERROR(IF(AF70="","",ROUND(AF70/$AF$11*100,2)),"") | AH70: =IFERROR(IF(AG70="","",ROUND(AG70*$AH$11,2)),"") | AI70: =IFERROR(R70+AE70+AH70,"") | AJ70: =IFERROR(VLOOKUP(AI70,'Helper(IMPORTANT!)'!$CQ$1:$CR$41,2,TRUE),"")
A71: 8 | B71: ='INPUT DATA'!O18 -> 0 | P71: =IF(COUNT($F71:$O71)=0,"",SUM($F71:$O71)) | Q71: =IFERROR(IF(P71="","",ROUND(P71/$P$11*100,2)),"") | R71: =IFERROR(IF(Q71="","",ROUND(Q71*$R$11,2)),"") | AC71: =IF(COUNT($S71:$AB71)=0,"",SUM($S71:$AB71)) | AD71: =IFERROR(IF(AC71="","",ROUND(AC71/$AC$11*100,2)),"") | AE71: =IFERROR(IF(AD71="","",ROUND(AD71*$AE$11,2)),"") | AG71: =IFERROR(IF(AF71="","",ROUND(AF71/$AF$11*100,2)),"") | AH71: =IFERROR(IF(AG71="","",ROUND(AG71*$AH$11,2)),"") | AI71: =IFERROR(R71+AE71+AH71,"") | AJ71: =IFERROR(VLOOKUP(AI71,'Helper(IMPORTANT!)'!$CQ$1:$CR$41,2,TRUE),"")
A72: 9 | B72: ='INPUT DATA'!O19 -> 0 | P72: =IF(COUNT($F72:$O72)=0,"",SUM($F72:$O72)) | Q72: =IFERROR(IF(P72="","",ROUND(P72/$P$11*100,2)),"") | R72: =IFERROR(IF(Q72="","",ROUND(Q72*$R$11,2)),"") | AC72: =IF(COUNT($S72:$AB72)=0,"",SUM($S72:$AB72)) | AD72: =IFERROR(IF(AC72="","",ROUND(AC72/$AC$11*100,2)),"") | AE72: =IFERROR(IF(AD72="","",ROUND(AD72*$AE$11,2)),"") | AG72: =IFERROR(IF(AF72="","",ROUND(AF72/$AF$11*100,2)),"") | AH72: =IFERROR(IF(AG72="","",ROUND(AG72*$AH$11,2)),"") | AI72: =IFERROR(R72+AE72+AH72,"") | AJ72: =IFERROR(VLOOKUP(AI72,'Helper(IMPORTANT!)'!$CQ$1:$CR$41,2,TRUE),"")
A73: 10 | B73: ='INPUT DATA'!O20 -> 0 | P73: =IF(COUNT($F73:$O73)=0,"",SUM($F73:$O73)) | Q73: =IFERROR(IF(P73="","",ROUND(P73/$P$11*100,2)),"") | R73: =IFERROR(IF(Q73="","",ROUND(Q73*$R$11,2)),"") | AC73: =IF(COUNT($S73:$AB73)=0,"",SUM($S73:$AB73)) | AD73: =IFERROR(IF(AC73="","",ROUND(AC73/$AC$11*100,2)),"") | AE73: =IFERROR(IF(AD73="","",ROUND(AD73*$AE$11,2)),"") | AG73: =IFERROR(IF(AF73="","",ROUND(AF73/$AF$11*100,2)),"") | AH73: =IFERROR(IF(AG73="","",ROUND(AG73*$AH$11,2)),"") | AI73: =IFERROR(R73+AE73+AH73,"") | AJ73: =IFERROR(VLOOKUP(AI73,'Helper(IMPORTANT!)'!$CQ$1:$CR$41,2,TRUE),"")
A74: 11 | B74: ='INPUT DATA'!O21 -> 0 | P74: =IF(COUNT($F74:$O74)=0,"",SUM($F74:$O74)) | Q74: =IFERROR(IF(P74="","",ROUND(P74/$P$11*100,2)),"") | R74: =IFERROR(IF(Q74="","",ROUND(Q74*$R$11,2)),"") | AC74: =IF(COUNT($S74:$AB74)=0,"",SUM($S74:$AB74)) | AD74: =IFERROR(IF(AC74="","",ROUND(AC74/$AC$11*100,2)),"") | AE74: =IFERROR(IF(AD74="","",ROUND(AD74*$AE$11,2)),"") | AG74: =IFERROR(IF(AF74="","",ROUND(AF74/$AF$11*100,2)),"") | AH74: =IFERROR(IF(AG74="","",ROUND(AG74*$AH$11,2)),"") | AI74: =IFERROR(R74+AE74+AH74,"") | AJ74: =IFERROR(VLOOKUP(AI74,'Helper(IMPORTANT!)'!$CQ$1:$CR$41,2,TRUE),"")
A75: 12 | B75: ='INPUT DATA'!O22 -> 0 | P75: =IF(COUNT($F75:$O75)=0,"",SUM($F75:$O75)) | Q75: =IFERROR(IF(P75="","",ROUND(P75/$P$11*100,2)),"") | R75: =IFERROR(IF(Q75="","",ROUND(Q75*$R$11,2)),"") | AC75: =IF(COUNT($S75:$AB75)=0,"",SUM($S75:$AB75)) | AD75: =IFERROR(IF(AC75="","",ROUND(AC75/$AC$11*100,2)),"") | AE75: =IFERROR(IF(AD75="","",ROUND(AD75*$AE$11,2)),"") | AG75: =IFERROR(IF(AF75="","",ROUND(AF75/$AF$11*100,2)),"") | AH75: =IFERROR(IF(AG75="","",ROUND(AG75*$AH$11,2)),"") | AI75: =IFERROR(R75+AE75+AH75,"") | AJ75: =IFERROR(VLOOKUP(AI75,'Helper(IMPORTANT!)'!$CQ$1:$CR$41,2,TRUE),"")
... A113: 50 | B113: ='INPUT DATA'!O60 -> 0 | P113: =IF(COUNT($F113:$O113)=0,"",SUM($F113:$O113)) | Q113: =IFERROR(IF(P113="","",ROUND(P113/$P$11*100,2)),"") | R113: =IFERROR(IF(Q113="","",ROUND(Q113*$R$11,2)),"") | AC113: =IF(COUNT($S113:$AB113)=0,"",SUM($S113:$AB113)) | AD113: =IFERROR(IF(AC113="","",ROUND(AC113/$AC$11*100,2)),"") | AE113: =IFERROR(IF(AD113="","",ROUND(AD113*$AE$11,2)),"") | AG113: =IFERROR(IF(AF113="","",ROUND(AF113/$AF$11*100,2)),"") | AH113: =IFERROR(IF(AG113="","",ROUND(AG113*$AH$11,2)),"") | AI113: =IFERROR(R113+AE113+AH113,"") | AJ113: =IFERROR(VLOOKUP(AI113,'Helper(IMPORTANT!)'!$CQ$1:$CR$41,2,TRUE),"")

Sheet Q4
A1: Strengthened Senior High School Class Record
A3: (Pursuant to Deped Order 8 series of 2015)
F4: REGION | G4: ='INPUT DATA'!F10 -> 0 | L4: DIVISION | O4: ='INPUT DATA'!F11 -> 0
F5: SCHOOL NAME | G5: ='INPUT DATA'!F14 -> 0 | T5: SCHOOL ID | X5: ='INPUT DATA'!F13 -> 0 | AD5: SCHOOL YEAR | AG5: ='INPUT DATA'!F16 -> 0
A7: FOURTH QUARTER | F7: GRADE & SECTION: | K7: ='INPUT DATA'!F24&" - "&'INPUT DATA'!F25 -> - | Q7: TEACHER: | S7: ='INPUT DATA'!F22 -> 0 | AC7: SUBJECT: | AE7: =IF('INPUT DATA'!F30<>"",'INPUT DATA'!F30,'INPUT DATA'!F28) -> 0
Q8: SEMESTER: | S8: - - | AC8: SUBJECT TYPE: | AE8: ='INPUT DATA'!F26 -> 0
A9: LEARNERS' NAMES | F9: =IF('INPUT DATA'!$F$26="","",INDEX('Helper(IMPORTANT!)'!$CI$2:$CI$6,MATCH(AE8,'Helper(IMPORTANT!)'!$CH$2:$CH$6,0))) | S9: =IF('INPUT DATA'!$F$26="","",INDEX('Helper(IMPORTANT!)'!$CJ$2:$CJ$6,MATCH(AE8,'Helper(IMPORTANT!)'!$CH$2:$CH$6,0))) | AF9: =IF('INPUT DATA'!$F$26="","",INDEX('Helper(IMPORTANT!)'!$CK$2:$CK$6,MATCH(AE8,'Helper(IMPORTANT!)'!$CH$2:$CH$6,0))) | AI9: Initial Grade | AJ9: Quarterly Grade
F10: 1 | G10: 2 | H10: 3 | I10: 4 | J10: 5 | K10: 6 | L10: 7 | M10: 8 | N10: 9 | O10: 10 | P10: Total | Q10: PS | R10: WS | S10: 1 | T10: 2 | U10: 3 | V10: 4 | W10: 5 | X10: 6 | Y10: 7 | Z10: 8 | AA10: 9 | AB10: 10 | AC10: Total | AD10: PS | AE10: WS | AF10: 1 | AG10: PS | AH10: WS
A11: HIGHEST POSSIBLE SCORE | P11: =IF(COUNT($F11:$O11)=0,"",SUM($F11:$O11)) | Q11: 100 | R11: =IF('INPUT DATA'!$F$26="","",INDEX('Helper(IMPORTANT!)'!$CL$2:$CL$6,MATCH(AE8,'Helper(IMPORTANT!)'!$CH$2:$CH$6,0))) | AC11: =IF(COUNT($S11:$AB11)=0,"",SUM($S11:$AB11)) | AD11: 100 | AE11: =IF('INPUT DATA'!$F$26="","",INDEX('Helper(IMPORTANT!)'!$CM$2:$CM$6,MATCH(AE8,'Helper(IMPORTANT!)'!$CH$2:$CH$6,0))) | AG11: 100 | AH11: =IF('INPUT DATA'!$F$26="","",INDEX('Helper(IMPORTANT!)'!$CN$2:$CN$6,MATCH(AE8,'Helper(IMPORTANT!)'!$CH$2:$CH$6,0)))
A12: MALE
