Workbook
Name TRANSMUTATION_TABLE: 'DO NOT DELETE'!$G$2:$J$42

Sheet INPUT DATA
A1: Input Data Sheet for E-Class Record
C4: REGION | L4: DIVISION
B5: SCHOOL NAME | G5: ARMS DEMO NATIONAL HIGH SCHOOL | T5: SCHOOL ID | X5: DEMO-ARMS | AD5: SCHOOL YEAR | AG5: 2026-2027
A7: SECOND QUARTER | F7: GRADE & SECTION: | K7: GRADE 7 - ILANG-ILANG | Q7: TEACHER: | S7: JOSELITO RAMOS | AC7: SUBJECT: | AG7: MAPEH
B8: LEARNERS' NAMES
B11: MALE | AK11: LRN (do not edit)
A12: 1 | B12: BAUTISTA, KYLE Z. | C12: 0 | D12: 0 | E12: 0 | AK12: 999911000001
A13: 2 | B13: FLORES, JEROME C. | C13: 0 | D13: 0 | E13: 0 | AK13: 999911000002
A14: 3 | B14: GONZALES, FRANCIS L. | C14: 0 | D14: 0 | E14: 0 | AK14: 999911000003
A15: 4 | B15: IGNACIO, CHRISTIAN D. | C15: 0 | D15: 0 | E15: 0 | AK15: 999911000004
A16: 5 | B16: LUMAPAS, JERICHO T. | C16: 0 | D16: 0 | E16: 0 | AK16: 999911000005
A17: 6 | B17: MENDOZA, EMMANUEL R. | C17: 0 | D17: 0 | E17: 0 | AK17: 999911000006
A18: 7 | B18: MENDOZA, JUAN MIGUEL O. | C18: 0 | D18: 0 | E18: 0 | AK18: 999911000007
A19: 8 | B19: MORALES, KYLE P. | C19: 0 | D19: 0 | E19: 0 | AK19: 999911000008
A20: 9 | B20: NAVARRO, MARK ANTHONY T. | C20: 0 | D20: 0 | E20: 0 | AK20: 999911000009
A21: 10 | B21: OCAMPO JR., CHRISTIAN U. | C21: 0 | D21: 0 | E21: 0 | AK21: 999911000010
A22: 11 | B22: PANGANIBAN, DOMINIC C. | C22: 0 | D22: 0 | E22: 0 | AK22: 999911000011
A23: 12 | B23: RAMOS, FRANCIS H. | C23: 0 | D23: 0 | E23: 0 | AK23: 999911000012
... A31: 20 | B31: YBANEZ, JOSHUA V. | C31: 0 | D31: 0 | E31: 0 | AK31: 999911000020
A32: 21 | C32: 0 | D32: 0 | E32: 0
A33: 22 | C33: 0 | D33: 0 | E33: 0
A34: 23 | C34: 0 | D34: 0 | E34: 0
A35: 24 | C35: 0 | D35: 0 | E35: 0
A36: 25 | C36: 0 | D36: 0 | E36: 0
A37: 26 | C37: 0 | D37: 0 | E37: 0
A38: 27 | C38: 0 | D38: 0 | E38: 0
A39: 28 | C39: 0 | D39: 0 | E39: 0
A40: 29 | C40: 0 | D40: 0 | E40: 0
A41: 30 | C41: 0 | D41: 0 | E41: 0
A42: 31 | C42: 0 | D42: 0 | E42: 0
A43: 32 | C43: 0 | D43: 0 | E43: 0
... A61: 50 | C61: 0 | D61: 0 | E61: 0
B62: FEMALE
A63: 1 | B63: AQUINO, ANGELICA U. | C63: 0 | D63: 0 | E63: 0 | AK63: 999911000021
A64: 2 | B64: BAUTISTA, MARIA CLARA I. | C64: 0 | D64: 0 | E64: 0 | AK64: 999911000022
A65: 3 | B65: DELA CRUZ, KATHLEEN K. | C65: 0 | D65: 0 | E65: 0 | AK65: 999911000023
A66: 4 | B66: DIMACULANGAN, ELLAINE O. | C66: 0 | D66: 0 | E66: 0 | AK66: 999911000024
A67: 5 | B67: DIMACULANGAN, TRISHA S. | C67: 0 | D67: 0 | E67: 0 | AK67: 999911000025
A68: 6 | B68: FERNANDEZ, JILLIAN V. | C68: 0 | D68: 0 | E68: 0 | AK68: 999911000026
A69: 7 | B69: GONZALES, MIKAELA C. | C69: 0 | D69: 0 | E69: 0 | AK69: 999911000027
...

Sheet MUSIC _Q2
A1: Class Record
A3: (Pursuant to Deped Order 8 series of 2015)
C4: REGION | G4: ='INPUT DATA'!G4 -> 0 | L4: DIVISION | O4: ='INPUT DATA'!O4 -> 0
B5: SCHOOL NAME | G5: ='INPUT DATA'!G5 -> ARMS DEMO NATIONAL HIGH SCHOOL | T5: SCHOOL ID | X5: ='[1]INPUT DATA'!X5 -> 0 | AD5: SCHOOL YEAR | AG5: ='INPUT DATA'!AG5 -> 2026-2027
A7: SECOND QUARTER | F7: GRADE & SECTION: | K7: ='INPUT DATA'!K7 -> GRADE 7 - ILANG-ILANG | Q7: TEACHER: | S7: ='INPUT DATA'!S7 -> JOSELITO RAMOS | AC7: SUBJECT: | AG7: MUSIC
B8: LEARNERS' NAMES | F8: WRITTEN WORKS (20%) | S8: PERFORMANCE TASKS (60%) | AF8: QUARTERLY ASSESSMENT (20%) | AI8: Initial | AJ8: Quarterly
F9: 1 | G9: 2 | H9: 3 | I9: 4 | J9: 5 | K9: 6 | L9: 7 | M9: 8 | N9: 9 | O9: 10 | P9: Total | Q9: PS | R9: WS | S9: 1 | T9: 2 | U9: 3 | V9: 4 | W9: 5 | X9: 6 | Y9: 7 | Z9: 8 | AA9: 9 | AB9: 10 | AC9: Total | AD9: PS | AE9: WS | AF9: 1 | AG9: PS | AH9: WS | AI9: Grade | AJ9: Grade
B10: HIGHEST POSSIBLE SCORE | F10: 10 | G10: 15 | H10: 10 | P10: =IF(COUNT($F10:$O10)=0,"",SUM($F10:$O10)) -> 35 | Q10: 100 | R10: 0.2 | S10: 40 | T10: 50 | U10: 30 | AC10: =IF(COUNT($S10:$AB10)=0,"",SUM($S10:$AB10)) -> 120 | AD10: 100 | AE10: 0.6 | AF10: 40 | AG10: 100 | AH10: 0.2
B11: MALE
A12: 1 | B12: ='INPUT DATA'!B12 -> BAUTISTA, KYLE Z. | F12: 7 | G12: 11 | H12: 7 | P12: =IF(COUNT($F12:$O12)=0,"",SUM($F12:$O12)) -> 25 | Q12: =IF(ISERROR(IF($P12="","",ROUND(($P12/$P$10)*$Q$10,2))),"",IF($P12="","",ROUND(($P12/$P$10)*$Q$10,2))) -> 71.43 | R12: =IF($Q12="","",ROUND($Q12*$R$10,2)) -> 14.29 | S12: 26 | T12: 34 | U12: 19 | AC12: =IF(COUNT($S12:$AB12)=0,"",SUM($S12:$AB12)) -> 79 | AD12: =IF(ISERROR(IF($AC12="","",ROUND(($AC12/$AC$10)*$AD$10,2))),"",IF($AC12="","",ROUND(($AC12/$AC$10)*$AD$10,2))) -> 65.83 | AE12: =IF($AD12="","",ROUND($AD12*$AE$10,2)) -> 39.5 | AF12: 27 | AG12: =IF(ISERROR(IF($AF12="","",ROUND(($AF12/$AF$10)*$AG$10,2))),"",IF($AF12="","",ROUND(($AF12/$AF$10)*$AG$10,2))) -> 67.5 | AH12: =IF($AG12="","",ROUND($AG12*$AH$10,2)) -> 13.5 | AI12: =IF(ISERROR(IF($AF12="","",ROUND(SUM($R12,$AE12,$AH12),2))),"",IF($AF12="","",ROUND(SUM($R12,$AE12,$AH12),2))) -> 67.29 | AJ12: =IF(ISERROR(IF($AF12="","",VLOOKUP(AI12,TRANSMUTATION_TABLE,4,TRUE))),"",IF($AF12="","",VLOOKUP(AI12,TRANSMUTATION_TABLE,4,TRUE))) -> 79
A13: 2 | B13: ='INPUT DATA'!B13 -> FLORES, JEROME C. | F13: 10 | G13: 14 | H13: 10 | P13: =IF(COUNT($F13:$O13)=0,"",SUM($F13:$O13)) -> 34 | Q13: =IF(ISERROR(IF($P13="","",ROUND(($P13/$P$10)*$Q$10,2))),"",IF($P13="","",ROUND(($P13/$P$10)*$Q$10,2))) -> 97.14 | R13: =IF($Q13="","",ROUND($Q13*$R$10,2)) -> 19.43 | S13: 33 | T13: 42 | U13: 29 | AC13: =IF(COUNT($S13:$AB13)=0,"",SUM($S13:$AB13)) -> 104 | AD13: =IF(ISERROR(IF($AC13="","",ROUND(($AC13/$AC$10)*$AD$10,2))),"",IF($AC13="","",ROUND(($AC13/$AC$10)*$AD$10,2))) -> 86.67 | AE13: =IF($AD13="","",ROUND($AD13*$AE$10,2)) -> 52 | AF13: 36 | AG13: =IF(ISERROR(IF($AF13="","",ROUND(($AF13/$AF$10)*$AG$10,2))),"",IF($AF13="","",ROUND(($AF13/$AF$10)*$AG$10,2))) -> 90 | AH13: =IF($AG13="","",ROUND($AG13*$AH$10,2)) -> 18 | AI13: =IF(ISERROR(IF($AF13="","",ROUND(SUM($R13,$AE13,$AH13),2))),"",IF($AF13="","",ROUND(SUM($R13,$AE13,$AH13),2))) -> 89.43 | AJ13: =IF(ISERROR(IF($AF13="","",VLOOKUP(AI13,TRANSMUTATION_TABLE,4,TRUE))),"",IF($AF13="","",VLOOKUP(AI13,TRANSMUTATION_TABLE,4,TRUE))) -> 93
A14: 3 | B14: ='INPUT DATA'!B14 -> GONZALES, FRANCIS L. | F14: 6 | G14: 10 | H14: 6 | P14: =IF(COUNT($F14:$O14)=0,"",SUM($F14:$O14)) -> 22 | Q14: =IF(ISERROR(IF($P14="","",ROUND(($P14/$P$10)*$Q$10,2))),"",IF($P14="","",ROUND(($P14/$P$10)*$Q$10,2))) -> 62.86 | R14: =IF($Q14="","",ROUND($Q14*$R$10,2)) -> 12.57 | S14: 24 | T14: 28 | U14: 21 | AC14: =IF(COUNT($S14:$AB14)=0,"",SUM($S14:$AB14)) -> 73 | AD14: =IF(ISERROR(IF($AC14="","",ROUND(($AC14/$AC$10)*$AD$10,2))),"",IF($AC14="","",ROUND(($AC14/$AC$10)*$AD$10,2))) -> 60.83 | AE14: =IF($AD14="","",ROUND($AD14*$AE$10,2)) -> 36.5 | AF14: 23 | AG14: =IF(ISERROR(IF($AF14="","",ROUND(($AF14/$AF$10)*$AG$10,2))),"",IF($AF14="","",ROUND(($AF14/$AF$10)*$AG$10,2))) -> 57.5 | AH14: =IF($AG14="","",ROUND($AG14*$AH$10,2)) -> 11.5 | AI14: =IF(ISERROR(IF($AF14="","",ROUND(SUM($R14,$AE14,$AH14),2))),"",IF($AF14="","",ROUND(SUM($R14,$AE14,$AH14),2))) -> 60.57 | AJ14: =IF(ISERROR(IF($AF14="","",VLOOKUP(AI14,TRANSMUTATION_TABLE,4,TRUE))),"",IF($AF14="","",VLOOKUP(AI14,TRANSMUTATION_TABLE,4,TRUE))) -> 75
A15: 4 | B15: ='INPUT DATA'!B15 -> IGNACIO, CHRISTIAN D. | F15: 6 | G15: 9 | H15: 6 | P15: =IF(COUNT($F15:$O15)=0,"",SUM($F15:$O15)) -> 21 | Q15: =IF(ISERROR(IF($P15="","",ROUND(($P15/$P$10)*$Q$10,2))),"",IF($P15="","",ROUND(($P15/$P$10)*$Q$10,2))) -> 60 | R15: =IF($Q15="","",ROUND($Q15*$R$10,2)) -> 12 | S15: 23 | T15: 34 | U15: 19 | AC15: =IF(COUNT($S15:$AB15)=0,"",SUM($S15:$AB15)) -> 76 | AD15: =IF(ISERROR(IF($AC15="","",ROUND(($AC15/$AC$10)*$AD$10,2))),"",IF($AC15="","",ROUND(($AC15/$AC$10)*$AD$10,2))) -> 63.33 | AE15: =IF($AD15="","",ROUND($AD15*$AE$10,2)) -> 38 | AF15: 26 | AG15: =IF(ISERROR(IF($AF15="","",ROUND(($AF15/$AF$10)*$AG$10,2))),"",IF($AF15="","",ROUND(($AF15/$AF$10)*$AG$10,2))) -> 65 | AH15: =IF($AG15="","",ROUND($AG15*$AH$10,2)) -> 13 | AI15: =IF(ISERROR(IF($AF15="","",ROUND(SUM($R15,$AE15,$AH15),2))),"",IF($AF15="","",ROUND(SUM($R15,$AE15,$AH15),2))) -> 63 | AJ15: =IF(ISERROR(IF($AF15="","",VLOOKUP(AI15,TRANSMUTATION_TABLE,4,TRUE))),"",IF($AF15="","",VLOOKUP(AI15,TRANSMUTATION_TABLE,4,TRUE))) -> 76
A16: 5 | B16: ='INPUT DATA'!B16 -> LUMAPAS, JERICHO T. | F16: 8 | G16: 12 | H16: 7 | P16: =IF(COUNT($F16:$O16)=0,"",SUM($F16:$O16)) -> 27 | Q16: =IF(ISERROR(IF($P16="","",ROUND(($P16/$P$10)*$Q$10,2))),"",IF($P16="","",ROUND(($P16/$P$10)*$Q$10,2))) -> 77.14 | R16: =IF($Q16="","",ROUND($Q16*$R$10,2)) -> 15.43 | S16: 32 | T16: 38 | U16: 25 | AC16: =IF(COUNT($S16:$AB16)=0,"",SUM($S16:$AB16)) -> 95 | AD16: =IF(ISERROR(IF($AC16="","",ROUND(($AC16/$AC$10)*$AD$10,2))),"",IF($AC16="","",ROUND(($AC16/$AC$10)*$AD$10,2))) -> 79.17 | AE16: =IF($AD16="","",ROUND($AD16*$AE$10,2)) -> 47.5 | AF16: 31 | AG16: =IF(ISERROR(IF($AF16="","",ROUND(($AF16/$AF$10)*$AG$10,2))),"",IF($AF16="","",ROUND(($AF16/$AF$10)*$AG$10,2))) -> 77.5 | AH16: =IF($AG16="","",ROUND($AG16*$AH$10,2)) -> 15.5 | AI16: =IF(ISERROR(IF($AF16="","",ROUND(SUM($R16,$AE16,$AH16),2))),"",IF($AF16="","",ROUND(SUM($R16,$AE16,$AH16),2))) -> 78.43 | AJ16: =IF(ISERROR(IF($AF16="","",VLOOKUP(AI16,TRANSMUTATION_TABLE,4,TRUE))),"",IF($AF16="","",VLOOKUP(AI16,TRANSMUTATION_TABLE,4,TRUE))) -> 86
A17: 6 | B17: ='INPUT DATA'!B17 -> MENDOZA, EMMANUEL R. | F17: 7 | G17: 11 | H17: 6 | P17: =IF(COUNT($F17:$O17)=0,"",SUM($F17:$O17)) -> 24 | Q17: =IF(ISERROR(IF($P17="","",ROUND(($P17/$P$10)*$Q$10,2))),"",IF($P17="","",ROUND(($P17/$P$10)*$Q$10,2))) -> 68.57 | R17: =IF($Q17="","",ROUND($Q17*$R$10,2)) -> 13.71 | S17: 28 | T17: 34 | U17: 18 | AC17: =IF(COUNT($S17:$AB17)=0,"",SUM($S17:$AB17)) -> 80 | AD17: =IF(ISERROR(IF($AC17="","",ROUND(($AC17/$AC$10)*$AD$10,2))),"",IF($AC17="","",ROUND(($AC17/$AC$10)*$AD$10,2))) -> 66.67 | AE17: =IF($AD17="","",ROUND($AD17*$AE$10,2)) -> 40 | AF17: 25 | AG17: =IF(ISERROR(IF($AF17="","",ROUND(($AF17/$AF$10)*$AG$10,2))),"",IF($AF17="","",ROUND(($AF17/$AF$10)*$AG$10,2))) -> 62.5 | AH17: =IF($AG17="","",ROUND($AG17*$AH$10,2)) -> 12.5 | AI17: =IF(ISERROR(IF($AF17="","",ROUND(SUM($R17,$AE17,$AH17),2))),"",IF($AF17="","",ROUND(SUM($R17,$AE17,$AH17),2))) -> 66.21 | AJ17: =IF(ISERROR(IF($AF17="","",VLOOKUP(AI17,TRANSMUTATION_TABLE,4,TRUE))),"",IF($AF17="","",VLOOKUP(AI17,TRANSMUTATION_TABLE,4,TRUE))) -> 78
A18: 7 | B18: ='INPUT DATA'!B18 -> MENDOZA, JUAN MIGUEL O. | F18: 7 | G18: 11 | H18: 8 | P18: =IF(COUNT($F18:$O18)=0,"",SUM($F18:$O18)) -> 26 | Q18: =IF(ISERROR(IF($P18="","",ROUND(($P18/$P$10)*$Q$10,2))),"",IF($P18="","",ROUND(($P18/$P$10)*$Q$10,2))) -> 74.29 | R18: =IF($Q18="","",ROUND($Q18*$R$10,2)) -> 14.86 | S18: 33 | T18: 37 | U18: 27 | AC18: =IF(COUNT($S18:$AB18)=0,"",SUM($S18:$AB18)) -> 97 | AD18: =IF(ISERROR(IF($AC18="","",ROUND(($AC18/$AC$10)*$AD$10,2))),"",IF($AC18="","",ROUND(($AC18/$AC$10)*$AD$10,2))) -> 80.83 | AE18: =IF($AD18="","",ROUND($AD18*$AE$10,2)) -> 48.5 | AF18: 36 | AG18: =IF(ISERROR(IF($AF18="","",ROUND(($AF18/$AF$10)*$AG$10,2))),"",IF($AF18="","",ROUND(($AF18/$AF$10)*$AG$10,2))) -> 90 | AH18: =IF($AG18="","",ROUND($AG18*$AH$10,2)) -> 18 | AI18: =IF(ISERROR(IF($AF18="","",ROUND(SUM($R18,$AE18,$AH18),2))),"",IF($AF18="","",ROUND(SUM($R18,$AE18,$AH18),2))) -> 81.36 | AJ18: =IF(ISERROR(IF($AF18="","",VLOOKUP(AI18,TRANSMUTATION_TABLE,4,TRUE))),"",IF($AF18="","",VLOOKUP(AI18,TRANSMUTATION_TABLE,4,TRUE))) -> 88
A19: 8 | B19: ='INPUT DATA'!B19 -> MORALES, KYLE P. | D19: 0 | F19: 9 | G19: 14 | H19: 9 | P19: =IF(COUNT($F19:$O19)=0,"",SUM($F19:$O19)) -> 32 | Q19: =IF(ISERROR(IF($P19="","",ROUND(($P19/$P$10)*$Q$10,2))),"",IF($P19="","",ROUND(($P19/$P$10)*$Q$10,2))) -> 91.43 | R19: =IF($Q19="","",ROUND($Q19*$R$10,2)) -> 18.29 | S19: 34 | T19: 41 | U19: 26 | AC19: =IF(COUNT($S19:$AB19)=0,"",SUM($S19:$AB19)) -> 101 | AD19: =IF(ISERROR(IF($AC19="","",ROUND(($AC19/$AC$10)*$AD$10,2))),"",IF($AC19="","",ROUND(($AC19/$AC$10)*$AD$10,2))) -> 84.17 | AE19: =IF($AD19="","",ROUND($AD19*$AE$10,2)) -> 50.5 | AF19: 36 | AG19: =IF(ISERROR(IF($AF19="","",ROUND(($AF19/$AF$10)*$AG$10,2))),"",IF($AF19="","",ROUND(($AF19/$AF$10)*$AG$10,2))) -> 90 | AH19: =IF($AG19="","",ROUND($AG19*$AH$10,2)) -> 18 | AI19: =IF(ISERROR(IF($AF19="","",ROUND(SUM($R19,$AE19,$AH19),2))),"",IF($AF19="","",ROUND(SUM($R19,$AE19,$AH19),2))) -> 86.79 | AJ19: =IF(ISERROR(IF($AF19="","",VLOOKUP(AI19,TRANSMUTATION_TABLE,4,TRUE))),"",IF($AF19="","",VLOOKUP(AI19,TRANSMUTATION_TABLE,4,TRUE))) -> 91
A20: 9 | B20: ='INPUT DATA'!B20 -> NAVARRO, MARK ANTHONY T. | F20: 9 | G20: 12 | H20: 8 | P20: =IF(COUNT($F20:$O20)=0,"",SUM($F20:$O20)) -> 29 | Q20: =IF(ISERROR(IF($P20="","",ROUND(($P20/$P$10)*$Q$10,2))),"",IF($P20="","",ROUND(($P20/$P$10)*$Q$10,2))) -> 82.86 | R20: =IF($Q20="","",ROUND($Q20*$R$10,2)) -> 16.57 | S20: 35 | T20: 43 | U20: 26 | AC20: =IF(COUNT($S20:$AB20)=0,"",SUM($S20:$AB20)) -> 104 | AD20: =IF(ISERROR(IF($AC20="","",ROUND(($AC20/$AC$10)*$AD$10,2))),"",IF($AC20="","",ROUND(($AC20/$AC$10)*$AD$10,2))) -> 86.67 | AE20: =IF($AD20="","",ROUND($AD20*$AE$10,2)) -> 52 | AF20: 38 | AG20: =IF(ISERROR(IF($AF20="","",ROUND(($AF20/$AF$10)*$AG$10,2))),"",IF($AF20="","",ROUND(($AF20/$AF$10)*$AG$10,2))) -> 95 | AH20: =IF($AG20="","",ROUND($AG20*$AH$10,2)) -> 19 | AI20: =IF(ISERROR(IF($AF20="","",ROUND(SUM($R20,$AE20,$AH20),2))),"",IF($AF20="","",ROUND(SUM($R20,$AE20,$AH20),2))) -> 87.57 | AJ20: =IF(ISERROR(IF($AF20="","",VLOOKUP(AI20,TRANSMUTATION_TABLE,4,TRUE))),"",IF($AF20="","",VLOOKUP(AI20,TRANSMUTATION_TABLE,4,TRUE))) -> 92
A21: 10 | B21: ='INPUT DATA'!B21 -> OCAMPO JR., CHRISTIAN U. | F21: 8 | G21: 13 | H21: 8 | P21: =IF(COUNT($F21:$O21)=0,"",SUM($F21:$O21)) -> 29 | Q21: =IF(ISERROR(IF($P21="","",ROUND(($P21/$P$10)*$Q$10,2))),"",IF($P21="","",ROUND(($P21/$P$10)*$Q$10,2))) -> 82.86 | R21: =IF($Q21="","",ROUND($Q21*$R$10,2)) -> 16.57 | S21: 31 | T21: 43 | U21: 24 | AC21: =IF(COUNT($S21:$AB21)=0,"",SUM($S21:$AB21)) -> 98 | AD21: =IF(ISERROR(IF($AC21="","",ROUND(($AC21/$AC$10)*$AD$10,2))),"",IF($AC21="","",ROUND(($AC21/$AC$10)*$AD$10,2))) -> 81.67 | AE21: =IF($AD21="","",ROUND($AD21*$AE$10,2)) -> 49 | AF21: 33 | AG21: =IF(ISERROR(IF($AF21="","",ROUND(($AF21/$AF$10)*$AG$10,2))),"",IF($AF21="","",ROUND(($AF21/$AF$10)*$AG$10,2))) -> 82.5 | AH21: =IF($AG21="","",ROUND($AG21*$AH$10,2)) -> 16.5 | AI21: =IF(ISERROR(IF($AF21="","",ROUND(SUM($R21,$AE21,$AH21),2))),"",IF($AF21="","",ROUND(SUM($R21,$AE21,$AH21),2))) -> 82.07 | AJ21: =IF(ISERROR(IF($AF21="","",VLOOKUP(AI21,TRANSMUTATION_TABLE,4,TRUE))),"",IF($AF21="","",VLOOKUP(AI21,TRANSMUTATION_TABLE,4,TRUE))) -> 88
A22: 11 | B22: ='INPUT DATA'!B22 -> PANGANIBAN, DOMINIC C. | D22: 0 | F22: 9 | G22: 12 | H22: 9 | P22: =IF(COUNT($F22:$O22)=0,"",SUM($F22:$O22)) -> 30 | Q22: =IF(ISERROR(IF($P22="","",ROUND(($P22/$P$10)*$Q$10,2))),"",IF($P22="","",ROUND(($P22/$P$10)*$Q$10,2))) -> 85.71 | R22: =IF($Q22="","",ROUND($Q22*$R$10,2)) -> 17.14 | S22: 33 | T22: 42 | U22: 23 | AC22: =IF(COUNT($S22:$AB22)=0,"",SUM($S22:$AB22)) -> 98 | AD22: =IF(ISERROR(IF($AC22="","",ROUND(($AC22/$AC$10)*$AD$10,2))),"",IF($AC22="","",ROUND(($AC22/$AC$10)*$AD$10,2))) -> 81.67 | AE22: =IF($AD22="","",ROUND($AD22*$AE$10,2)) -> 49 | AF22: 38 | AG22: =IF(ISERROR(IF($AF22="","",ROUND(($AF22/$AF$10)*$AG$10,2))),"",IF($AF22="","",ROUND(($AF22/$AF$10)*$AG$10,2))) -> 95 | AH22: =IF($AG22="","",ROUND($AG22*$AH$10,2)) -> 19 | AI22: =IF(ISERROR(IF($AF22="","",ROUND(SUM($R22,$AE22,$AH22),2))),"",IF($AF22="","",ROUND(SUM($R22,$AE22,$AH22),2))) -> 85.14 | AJ22: =IF(ISERROR(IF($AF22="","",VLOOKUP(AI22,TRANSMUTATION_TABLE,4,TRUE))),"",IF($AF22="","",VLOOKUP(AI22,TRANSMUTATION_TABLE,4,TRUE))) -> 90
A23: 12 | B23: ='INPUT DATA'!B23 -> RAMOS, FRANCIS H. | F23: 9 | G23: 13 | H23: 9 | P23: =IF(COUNT($F23:$O23)=0,"",SUM($F23:$O23)) -> 31 | Q23: =IF(ISERROR(IF($P23="","",ROUND(($P23/$P$10)*$Q$10,2))),"",IF($P23="","",ROUND(($P23/$P$10)*$Q$10,2))) -> 88.57 | R23: =IF($Q23="","",ROUND($Q23*$R$10,2)) -> 17.71 | S23: 36 | T23: 45 | U23: 27 | AC23: =IF(COUNT($S23:$AB23)=0,"",SUM($S23:$AB23)) -> 108 | AD23: =IF(ISERROR(IF($AC23="","",ROUND(($AC23/$AC$10)*$AD$10,2))),"",IF($AC23="","",ROUND(($AC23/$AC$10)*$AD$10,2))) -> 90 | AE23: =IF($AD23="","",ROUND($AD23*$AE$10,2)) -> 54 | AF23: 38 | AG23: =IF(ISERROR(IF($AF23="","",ROUND(($AF23/$AF$10)*$AG$10,2))),"",IF($AF23="","",ROUND(($AF23/$AF$10)*$AG$10,2))) -> 95 | AH23: =IF($AG23="","",ROUND($AG23*$AH$10,2)) -> 19 | AI23: =IF(ISERROR(IF($AF23="","",ROUND(SUM($R23,$AE23,$AH23),2))),"",IF($AF23="","",ROUND(SUM($R23,$AE23,$AH23),2))) -> 90.71 | AJ23: =IF(ISERROR(IF($AF23="","",VLOOKUP(AI23,TRANSMUTATION_TABLE,4,TRUE))),"",IF($AF23="","",VLOOKUP(AI23,TRANSMUTATION_TABLE,4,TRUE))) -> 94
A24: 13 | B24: ='INPUT DATA'!B24 -> RAMOS JR., KYLE R. | F24: 6 | G24: 10 | H24: 6 | P24: =IF(COUNT($F24:$O24)=0,"",SUM($F24:$O24)) -> 22 | Q24: =IF(ISERROR(IF($P24="","",ROUND(($P24/$P$10)*$Q$10,2))),"",IF($P24="","",ROUND(($P24/$P$10)*$Q$10,2))) -> 62.86 | R24: =IF($Q24="","",ROUND($Q24*$R$10,2)) -> 12.57 | S24: 27 | T24: 29 | U24: 21 | AC24: =IF(COUNT($S24:$AB24)=0,"",SUM($S24:$AB24)) -> 77 | AD24: =IF(ISERROR(IF($AC24="","",ROUND(($AC24/$AC$10)*$AD$10,2))),"",IF($AC24="","",ROUND(($AC24/$AC$10)*$AD$10,2))) -> 64.17 | AE24: =IF($AD24="","",ROUND($AD24*$AE$10,2)) -> 38.5 | AF24: 23 | AG24: =IF(ISERROR(IF($AF24="","",ROUND(($AF24/$AF$10)*$AG$10,2))),"",IF($AF24="","",ROUND(($AF24/$AF$10)*$AG$10,2))) -> 57.5 | AH24: =IF($AG24="","",ROUND($AG24*$AH$10,2)) -> 11.5 | AI24: =IF(ISERROR(IF($AF24="","",ROUND(SUM($R24,$AE24,$AH24),2))),"",IF($AF24="","",ROUND(SUM($R24,$AE24,$AH24),2))) -> 62.57 | AJ24: =IF(ISERROR(IF($AF24="","",VLOOKUP(AI24,TRANSMUTATION_TABLE,4,TRUE))),"",IF($AF24="","",VLOOKUP(AI24,TRANSMUTATION_TABLE,4,TRUE))) -> 76
A25: 14 | B25: ='INPUT DATA'!B25 -> SANTOS, KYLE A. | F25: 8 | G25: 12 | H25: 8 | P25: =IF(COUNT($F25:$O25)=0,"",SUM($F25:$O25)) -> 28 | Q25: =IF(ISERROR(IF($P25="","",ROUND(($P25/$P$10)*$Q$10,2))),"",IF($P25="","",ROUND(($P25/$P$10)*$Q$10,2))) -> 80 | R25: =IF($Q25="","",ROUND($Q25*$R$10,2)) -> 16 | S25: 31 | T25: 41 | U25: 21 | AC25: =IF(COUNT($S25:$AB25)=0,"",SUM($S25:$AB25)) -> 93 | AD25: =IF(ISERROR(IF($AC25="","",ROUND(($AC25/$AC$10)*$AD$10,2))),"",IF($AC25="","",ROUND(($AC25/$AC$10)*$AD$10,2))) -> 77.5 | AE25: =IF($AD25="","",ROUND($AD25*$AE$10,2)) -> 46.5 | AF25: 32 | AG25: =IF(ISERROR(IF($AF25="","",ROUND(($AF25/$AF$10)*$AG$10,2))),"",IF($AF25="","",ROUND(($AF25/$AF$10)*$AG$10,2))) -> 80 | AH25: =IF($AG25="","",ROUND($AG25*$AH$10,2)) -> 16 | AI25: =IF(ISERROR(IF($AF25="","",ROUND(SUM($R25,$AE25,$AH25),2))),"",IF($AF25="","",ROUND(SUM($R25,$AE25,$AH25),2))) -> 78.5 | AJ25: =IF(ISERROR(IF($AF25="","",VLOOKUP(AI25,TRANSMUTATION_TABLE,4,TRUE))),"",IF($AF25="","",VLOOKUP(AI25,TRANSMUTATION_TABLE,4,TRUE))) -> 86
A26: 15 | B26: ='INPUT DATA'!B26 -> TOLENTINO, CARLO O. | F26: 9 | G26: 14 | H26: 10 | P26: =IF(COUNT($F26:$O26)=0,"",SUM($F26:$O26)) -> 33 | Q26: =IF(ISERROR(IF($P26="","",ROUND(($P26/$P$10)*$Q$10,2))),"",IF($P26="","",ROUND(($P26/$P$10)*$Q$10,2))) -> 94.29 | R26: =IF($Q26="","",ROUND($Q26*$R$10,2)) -> 18.86 | S26: 40 | T26: 50 | U26: 27 | AC26: =IF(COUNT($S26:$AB26)=0,"",SUM($S26:$AB26)) -> 117 | AD26: =IF(ISERROR(IF($AC26="","",ROUND(($AC26/$AC$10)*$AD$10,2))),"",IF($AC26="","",ROUND(($AC26/$AC$10)*$AD$10,2))) -> 97.5 | AE26: =IF($AD26="","",ROUND($AD26*$AE$10,2)) -> 58.5 | AF26: 39 | AG26: =IF(ISERROR(IF($AF26="","",ROUND(($AF26/$AF$10)*$AG$10,2))),"",IF($AF26="","",ROUND(($AF26/$AF$10)*$AG$10,2))) -> 97.5 | AH26: =IF($AG26="","",ROUND($AG26*$AH$10,2)) -> 19.5 | AI26: =IF(ISERROR(IF($AF26="","",ROUND(SUM($R26,$AE26,$AH26),2))),"",IF($AF26="","",ROUND(SUM($R26,$AE26,$AH26),2))) -> 96.86 | AJ26: =IF(ISERROR(IF($AF26="","",VLOOKUP(AI26,TRANSMUTATION_TABLE,4,TRUE))),"",IF($AF26="","",VLOOKUP(AI26,TRANSMUTATION_TABLE,4,TRUE))) -> 98
A27: 16 | B27: ='INPUT DATA'!B27 -> TOLENTINO, JEROME H. | F27: 7 | G27: 11 | H27: 6 | P27: =IF(COUNT($F27:$O27)=0,"",SUM($F27:$O27)) -> 24 | Q27: =IF(ISERROR(IF($P27="","",ROUND(($P27/$P$10)*$Q$10,2))),"",IF($P27="","",ROUND(($P27/$P$10)*$Q$10,2))) -> 68.57 | R27: =IF($Q27="","",ROUND($Q27*$R$10,2)) -> 13.71 | S27: 26 | T27: 37 | U27: 21 | AC27: =IF(COUNT($S27:$AB27)=0,"",SUM($S27:$AB27)) -> 84 | AD27: =IF(ISERROR(IF($AC27="","",ROUND(($AC27/$AC$10)*$AD$10,2))),"",IF($AC27="","",ROUND(($AC27/$AC$10)*$AD$10,2))) -> 70 | AE27: =IF($AD27="","",ROUND($AD27*$AE$10,2)) -> 42 | AF27: 28 | AG27: =IF(ISERROR(IF($AF27="","",ROUND(($AF27/$AF$10)*$AG$10,2))),"",IF($AF27="","",ROUND(($AF27/$AF$10)*$AG$10,2))) -> 70 | AH27: =IF($AG27="","",ROUND($AG27*$AH$10,2)) -> 14 | AI27: =IF(ISERROR(IF($AF27="","",ROUND(SUM($R27,$AE27,$AH27),2))),"",IF($AF27="","",ROUND(SUM($R27,$AE27,$AH27),2))) -> 69.71 | AJ27: =IF(ISERROR(IF($AF27="","",VLOOKUP(AI27,TRANSMUTATION_TABLE,4,TRUE))),"",IF($AF27="","",VLOOKUP(AI27,TRANSMUTATION_TABLE,4,TRUE))) -> 81
A28: 17 | B28: ='INPUT DATA'!B28 -> TORRES, EMMANUEL A. | F28: 10 | G28: 13 | H28: 9 | P28: =IF(COUNT($F28:$O28)=0,"",SUM($F28:$O28)) -> 32 | Q28: =IF(ISERROR(IF($P28="","",ROUND(($P28/$P$10)*$Q$10,2))),"",IF($P28="","",ROUND(($P28/$P$10)*$Q$10,2))) -> 91.43 | R28: =IF($Q28="","",ROUND($Q28*$R$10,2)) -> 18.29 | S28: 32 | T28: 45 | U28: 24 | AC28: =IF(COUNT($S28:$AB28)=0,"",SUM($S28:$AB28)) -> 101 | AD28: =IF(ISERROR(IF($AC28="","",ROUND(($AC28/$AC$10)*$AD$10,2))),"",IF($AC28="","",ROUND(($AC28/$AC$10)*$AD$10,2))) -> 84.17 | AE28: =IF($AD28="","",ROUND($AD28*$AE$10,2)) -> 50.5 | AF28: 34 | AG28: =IF(ISERROR(IF($AF28="","",ROUND(($AF28/$AF$10)*$AG$10,2))),"",IF($AF28="","",ROUND(($AF28/$AF$10)*$AG$10,2))) -> 85 | AH28: =IF($AG28="","",ROUND($AG28*$AH$10,2)) -> 17 | AI28: =IF(ISERROR(IF($AF28="","",ROUND(SUM($R28,$AE28,$AH28),2))),"",IF($AF28="","",ROUND(SUM($R28,$AE28,$AH28),2))) -> 85.79 | AJ28: =IF(ISERROR(IF($AF28="","",VLOOKUP(AI28,TRANSMUTATION_TABLE,4,TRUE))),"",IF($AF28="","",VLOOKUP(AI28,TRANSMUTATION_TABLE,4,TRUE))) -> 91
A29: 18 | B29: ='INPUT DATA'!B29 -> VILLANUEVA, BENEDICT Q. | F29: 7 | G29: 11 | H29: 8 | P29: =IF(COUNT($F29:$O29)=0,"",SUM($F29:$O29)) -> 26 | Q29: =IF(ISERROR(IF($P29="","",ROUND(($P29/$P$10)*$Q$10,2))),"",IF($P29="","",ROUND(($P29/$P$10)*$Q$10,2))) -> 74.29 | R29: =IF($Q29="","",ROUND($Q29*$R$10,2)) -> 14.86 | S29: 30 | T29: 35 | U29: 24 | AC29: =IF(COUNT($S29:$AB29)=0,"",SUM($S29:$AB29)) -> 89 | AD29: =IF(ISERROR(IF($AC29="","",ROUND(($AC29/$AC$10)*$AD$10,2))),"",IF($AC29="","",ROUND(($AC29/$AC$10)*$AD$10,2))) -> 74.17 | AE29: =IF($AD29="","",ROUND($AD29*$AE$10,2)) -> 44.5 | AF29: 33 | AG29: =IF(ISERROR(IF($AF29="","",ROUND(($AF29/$AF$10)*$AG$10,2))),"",IF($AF29="","",ROUND(($AF29/$AF$10)*$AG$10,2))) -> 82.5 | AH29: =IF($AG29="","",ROUND($AG29*$AH$10,2)) -> 16.5 | AI29: =IF(ISERROR(IF($AF29="","",ROUND(SUM($R29,$AE29,$AH29),2))),"",IF($AF29="","",ROUND(SUM($R29,$AE29,$AH29),2))) -> 75.86 | AJ29: =IF(ISERROR(IF($AF29="","",VLOOKUP(AI29,TRANSMUTATION_TABLE,4,TRUE))),"",IF($AF29="","",VLOOKUP(AI29,TRANSMUTATION_TABLE,4,TRUE))) -> 84
A30: 19 | B30: ='INPUT DATA'!B30 -> VILLANUEVA, NATHANIEL P. | F30: 7 | G30: 12 | H30: 8 | P30: =IF(COUNT($F30:$O30)=0,"",SUM($F30:$O30)) -> 27 | Q30: =IF(ISERROR(IF($P30="","",ROUND(($P30/$P$10)*$Q$10,2))),"",IF($P30="","",ROUND(($P30/$P$10)*$Q$10,2))) -> 77.14 | R30: =IF($Q30="","",ROUND($Q30*$R$10,2)) -> 15.43 | S30: 28 | T30: 36 | U30: 20 | AC30: =IF(COUNT($S30:$AB30)=0,"",SUM($S30:$AB30)) -> 84 | AD30: =IF(ISERROR(IF($AC30="","",ROUND(($AC30/$AC$10)*$AD$10,2))),"",IF($AC30="","",ROUND(($AC30/$AC$10)*$AD$10,2))) -> 70 | AE30: =IF($AD30="","",ROUND($AD30*$AE$10,2)) -> 42 | AF30: 26 | AG30: =IF(ISERROR(IF($AF30="","",ROUND(($AF30/$AF$10)*$AG$10,2))),"",IF($AF30="","",ROUND(($AF30/$AF$10)*$AG$10,2))) -> 65 | AH30: =IF($AG30="","",ROUND($AG30*$AH$10,2)) -> 13 | AI30: =IF(ISERROR(IF($AF30="","",ROUND(SUM($R30,$AE30,$AH30),2))),"",IF($AF30="","",ROUND(SUM($R30,$AE30,$AH30),2))) -> 70.43 | AJ30: =IF(ISERROR(IF($AF30="","",VLOOKUP(AI30,TRANSMUTATION_TABLE,4,TRUE))),"",IF($AF30="","",VLOOKUP(AI30,TRANSMUTATION_TABLE,4,TRUE))) -> 81
A31: 20 | B31: ='INPUT DATA'!B31 -> YBANEZ, JOSHUA V. | F31: 7 | G31: 8 | H31: 6 | P31: =IF(COUNT($F31:$O31)=0,"",SUM($F31:$O31)) -> 21 | Q31: =IF(ISERROR(IF($P31="","",ROUND(($P31/$P$10)*$Q$10,2))),"",IF($P31="","",ROUND(($P31/$P$10)*$Q$10,2))) -> 60 | R31: =IF($Q31="","",ROUND($Q31*$R$10,2)) -> 12 | S31: 24 | T31: 34 | U31: 19 | AC31: =IF(COUNT($S31:$AB31)=0,"",SUM($S31:$AB31)) -> 77 | AD31: =IF(ISERROR(IF($AC31="","",ROUND(($AC31/$AC$10)*$AD$10,2))),"",IF($AC31="","",ROUND(($AC31/$AC$10)*$AD$10,2))) -> 64.17 | AE31: =IF($AD31="","",ROUND($AD31*$AE$10,2)) -> 38.5 | AF31: 27 | AG31: =IF(ISERROR(IF($AF31="","",ROUND(($AF31/$AF$10)*$AG$10,2))),"",IF($AF31="","",ROUND(($AF31/$AF$10)*$AG$10,2))) -> 67.5 | AH31: =IF($AG31="","",ROUND($AG31*$AH$10,2)) -> 13.5 | AI31: =IF(ISERROR(IF($AF31="","",ROUND(SUM($R31,$AE31,$AH31),2))),"",IF($AF31="","",ROUND(SUM($R31,$AE31,$AH31),2))) -> 64 | AJ31: =IF(ISERROR(IF($AF31="","",VLOOKUP(AI31,TRANSMUTATION_TABLE,4,TRUE))),"",IF($AF31="","",VLOOKUP(AI31,TRANSMUTATION_TABLE,4,TRUE))) -> 77
A32: 21 | B32: ='INPUT DATA'!B32 -> 0 | P32: =IF(COUNT($F32:$O32)=0,"",SUM($F32:$O32)) | Q32: =IF(ISERROR(IF($P32="","",ROUND(($P32/$P$10)*$Q$10,2))),"",IF($P32="","",ROUND(($P32/$P$10)*$Q$10,2))) | R32: =IF($Q32="","",ROUND($Q32*$R$10,2)) | AC32: =IF(COUNT($S32:$AB32)=0,"",SUM($S32:$AB32)) | AD32: =IF(ISERROR(IF($AC32="","",ROUND(($AC32/$AC$10)*$AD$10,2))),"",IF($AC32="","",ROUND(($AC32/$AC$10)*$AD$10,2))) | AE32: =IF($AD32="","",ROUND($AD32*$AE$10,2)) | AG32: =IF(ISERROR(IF($AF32="","",ROUND(($AF32/$AF$10)*$AG$10,2))),"",IF($AF32="","",ROUND(($AF32/$AF$10)*$AG$10,2))) | AH32: =IF($AG32="","",ROUND($AG32*$AH$10,2)) | AI32: =IF(ISERROR(IF($AF32="","",ROUND(SUM($R32,$AE32,$AH32),2))),"",IF($AF32="","",ROUND(SUM($R32,$AE32,$AH32),2))) | AJ32: =IF(ISERROR(IF($AF32="","",VLOOKUP(AI32,TRANSMUTATION_TABLE,4,TRUE))),"",IF($AF32="","",VLOOKUP(AI32,TRANSMUTATION_TABLE,4,TRUE)))
A33: 22 | B33: ='INPUT DATA'!B33 -> 0 | P33: =IF(COUNT($F33:$O33)=0,"",SUM($F33:$O33)) | Q33: =IF(ISERROR(IF($P33="","",ROUND(($P33/$P$10)*$Q$10,2))),"",IF($P33="","",ROUND(($P33/$P$10)*$Q$10,2))) | R33: =IF($Q33="","",ROUND($Q33*$R$10,2)) | AC33: =IF(COUNT($S33:$AB33)=0,"",SUM($S33:$AB33)) | AD33: =IF(ISERROR(IF($AC33="","",ROUND(($AC33/$AC$10)*$AD$10,2))),"",IF($AC33="","",ROUND(($AC33/$AC$10)*$AD$10,2))) | AE33: =IF($AD33="","",ROUND($AD33*$AE$10,2)) | AG33: =IF(ISERROR(IF($AF33="","",ROUND(($AF33/$AF$10)*$AG$10,2))),"",IF($AF33="","",ROUND(($AF33/$AF$10)*$AG$10,2))) | AH33: =IF($AG33="","",ROUND($AG33*$AH$10,2)) | AI33: =IF(ISERROR(IF($AF33="","",ROUND(SUM($R33,$AE33,$AH33),2))),"",IF($AF33="","",ROUND(SUM($R33,$AE33,$AH33),2))) | AJ33: =IF(ISERROR(IF($AF33="","",VLOOKUP(AI33,TRANSMUTATION_TABLE,4,TRUE))),"",IF($AF33="","",VLOOKUP(AI33,TRANSMUTATION_TABLE,4,TRUE)))
A34: 23 | B34: ='INPUT DATA'!B34 -> 0 | P34: =IF(COUNT($F34:$O34)=0,"",SUM($F34:$O34)) | Q34: =IF(ISERROR(IF($P34="","",ROUND(($P34/$P$10)*$Q$10,2))),"",IF($P34="","",ROUND(($P34/$P$10)*$Q$10,2))) | R34: =IF($Q34="","",ROUND($Q34*$R$10,2)) | AC34: =IF(COUNT($S34:$AB34)=0,"",SUM($S34:$AB34)) | AD34: =IF(ISERROR(IF($AC34="","",ROUND(($AC34/$AC$10)*$AD$10,2))),"",IF($AC34="","",ROUND(($AC34/$AC$10)*$AD$10,2))) | AE34: =IF($AD34="","",ROUND($AD34*$AE$10,2)) | AG34: =IF(ISERROR(IF($AF34="","",ROUND(($AF34/$AF$10)*$AG$10,2))),"",IF($AF34="","",ROUND(($AF34/$AF$10)*$AG$10,2))) | AH34: =IF($AG34="","",ROUND($AG34*$AH$10,2)) | AI34: =IF(ISERROR(IF($AF34="","",ROUND(SUM($R34,$AE34,$AH34),2))),"",IF($AF34="","",ROUND(SUM($R34,$AE34,$AH34),2))) | AJ34: =IF(ISERROR(IF($AF34="","",VLOOKUP(AI34,TRANSMUTATION_TABLE,4,TRUE))),"",IF($AF34="","",VLOOKUP(AI34,TRANSMUTATION_TABLE,4,TRUE)))
A35: 24 | B35: ='INPUT DATA'!B35 -> 0 | P35: =IF(COUNT($F35:$O35)=0,"",SUM($F35:$O35)) | Q35: =IF(ISERROR(IF($P35="","",ROUND(($P35/$P$10)*$Q$10,2))),"",IF($P35="","",ROUND(($P35/$P$10)*$Q$10,2))) | R35: =IF($Q35="","",ROUND($Q35*$R$10,2)) | AC35: =IF(COUNT($S35:$AB35)=0,"",SUM($S35:$AB35)) | AD35: =IF(ISERROR(IF($AC35="","",ROUND(($AC35/$AC$10)*$AD$10,2))),"",IF($AC35="","",ROUND(($AC35/$AC$10)*$AD$10,2))) | AE35: =IF($AD35="","",ROUND($AD35*$AE$10,2)) | AG35: =IF(ISERROR(IF($AF35="","",ROUND(($AF35/$AF$10)*$AG$10,2))),"",IF($AF35="","",ROUND(($AF35/$AF$10)*$AG$10,2))) | AH35: =IF($AG35="","",ROUND($AG35*$AH$10,2)) | AI35: =IF(ISERROR(IF($AF35="","",ROUND(SUM($R35,$AE35,$AH35),2))),"",IF($AF35="","",ROUND(SUM($R35,$AE35,$AH35),2))) | AJ35: =IF(ISERROR(IF($AF35="","",VLOOKUP(AI35,TRANSMUTATION_TABLE,4,TRUE))),"",IF($AF35="","",VLOOKUP(AI35,TRANSMUTATION_TABLE,4,TRUE)))
A36: 25 | B36: ='INPUT DATA'!B36 -> 0 | P36: =IF(COUNT($F36:$O36)=0,"",SUM($F36:$O36)) | Q36: =IF(ISERROR(IF($P36="","",ROUND(($P36/$P$10)*$Q$10,2))),"",IF($P36="","",ROUND(($P36/$P$10)*$Q$10,2))) | R36: =IF($Q36="","",ROUND($Q36*$R$10,2)) | AC36: =IF(COUNT($S36:$AB36)=0,"",SUM($S36:$AB36)) | AD36: =IF(ISERROR(IF($AC36="","",ROUND(($AC36/$AC$10)*$AD$10,2))),"",IF($AC36="","",ROUND(($AC36/$AC$10)*$AD$10,2))) | AE36: =IF($AD36="","",ROUND($AD36*$AE$10,2)) | AG36: =IF(ISERROR(IF($AF36="","",ROUND(($AF36/$AF$10)*$AG$10,2))),"",IF($AF36="","",ROUND(($AF36/$AF$10)*$AG$10,2))) | AH36: =IF($AG36="","",ROUND($AG36*$AH$10,2)) | AI36: =IF(ISERROR(IF($AF36="","",ROUND(SUM($R36,$AE36,$AH36),2))),"",IF($AF36="","",ROUND(SUM($R36,$AE36,$AH36),2))) | AJ36: =IF(ISERROR(IF($AF36="","",VLOOKUP(AI36,TRANSMUTATION_TABLE,4,TRUE))),"",IF($AF36="","",VLOOKUP(AI36,TRANSMUTATION_TABLE,4,TRUE)))
A37: 26 | B37: ='INPUT DATA'!B37 -> 0 | P37: =IF(COUNT($F37:$O37)=0,"",SUM($F37:$O37)) | Q37: =IF(ISERROR(IF($P37="","",ROUND(($P37/$P$10)*$Q$10,2))),"",IF($P37="","",ROUND(($P37/$P$10)*$Q$10,2))) | R37: =IF($Q37="","",ROUND($Q37*$R$10,2)) | AC37: =IF(COUNT($S37:$AB37)=0,"",SUM($S37:$AB37)) | AD37: =IF(ISERROR(IF($AC37="","",ROUND(($AC37/$AC$10)*$AD$10,2))),"",IF($AC37="","",ROUND(($AC37/$AC$10)*$AD$10,2))) | AE37: =IF($AD37="","",ROUND($AD37*$AE$10,2)) | AG37: =IF(ISERROR(IF($AF37="","",ROUND(($AF37/$AF$10)*$AG$10,2))),"",IF($AF37="","",ROUND(($AF37/$AF$10)*$AG$10,2))) | AH37: =IF($AG37="","",ROUND($AG37*$AH$10,2)) | AI37: =IF(ISERROR(IF($AF37="","",ROUND(SUM($R37,$AE37,$AH37),2))),"",IF($AF37="","",ROUND(SUM($R37,$AE37,$AH37),2))) | AJ37: =IF(ISERROR(IF($AF37="","",VLOOKUP(AI37,TRANSMUTATION_TABLE,4,TRUE))),"",IF($AF37="","",VLOOKUP(AI37,TRANSMUTATION_TABLE,4,TRUE)))
A38: 27 | B38: ='INPUT DATA'!B38 -> 0 | P38: =IF(COUNT($F38:$O38)=0,"",SUM($F38:$O38)) | Q38: =IF(ISERROR(IF($P38="","",ROUND(($P38/$P$10)*$Q$10,2))),"",IF($P38="","",ROUND(($P38/$P$10)*$Q$10,2))) | R38: =IF($Q38="","",ROUND($Q38*$R$10,2)) | AC38: =IF(COUNT($S38:$AB38)=0,"",SUM($S38:$AB38)) | AD38: =IF(ISERROR(IF($AC38="","",ROUND(($AC38/$AC$10)*$AD$10,2))),"",IF($AC38="","",ROUND(($AC38/$AC$10)*$AD$10,2))) | AE38: =IF($AD38="","",ROUND($AD38*$AE$10,2)) | AG38: =IF(ISERROR(IF($AF38="","",ROUND(($AF38/$AF$10)*$AG$10,2))),"",IF($AF38="","",ROUND(($AF38/$AF$10)*$AG$10,2))) | AH38: =IF($AG38="","",ROUND($AG38*$AH$10,2)) | AI38: =IF(ISERROR(IF($AF38="","",ROUND(SUM($R38,$AE38,$AH38),2))),"",IF($AF38="","",ROUND(SUM($R38,$AE38,$AH38),2))) | AJ38: =IF(ISERROR(IF($AF38="","",VLOOKUP(AI38,TRANSMUTATION_TABLE,4,TRUE))),"",IF($AF38="","",VLOOKUP(AI38,TRANSMUTATION_TABLE,4,TRUE)))
A39: 28 | B39: ='INPUT DATA'!B39 -> 0 | P39: =IF(COUNT($F39:$O39)=0,"",SUM($F39:$O39)) | Q39: =IF(ISERROR(IF($P39="","",ROUND(($P39/$P$10)*$Q$10,2))),"",IF($P39="","",ROUND(($P39/$P$10)*$Q$10,2))) | R39: =IF($Q39="","",ROUND($Q39*$R$10,2)) | AC39: =IF(COUNT($S39:$AB39)=0,"",SUM($S39:$AB39)) | AD39: =IF(ISERROR(IF($AC39="","",ROUND(($AC39/$AC$10)*$AD$10,2))),"",IF($AC39="","",ROUND(($AC39/$AC$10)*$AD$10,2))) | AE39: =IF($AD39="","",ROUND($AD39*$AE$10,2)) | AG39: =IF(ISERROR(IF($AF39="","",ROUND(($AF39/$AF$10)*$AG$10,2))),"",IF($AF39="","",ROUND(($AF39/$AF$10)*$AG$10,2))) | AH39: =IF($AG39="","",ROUND($AG39*$AH$10,2)) | AI39: =IF(ISERROR(IF($AF39="","",ROUND(SUM($R39,$AE39,$AH39),2))),"",IF($AF39="","",ROUND(SUM($R39,$AE39,$AH39),2))) | AJ39: =IF(ISERROR(IF($AF39="","",VLOOKUP(AI39,TRANSMUTATION_TABLE,4,TRUE))),"",IF($AF39="","",VLOOKUP(AI39,TRANSMUTATION_TABLE,4,TRUE)))
A40: 29 | B40: ='INPUT DATA'!B40 -> 0 | P40: =IF(COUNT($F40:$O40)=0,"",SUM($F40:$O40)) | Q40: =IF(ISERROR(IF($P40="","",ROUND(($P40/$P$10)*$Q$10,2))),"",IF($P40="","",ROUND(($P40/$P$10)*$Q$10,2))) | R40: =IF($Q40="","",ROUND($Q40*$R$10,2)) | AC40: =IF(COUNT($S40:$AB40)=0,"",SUM($S40:$AB40)) | AD40: =IF(ISERROR(IF($AC40="","",ROUND(($AC40/$AC$10)*$AD$10,2))),"",IF($AC40="","",ROUND(($AC40/$AC$10)*$AD$10,2))) | AE40: =IF($AD40="","",ROUND($AD40*$AE$10,2)) | AG40: =IF(ISERROR(IF($AF40="","",ROUND(($AF40/$AF$10)*$AG$10,2))),"",IF($AF40="","",ROUND(($AF40/$AF$10)*$AG$10,2))) | AH40: =IF($AG40="","",ROUND($AG40*$AH$10,2)) | AI40: =IF(ISERROR(IF($AF40="","",ROUND(SUM($R40,$AE40,$AH40),2))),"",IF($AF40="","",ROUND(SUM($R40,$AE40,$AH40),2))) | AJ40: =IF(ISERROR(IF($AF40="","",VLOOKUP(AI40,TRANSMUTATION_TABLE,4,TRUE))),"",IF($AF40="","",VLOOKUP(AI40,TRANSMUTATION_TABLE,4,TRUE)))
A41: 30 | B41: ='INPUT DATA'!B41 -> 0 | P41: =IF(COUNT($F41:$O41)=0,"",SUM($F41:$O41)) | Q41: =IF(ISERROR(IF($P41="","",ROUND(($P41/$P$10)*$Q$10,2))),"",IF($P41="","",ROUND(($P41/$P$10)*$Q$10,2))) | R41: =IF($Q41="","",ROUND($Q41*$R$10,2)) | AC41: =IF(COUNT($S41:$AB41)=0,"",SUM($S41:$AB41)) | AD41: =IF(ISERROR(IF($AC41="","",ROUND(($AC41/$AC$10)*$AD$10,2))),"",IF($AC41="","",ROUND(($AC41/$AC$10)*$AD$10,2))) | AE41: =IF($AD41="","",ROUND($AD41*$AE$10,2)) | AG41: =IF(ISERROR(IF($AF41="","",ROUND(($AF41/$AF$10)*$AG$10,2))),"",IF($AF41="","",ROUND(($AF41/$AF$10)*$AG$10,2))) | AH41: =IF($AG41="","",ROUND($AG41*$AH$10,2)) | AI41: =IF(ISERROR(IF($AF41="","",ROUND(SUM($R41,$AE41,$AH41),2))),"",IF($AF41="","",ROUND(SUM($R41,$AE41,$AH41),2))) | AJ41: =IF(ISERROR(IF($AF41="","",VLOOKUP(AI41,TRANSMUTATION_TABLE,4,TRUE))),"",IF($AF41="","",VLOOKUP(AI41,TRANSMUTATION_TABLE,4,TRUE)))
A42: 31 | B42: ='INPUT DATA'!B42 -> 0 | P42: =IF(COUNT($F42:$O42)=0,"",SUM($F42:$O42)) | Q42: =IF(ISERROR(IF($P42="","",ROUND(($P42/$P$10)*$Q$10,2))),"",IF($P42="","",ROUND(($P42/$P$10)*$Q$10,2))) | R42: =IF($Q42="","",ROUND($Q42*$R$10,2)) | AC42: =IF(COUNT($S42:$AB42)=0,"",SUM($S42:$AB42)) | AD42: =IF(ISERROR(IF($AC42="","",ROUND(($AC42/$AC$10)*$AD$10,2))),"",IF($AC42="","",ROUND(($AC42/$AC$10)*$AD$10,2))) | AE42: =IF($AD42="","",ROUND($AD42*$AE$10,2)) | AG42: =IF(ISERROR(IF($AF42="","",ROUND(($AF42/$AF$10)*$AG$10,2))),"",IF($AF42="","",ROUND(($AF42/$AF$10)*$AG$10,2))) | AH42: =IF($AG42="","",ROUND($AG42*$AH$10,2)) | AI42: =IF(ISERROR(IF($AF42="","",ROUND(SUM($R42,$AE42,$AH42),2))),"",IF($AF42="","",ROUND(SUM($R42,$AE42,$AH42),2))) | AJ42: =IF(ISERROR(IF($AF42="","",VLOOKUP(AI42,TRANSMUTATION_TABLE,4,TRUE))),"",IF($AF42="","",VLOOKUP(AI42,TRANSMUTATION_TABLE,4,TRUE)))
...

Sheet ARTS_Q2
A1: Class Record
A3: (Pursuant to Deped Order 8 series of 2015)
C4: REGION | G4: ='INPUT DATA'!G4 -> 0 | L4: DIVISION | O4: ='INPUT DATA'!O4 -> 0
B5: SCHOOL NAME | G5: ='INPUT DATA'!G5 -> ARMS DEMO NATIONAL HIGH SCHOOL | T5: SCHOOL ID | X5: ='[1]INPUT DATA'!X5 -> 0 | AD5: SCHOOL YEAR | AG5: ='INPUT DATA'!AG5 -> 2026-2027
A7: SECOND QUARTER | F7: GRADE & SECTION: | K7: ='INPUT DATA'!K7 -> GRADE 7 - ILANG-ILANG | Q7: TEACHER: | S7: ='INPUT DATA'!S7 -> JOSELITO RAMOS | AC7: SUBJECT: | AG7: ARTS
B8: LEARNERS' NAMES | F8: WRITTEN WORKS (20%) | S8: PERFORMANCE TASKS (60%) | AF8: QUARTERLY ASSESSMENT (20%) | AI8: Initial | AJ8: Quarterly
F9: 1 | G9: 2 | H9: 3 | I9: 4 | J9: 5 | K9: 6 | L9: 7 | M9: 8 | N9: 9 | O9: 10 | P9: Total | Q9: PS | R9: WS | S9: 1 | T9: 2 | U9: 3 | V9: 4 | W9: 5 | X9: 6 | Y9: 7 | Z9: 8 | AA9: 9 | AB9: 10 | AC9: Total | AD9: PS | AE9: WS | AF9: 1 | AG9: PS | AH9: WS | AI9: Grade | AJ9: Grade
B10: HIGHEST POSSIBLE SCORE | F10: 10 | G10: 15 | H10: 10 | P10: =IF(COUNT($F10:$O10)=0,"",SUM($F10:$O10)) -> 35 | Q10: 100 | R10: 0.2 | S10: 40 | T10: 50 | U10: 30 | AC10: =IF(COUNT($S10:$AB10)=0,"",SUM($S10:$AB10)) -> 120 | AD10: 100 | AE10: 0.6 | AF10: 40 | AG10: 100 | AH10: 0.2
B11: MALE
A12: 1 | B12: ='INPUT DATA'!B12 -> BAUTISTA, KYLE Z. | F12: 8 | G12: 12 | H12: 7 | P12: =IF(COUNT($F12:$O12)=0,"",SUM($F12:$O12)) -> 27 | Q12: =IF(ISERROR(IF($P12="","",ROUND(($P12/$P$10)*$Q$10,2))),"",IF($P12="","",ROUND(($P12/$P$10)*$Q$10,2))) -> 77.14 | R12: =IF($Q12="","",ROUND($Q12*$R$10,2)) -> 15.43 | S12: 33 | T12: 35 | U12: 23 | AC12: =IF(COUNT($S12:$AB12)=0,"",SUM($S12:$AB12)) -> 91 | AD12: =IF(ISERROR(IF($AC12="","",ROUND(($AC12/$AC$10)*$AD$10,2))),"",IF($AC12="","",ROUND(($AC12/$AC$10)*$AD$10,2))) -> 75.83 | AE12: =IF($AD12="","",ROUND($AD12*$AE$10,2)) -> 45.5 | AF12: 32 | AG12: =IF(ISERROR(IF($AF12="","",ROUND(($AF12/$AF$10)*$AG$10,2))),"",IF($AF12="","",ROUND(($AF12/$AF$10)*$AG$10,2))) -> 80 | AH12: =IF($AG12="","",ROUND($AG12*$AH$10,2)) -> 16 | AI12: =IF(ISERROR(IF($AF12="","",ROUND(SUM($R12,$AE12,$AH12),2))),"",IF($AF12="","",ROUND(SUM($R12,$AE12,$AH12),2))) -> 76.93 | AJ12: =IF(ISERROR(IF($AF12="","",VLOOKUP(AI12,TRANSMUTATION_TABLE,4,TRUE))),"",IF($AF12="","",VLOOKUP(AI12,TRANSMUTATION_TABLE,4,TRUE))) -> 85
A13: 2 | B13: ='INPUT DATA'!B13 -> FLORES, JEROME C. | F13: 9 | G13: 11 | H13: 8 | P13: =IF(COUNT($F13:$O13)=0,"",SUM($F13:$O13)) -> 28 | Q13: =IF(ISERROR(IF($P13="","",ROUND(($P13/$P$10)*$Q$10,2))),"",IF($P13="","",ROUND(($P13/$P$10)*$Q$10,2))) -> 80 | R13: =IF($Q13="","",ROUND($Q13*$R$10,2)) -> 16 | S13: 31 | T13: 37 | U13: 22 | AC13: =IF(COUNT($S13:$AB13)=0,"",SUM($S13:$AB13)) -> 90 | AD13: =IF(ISERROR(IF($AC13="","",ROUND(($AC13/$AC$10)*$AD$10,2))),"",IF($AC13="","",ROUND(($AC13/$AC$10)*$AD$10,2))) -> 75 | AE13: =IF($AD13="","",ROUND($AD13*$AE$10,2)) -> 45 | AF13: 32 | AG13: =IF(ISERROR(IF($AF13="","",ROUND(($AF13/$AF$10)*$AG$10,2))),"",IF($AF13="","",ROUND(($AF13/$AF$10)*$AG$10,2))) -> 80 | AH13: =IF($AG13="","",ROUND($AG13*$AH$10,2)) -> 16 | AI13: =IF(ISERROR(IF($AF13="","",ROUND(SUM($R13,$AE13,$AH13),2))),"",IF($AF13="","",ROUND(SUM($R13,$AE13,$AH13),2))) -> 77 | AJ13: =IF(ISERROR(IF($AF13="","",VLOOKUP(AI13,TRANSMUTATION_TABLE,4,TRUE))),"",IF($AF13="","",VLOOKUP(AI13,TRANSMUTATION_TABLE,4,TRUE))) -> 85
A14: 3 | B14: ='INPUT DATA'!B14 -> GONZALES, FRANCIS L. | F14: 7 | G14: 11 | H14: 8 | P14: =IF(COUNT($F14:$O14)=0,"",SUM($F14:$O14)) -> 26 | Q14: =IF(ISERROR(IF($P14="","",ROUND(($P14/$P$10)*$Q$10,2))),"",IF($P14="","",ROUND(($P14/$P$10)*$Q$10,2))) -> 74.29 | R14: =IF($Q14="","",ROUND($Q14*$R$10,2)) -> 14.86 | S14: 29 | T14: 33 | U14: 20 | AC14: =IF(COUNT($S14:$AB14)=0,"",SUM($S14:$AB14)) -> 82 | AD14: =IF(ISERROR(IF($AC14="","",ROUND(($AC14/$AC$10)*$AD$10,2))),"",IF($AC14="","",ROUND(($AC14/$AC$10)*$AD$10,2))) -> 68.33 | AE14: =IF($AD14="","",ROUND($AD14*$AE$10,2)) -> 41 | AF14: 30 | AG14: =IF(ISERROR(IF($AF14="","",ROUND(($AF14/$AF$10)*$AG$10,2))),"",IF($AF14="","",ROUND(($AF14/$AF$10)*$AG$10,2))) -> 75 | AH14: =IF($AG14="","",ROUND($AG14*$AH$10,2)) -> 15 | AI14: =IF(ISERROR(IF($AF14="","",ROUND(SUM($R14,$AE14,$AH14),2))),"",IF($AF14="","",ROUND(SUM($R14,$AE14,$AH14),2))) -> 70.86 | AJ14: =IF(ISERROR(IF($AF14="","",VLOOKUP(AI14,TRANSMUTATION_TABLE,4,TRUE))),"",IF($AF14="","",VLOOKUP(AI14,TRANSMUTATION_TABLE,4,TRUE))) -> 81
A15: 4 | B15: ='INPUT DATA'!B15 -> IGNACIO, CHRISTIAN D. | F15: 7 | G15: 9 | H15: 6 | P15: =IF(COUNT($F15:$O15)=0,"",SUM($F15:$O15)) -> 22 | Q15: =IF(ISERROR(IF($P15="","",ROUND(($P15/$P$10)*$Q$10,2))),"",IF($P15="","",ROUND(($P15/$P$10)*$Q$10,2))) -> 62.86 | R15: =IF($Q15="","",ROUND($Q15*$R$10,2)) -> 12.57 | S15: 27 | T15: 37 | U15: 21 | AC15: =IF(COUNT($S15:$AB15)=0,"",SUM($S15:$AB15)) -> 85 | AD15: =IF(ISERROR(IF($AC15="","",ROUND(($AC15/$AC$10)*$AD$10,2))),"",IF($AC15="","",ROUND(($AC15/$AC$10)*$AD$10,2))) -> 70.83 | AE15: =IF($AD15="","",ROUND($AD15*$AE$10,2)) -> 42.5 | AF15: 29 | AG15: =IF(ISERROR(IF($AF15="","",ROUND(($AF15/$AF$10)*$AG$10,2))),"",IF($AF15="","",ROUND(($AF15/$AF$10)*$AG$10,2))) -> 72.5 | AH15: =IF($AG15="","",ROUND($AG15*$AH$10,2)) -> 14.5 | AI15: =IF(ISERROR(IF($AF15="","",ROUND(SUM($R15,$AE15,$AH15),2))),"",IF($AF15="","",ROUND(SUM($R15,$AE15,$AH15),2))) -> 69.57 | AJ15: =IF(ISERROR(IF($AF15="","",VLOOKUP(AI15,TRANSMUTATION_TABLE,4,TRUE))),"",IF($AF15="","",VLOOKUP(AI15,TRANSMUTATION_TABLE,4,TRUE))) -> 80
A16: 5 | B16: ='INPUT DATA'!B16 -> LUMAPAS, JERICHO T. | F16: 7 | G16: 11 | H16: 7 | P16: =IF(COUNT($F16:$O16)=0,"",SUM($F16:$O16)) -> 25 | Q16: =IF(ISERROR(IF($P16="","",ROUND(($P16/$P$10)*$Q$10,2))),"",IF($P16="","",ROUND(($P16/$P$10)*$Q$10,2))) -> 71.43 | R16: =IF($Q16="","",ROUND($Q16*$R$10,2)) -> 14.29 | S16: 30 | T16: 32 | U16: 19 | AC16: =IF(COUNT($S16:$AB16)=0,"",SUM($S16:$AB16)) -> 81 | AD16: =IF(ISERROR(IF($AC16="","",ROUND(($AC16/$AC$10)*$AD$10,2))),"",IF($AC16="","",ROUND(($AC16/$AC$10)*$AD$10,2))) -> 67.5 | AE16: =IF($AD16="","",ROUND($AD16*$AE$10,2)) -> 40.5 | AF16: 28 | AG16: =IF(ISERROR(IF($AF16="","",ROUND(($AF16/$AF$10)*$AG$10,2))),"",IF($AF16="","",ROUND(($AF16/$AF$10)*$AG$10,2))) -> 70 | AH16: =IF($AG16="","",ROUND($AG16*$AH$10,2)) -> 14 | AI16: =IF(ISERROR(IF($AF16="","",ROUND(SUM($R16,$AE16,$AH16),2))),"",IF($AF16="","",ROUND(SUM($R16,$AE16,$AH16),2))) -> 68.79 | AJ16: =IF(ISERROR(IF($AF16="","",VLOOKUP(AI16,TRANSMUTATION_TABLE,4,TRUE))),"",IF($AF16="","",VLOOKUP(AI16,TRANSMUTATION_TABLE,4,TRUE))) -> 80
A17: 6 | B17: ='INPUT DATA'!B17 -> MENDOZA, EMMANUEL R. | F17: 6 | G17: 11 | H17: 8 | P17: =IF(COUNT($F17:$O17)=0,"",SUM($F17:$O17)) -> 25 | Q17: =IF(ISERROR(IF($P17="","",ROUND(($P17/$P$10)*$Q$10,2))),"",IF($P17="","",ROUND(($P17/$P$10)*$Q$10,2))) -> 71.43 | R17: =IF($Q17="","",ROUND($Q17*$R$10,2)) -> 14.29 | S17: 26 | T17: 31 | U17: 19 | AC17: =IF(COUNT($S17:$AB17)=0,"",SUM($S17:$AB17)) -> 76 | AD17: =IF(ISERROR(IF($AC17="","",ROUND(($AC17/$AC$10)*$AD$10,2))),"",IF($AC17="","",ROUND(($AC17/$AC$10)*$AD$10,2))) -> 63.33 | AE17: =IF($AD17="","",ROUND($AD17*$AE$10,2)) -> 38 | AF17: 25 | AG17: =IF(ISERROR(IF($AF17="","",ROUND(($AF17/$AF$10)*$AG$10,2))),"",IF($AF17="","",ROUND(($AF17/$AF$10)*$AG$10,2))) -> 62.5 | AH17: =IF($AG17="","",ROUND($AG17*$AH$10,2)) -> 12.5 | AI17: =IF(ISERROR(IF($AF17="","",ROUND(SUM($R17,$AE17,$AH17),2))),"",IF($AF17="","",ROUND(SUM($R17,$AE17,$AH17),2))) -> 64.79 | AJ17: =IF(ISERROR(IF($AF17="","",VLOOKUP(AI17,TRANSMUTATION_TABLE,4,TRUE))),"",IF($AF17="","",VLOOKUP(AI17,TRANSMUTATION_TABLE,4,TRUE))) -> 77
A18: 7 | B18: ='INPUT DATA'!B18 -> MENDOZA, JUAN MIGUEL O. | F18: 8 | G18: 14 | H18: 8 | P18: =IF(COUNT($F18:$O18)=0,"",SUM($F18:$O18)) -> 30 | Q18: =IF(ISERROR(IF($P18="","",ROUND(($P18/$P$10)*$Q$10,2))),"",IF($P18="","",ROUND(($P18/$P$10)*$Q$10,2))) -> 85.71 | R18: =IF($Q18="","",ROUND($Q18*$R$10,2)) -> 17.14 | S18: 34 | T18: 39 | U18: 27 | AC18: =IF(COUNT($S18:$AB18)=0,"",SUM($S18:$AB18)) -> 100 | AD18: =IF(ISERROR(IF($AC18="","",ROUND(($AC18/$AC$10)*$AD$10,2))),"",IF($AC18="","",ROUND(($AC18/$AC$10)*$AD$10,2))) -> 83.33 | AE18: =IF($AD18="","",ROUND($AD18*$AE$10,2)) -> 50 | AF18: 33 | AG18: =IF(ISERROR(IF($AF18="","",ROUND(($AF18/$AF$10)*$AG$10,2))),"",IF($AF18="","",ROUND(($AF18/$AF$10)*$AG$10,2))) -> 82.5 | AH18: =IF($AG18="","",ROUND($AG18*$AH$10,2)) -> 16.5 | AI18: =IF(ISERROR(IF($AF18="","",ROUND(SUM($R18,$AE18,$AH18),2))),"",IF($AF18="","",ROUND(SUM($R18,$AE18,$AH18),2))) -> 83.64 | AJ18: =IF(ISERROR(IF($AF18="","",VLOOKUP(AI18,TRANSMUTATION_TABLE,4,TRUE))),"",IF($AF18="","",VLOOKUP(AI18,TRANSMUTATION_TABLE,4,TRUE))) -> 89
A19: 8 | B19: ='INPUT DATA'!B19 -> MORALES, KYLE P. | D19: 0 | F19: 7 | G19: 11 | H19: 6 | P19: =IF(COUNT($F19:$O19)=0,"",SUM($F19:$O19)) -> 24 | Q19: =IF(ISERROR(IF($P19="","",ROUND(($P19/$P$10)*$Q$10,2))),"",IF($P19="","",ROUND(($P19/$P$10)*$Q$10,2))) -> 68.57 | R19: =IF($Q19="","",ROUND($Q19*$R$10,2)) -> 13.71 | S19: 25 | T19: 36 | U19: 19 | AC19: =IF(COUNT($S19:$AB19)=0,"",SUM($S19:$AB19)) -> 80 | AD19: =IF(ISERROR(IF($AC19="","",ROUND(($AC19/$AC$10)*$AD$10,2))),"",IF($AC19="","",ROUND(($AC19/$AC$10)*$AD$10,2))) -> 66.67 | AE19: =IF($AD19="","",ROUND($AD19*$AE$10,2)) -> 40 | AF19: 24 | AG19: =IF(ISERROR(IF($AF19="","",ROUND(($AF19/$AF$10)*$AG$10,2))),"",IF($AF19="","",ROUND(($AF19/$AF$10)*$AG$10,2))) -> 60 | AH19: =IF($AG19="","",ROUND($AG19*$AH$10,2)) -> 12 | AI19: =IF(ISERROR(IF($AF19="","",ROUND(SUM($R19,$AE19,$AH19),2))),"",IF($AF19="","",ROUND(SUM($R19,$AE19,$AH19),2))) -> 65.71 | AJ19: =IF(ISERROR(IF($AF19="","",VLOOKUP(AI19,TRANSMUTATION_TABLE,4,TRUE))),"",IF($AF19="","",VLOOKUP(AI19,TRANSMUTATION_TABLE,4,TRUE))) -> 78
A20: 9 | B20: ='INPUT DATA'!B20 -> NAVARRO, MARK ANTHONY T. | F20: 10 | G20: 14 | H20: 9 | P20: =IF(COUNT($F20:$O20)=0,"",SUM($F20:$O20)) -> 33 | Q20: =IF(ISERROR(IF($P20="","",ROUND(($P20/$P$10)*$Q$10,2))),"",IF($P20="","",ROUND(($P20/$P$10)*$Q$10,2))) -> 94.29 | R20: =IF($Q20="","",ROUND($Q20*$R$10,2)) -> 18.86 | S20: 34 | T20: 48 | U20: 29 | AC20: =IF(COUNT($S20:$AB20)=0,"",SUM($S20:$AB20)) -> 111 | AD20: =IF(ISERROR(IF($AC20="","",ROUND(($AC20/$AC$10)*$AD$10,2))),"",IF($AC20="","",ROUND(($AC20/$AC$10)*$AD$10,2))) -> 92.5 | AE20: =IF($AD20="","",ROUND($AD20*$AE$10,2)) -> 55.5 | AF20: 39 | AG20: =IF(ISERROR(IF($AF20="","",ROUND(($AF20/$AF$10)*$AG$10,2))),"",IF($AF20="","",ROUND(($AF20/$AF$10)*$AG$10,2))) -> 97.5 | AH20: =IF($AG20="","",ROUND($AG20*$AH$10,2)) -> 19.5 | AI20: =IF(ISERROR(IF($AF20="","",ROUND(SUM($R20,$AE20,$AH20),2))),"",IF($AF20="","",ROUND(SUM($R20,$AE20,$AH20),2))) -> 93.86 | AJ20: =IF(ISERROR(IF($AF20="","",VLOOKUP(AI20,TRANSMUTATION_TABLE,4,TRUE))),"",IF($AF20="","",VLOOKUP(AI20,TRANSMUTATION_TABLE,4,TRUE))) -> 96
A21: 10 | B21: ='INPUT DATA'!B21 -> OCAMPO JR., CHRISTIAN U. | F21: 8 | G21: 12 | H21: 8 | P21: =IF(COUNT($F21:$O21)=0,"",SUM($F21:$O21)) -> 28 | Q21: =IF(ISERROR(IF($P21="","",ROUND(($P21/$P$10)*$Q$10,2))),"",IF($P21="","",ROUND(($P21/$P$10)*$Q$10,2))) -> 80 | R21: =IF($Q21="","",ROUND($Q21*$R$10,2)) -> 16 | S21: 35 | T21: 41 | U21: 25 | AC21: =IF(COUNT($S21:$AB21)=0,"",SUM($S21:$AB21)) -> 101 | AD21: =IF(ISERROR(IF($AC21="","",ROUND(($AC21/$AC$10)*$AD$10,2))),"",IF($AC21="","",ROUND(($AC21/$AC$10)*$AD$10,2))) -> 84.17 | AE21: =IF($AD21="","",ROUND($AD21*$AE$10,2)) -> 50.5 | AF21: 33 | AG21: =IF(ISERROR(IF($AF21="","",ROUND(($AF21/$AF$10)*$AG$10,2))),"",IF($AF21="","",ROUND(($AF21/$AF$10)*$AG$10,2))) -> 82.5 | AH21: =IF($AG21="","",ROUND($AG21*$AH$10,2)) -> 16.5 | AI21: =IF(ISERROR(IF($AF21="","",ROUND(SUM($R21,$AE21,$AH21),2))),"",IF($AF21="","",ROUND(SUM($R21,$AE21,$AH21),2))) -> 83 | AJ21: =IF(ISERROR(IF($AF21="","",VLOOKUP(AI21,TRANSMUTATION_TABLE,4,TRUE))),"",IF($AF21="","",VLOOKUP(AI21,TRANSMUTATION_TABLE,4,TRUE))) -> 89
A22: 11 | B22: ='INPUT DATA'!B22 -> PANGANIBAN, DOMINIC C. | D22: 0 | F22: 10 | G22: 13 | H22: 10 | P22: =IF(COUNT($F22:$O22)=0,"",SUM($F22:$O22)) -> 33 | Q22: =IF(ISERROR(IF($P22="","",ROUND(($P22/$P$10)*$Q$10,2))),"",IF($P22="","",ROUND(($P22/$P$10)*$Q$10,2))) -> 94.29 | R22: =IF($Q22="","",ROUND($Q22*$R$10,2)) -> 18.86 | S22: 38 | T22: 43 | U22: 25 | AC22: =IF(COUNT($S22:$AB22)=0,"",SUM($S22:$AB22)) -> 106 | AD22: =IF(ISERROR(IF($AC22="","",ROUND(($AC22/$AC$10)*$AD$10,2))),"",IF($AC22="","",ROUND(($AC22/$AC$10)*$AD$10,2))) -> 88.33 | AE22: =IF($AD22="","",ROUND($AD22*$AE$10,2)) -> 53 | AF22: 37 | AG22: =IF(ISERROR(IF($AF22="","",ROUND(($AF22/$AF$10)*$AG$10,2))),"",IF($AF22="","",ROUND(($AF22/$AF$10)*$AG$10,2))) -> 92.5 | AH22: =IF($AG22="","",ROUND($AG22*$AH$10,2)) -> 18.5 | AI22: =IF(ISERROR(IF($AF22="","",ROUND(SUM($R22,$AE22,$AH22),2))),"",IF($AF22="","",ROUND(SUM($R22,$AE22,$AH22),2))) -> 90.36 | AJ22: =IF(ISERROR(IF($AF22="","",VLOOKUP(AI22,TRANSMUTATION_TABLE,4,TRUE))),"",IF($AF22="","",VLOOKUP(AI22,TRANSMUTATION_TABLE,4,TRUE))) -> 93
A23: 12 | B23: ='INPUT DATA'!B23 -> RAMOS, FRANCIS H. | F23: 8 | G23: 13 | H23: 9 | P23: =IF(COUNT($F23:$O23)=0,"",SUM($F23:$O23)) -> 30 | Q23: =IF(ISERROR(IF($P23="","",ROUND(($P23/$P$10)*$Q$10,2))),"",IF($P23="","",ROUND(($P23/$P$10)*$Q$10,2))) -> 85.71 | R23: =IF($Q23="","",ROUND($Q23*$R$10,2)) -> 17.14 | S23: 32 | T23: 39 | U23: 22 | AC23: =IF(COUNT($S23:$AB23)=0,"",SUM($S23:$AB23)) -> 93 | AD23: =IF(ISERROR(IF($AC23="","",ROUND(($AC23/$AC$10)*$AD$10,2))),"",IF($AC23="","",ROUND(($AC23/$AC$10)*$AD$10,2))) -> 77.5 | AE23: =IF($AD23="","",ROUND($AD23*$AE$10,2)) -> 46.5 | AF23: 28 | AG23: =IF(ISERROR(IF($AF23="","",ROUND(($AF23/$AF$10)*$AG$10,2))),"",IF($AF23="","",ROUND(($AF23/$AF$10)*$AG$10,2))) -> 70 | AH23: =IF($AG23="","",ROUND($AG23*$AH$10,2)) -> 14 | AI23: =IF(ISERROR(IF($AF23="","",ROUND(SUM($R23,$AE23,$AH23),2))),"",IF($AF23="","",ROUND(SUM($R23,$AE23,$AH23),2))) -> 77.64 | AJ23: =IF(ISERROR(IF($AF23="","",VLOOKUP(AI23,TRANSMUTATION_TABLE,4,TRUE))),"",IF($AF23="","",VLOOKUP(AI23,TRANSMUTATION_TABLE,4,TRUE))) -> 86
A24: 13 | B24: ='INPUT DATA'!B24 -> RAMOS JR., KYLE R. | F24: 8 | G24: 14 | H24: 9 | P24: =IF(COUNT($F24:$O24)=0,"",SUM($F24:$O24)) -> 31 | Q24: =IF(ISERROR(IF($P24="","",ROUND(($P24/$P$10)*$Q$10,2))),"",IF($P24="","",ROUND(($P24/$P$10)*$Q$10,2))) -> 88.57 | R24: =IF($Q24="","",ROUND($Q24*$R$10,2)) -> 17.71 | S24: 33 | T24: 46 | U24: 25 | AC24: =IF(COUNT($S24:$AB24)=0,"",SUM($S24:$AB24)) -> 104 | AD24: =IF(ISERROR(IF($AC24="","",ROUND(($AC24/$AC$10)*$AD$10,2))),"",IF($AC24="","",ROUND(($AC24/$AC$10)*$AD$10,2))) -> 86.67 | AE24: =IF($AD24="","",ROUND($AD24*$AE$10,2)) -> 52 | AF24: 32 | AG24: =IF(ISERROR(IF($AF24="","",ROUND(($AF24/$AF$10)*$AG$10,2))),"",IF($AF24="","",ROUND(($AF24/$AF$10)*$AG$10,2))) -> 80 | AH24: =IF($AG24="","",ROUND($AG24*$AH$10,2)) -> 16 | AI24: =IF(ISERROR(IF($AF24="","",ROUND(SUM($R24,$AE24,$AH24),2))),"",IF($AF24="","",ROUND(SUM($R24,$AE24,$AH24),2))) -> 85.71 | AJ24: =IF(ISERROR(IF($AF24="","",VLOOKUP(AI24,TRANSMUTATION_TABLE,4,TRUE))),"",IF($AF24="","",VLOOKUP(AI24,TRANSMUTATION_TABLE,4,TRUE))) -> 91
A25: 14 | B25: ='INPUT DATA'!B25 -> SANTOS, KYLE A. | F25: 9 | G25: 14 | H25: 10 | P25: =IF(COUNT($F25:$O25)=0,"",SUM($F25:$O25)) -> 33 | Q25: =IF(ISERROR(IF($P25="","",ROUND(($P25/$P$10)*$Q$10,2))),"",IF($P25="","",ROUND(($P25/$P$10)*$Q$10,2))) -> 94.29 | R25: =IF($Q25="","",ROUND($Q25*$R$10,2)) -> 18.86 | S25: 36 | T25: 50 | U25: 27 | AC25: =IF(COUNT($S25:$AB25)=0,"",SUM($S25:$AB25)) -> 113 | AD25: =IF(ISERROR(IF($AC25="","",ROUND(($AC25/$AC$10)*$AD$10,2))),"",IF($AC25="","",ROUND(($AC25/$AC$10)*$AD$10,2))) -> 94.17 | AE25: =IF($AD25="","",ROUND($AD25*$AE$10,2)) -> 56.5 | AF25: 40 | AG25: =IF(ISERROR(IF($AF25="","",ROUND(($AF25/$AF$10)*$AG$10,2))),"",IF($AF25="","",ROUND(($AF25/$AF$10)*$AG$10,2))) -> 100 | AH25: =IF($AG25="","",ROUND($AG25*$AH$10,2)) -> 20 | AI25: =IF(ISERROR(IF($AF25="","",ROUND(SUM($R25,$AE25,$AH25),2))),"",IF($AF25="","",ROUND(SUM($R25,$AE25,$AH25),2))) -> 95.36 | AJ25: =IF(ISERROR(IF($AF25="","",VLOOKUP(AI25,TRANSMUTATION_TABLE,4,TRUE))),"",IF($AF25="","",VLOOKUP(AI25,TRANSMUTATION_TABLE,4,TRUE))) -> 97
A26: 15 | B26: ='INPUT DATA'!B26 -> TOLENTINO, CARLO O. | F26: 8 | G26: 13 | H26: 9 | P26: =IF(COUNT($F26:$O26)=0,"",SUM($F26:$O26)) -> 30 | Q26: =IF(ISERROR(IF($P26="","",ROUND(($P26/$P$10)*$Q$10,2))),"",IF($P26="","",ROUND(($P26/$P$10)*$Q$10,2))) -> 85.71 | R26: =IF($Q26="","",ROUND($Q26*$R$10,2)) -> 17.14 | S26: 34 | T26: 42 | U26: 24 | AC26: =IF(COUNT($S26:$AB26)=0,"",SUM($S26:$AB26)) -> 100 | AD26: =IF(ISERROR(IF($AC26="","",ROUND(($AC26/$AC$10)*$AD$10,2))),"",IF($AC26="","",ROUND(($AC26/$AC$10)*$AD$10,2))) -> 83.33 | AE26: =IF($AD26="","",ROUND($AD26*$AE$10,2)) -> 50 | AF26: 32 | AG26: =IF(ISERROR(IF($AF26="","",ROUND(($AF26/$AF$10)*$AG$10,2))),"",IF($AF26="","",ROUND(($AF26/$AF$10)*$AG$10,2))) -> 80 | AH26: =IF($AG26="","",ROUND($AG26*$AH$10,2)) -> 16 | AI26: =IF(ISERROR(IF($AF26="","",ROUND(SUM($R26,$AE26,$AH26),2))),"",IF($AF26="","",ROUND(SUM($R26,$AE26,$AH26),2))) -> 83.14 | AJ26: =IF(ISERROR(IF($AF26="","",VLOOKUP(AI26,TRANSMUTATION_TABLE,4,TRUE))),"",IF($AF26="","",VLOOKUP(AI26,TRANSMUTATION_TABLE,4,TRUE))) -> 89
A27: 16 | B27: ='INPUT DATA'!B27 -> TOLENTINO, JEROME H. | F27: 10 | G27: 14 | H27: 10 | P27: =IF(COUNT($F27:$O27)=0,"",SUM($F27:$O27)) -> 34 | Q27: =IF(ISERROR(IF($P27="","",ROUND(($P27/$P$10)*$Q$10,2))),"",IF($P27="","",ROUND(($P27/$P$10)*$Q$10,2))) -> 97.14 | R27: =IF($Q27="","",ROUND($Q27*$R$10,2)) -> 19.43 | S27: 35 | T27: 50 | U27: 29 | AC27: =IF(COUNT($S27:$AB27)=0,"",SUM($S27:$AB27)) -> 114 | AD27: =IF(ISERROR(IF($AC27="","",ROUND(($AC27/$AC$10)*$AD$10,2))),"",IF($AC27="","",ROUND(($AC27/$AC$10)*$AD$10,2))) -> 95 | AE27: =IF($AD27="","",ROUND($AD27*$AE$10,2)) -> 57 | AF27: 39 | AG27: =IF(ISERROR(IF($AF27="","",ROUND(($AF27/$AF$10)*$AG$10,2))),"",IF($AF27="","",ROUND(($AF27/$AF$10)*$AG$10,2))) -> 97.5 | AH27: =IF($AG27="","",ROUND($AG27*$AH$10,2)) -> 19.5 | AI27: =IF(ISERROR(IF($AF27="","",ROUND(SUM($R27,$AE27,$AH27),2))),"",IF($AF27="","",ROUND(SUM($R27,$AE27,$AH27),2))) -> 95.93 | AJ27: =IF(ISERROR(IF($AF27="","",VLOOKUP(AI27,TRANSMUTATION_TABLE,4,TRUE))),"",IF($AF27="","",VLOOKUP(AI27,TRANSMUTATION_TABLE,4,TRUE))) -> 97
A28: 17 | B28: ='INPUT DATA'!B28 -> TORRES, EMMANUEL A. | F28: 9 | G28: 14 | H28: 9 | P28: =IF(COUNT($F28:$O28)=0,"",SUM($F28:$O28)) -> 32 | Q28: =IF(ISERROR(IF($P28="","",ROUND(($P28/$P$10)*$Q$10,2))),"",IF($P28="","",ROUND(($P28/$P$10)*$Q$10,2))) -> 91.43 | R28: =IF($Q28="","",ROUND($Q28*$R$10,2)) -> 18.29 | S28: 35 | T28: 42 | U28: 28 | AC28: =IF(COUNT($S28:$AB28)=0,"",SUM($S28:$AB28)) -> 105 | AD28: =IF(ISERROR(IF($AC28="","",ROUND(($AC28/$AC$10)*$AD$10,2))),"",IF($AC28="","",ROUND(($AC28/$AC$10)*$AD$10,2))) -> 87.5 | AE28: =IF($AD28="","",ROUND($AD28*$AE$10,2)) -> 52.5 | AF28: 34 | AG28: =IF(ISERROR(IF($AF28="","",ROUND(($AF28/$AF$10)*$AG$10,2))),"",IF($AF28="","",ROUND(($AF28/$AF$10)*$AG$10,2))) -> 85 | AH28: =IF($AG28="","",ROUND($AG28*$AH$10,2)) -> 17 | AI28: =IF(ISERROR(IF($AF28="","",ROUND(SUM($R28,$AE28,$AH28),2))),"",IF($AF28="","",ROUND(SUM($R28,$AE28,$AH28),2))) -> 87.79 | AJ28: =IF(ISERROR(IF($AF28="","",VLOOKUP(AI28,TRANSMUTATION_TABLE,4,TRUE))),"",IF($AF28="","",VLOOKUP(AI28,TRANSMUTATION_TABLE,4,TRUE))) -> 92
A29: 18 | B29: ='INPUT DATA'!B29 -> VILLANUEVA, BENEDICT Q. | F29: 6 | G29: 9 | H29: 6 | P29: =IF(COUNT($F29:$O29)=0,"",SUM($F29:$O29)) -> 21 | Q29: =IF(ISERROR(IF($P29="","",ROUND(($P29/$P$10)*$Q$10,2))),"",IF($P29="","",ROUND(($P29/$P$10)*$Q$10,2))) -> 60 | R29: =IF($Q29="","",ROUND($Q29*$R$10,2)) -> 12 | S29: 23 | T29: 36 | U29: 17 | AC29: =IF(COUNT($S29:$AB29)=0,"",SUM($S29:$AB29)) -> 76 | AD29: =IF(ISERROR(IF($AC29="","",ROUND(($AC29/$AC$10)*$AD$10,2))),"",IF($AC29="","",ROUND(($AC29/$AC$10)*$AD$10,2))) -> 63.33 | AE29: =IF($AD29="","",ROUND($AD29*$AE$10,2)) -> 38 | AF29: 27 | AG29: =IF(ISERROR(IF($AF29="","",ROUND(($AF29/$AF$10)*$AG$10,2))),"",IF($AF29="","",ROUND(($AF29/$AF$10)*$AG$10,2))) -> 67.5 | AH29: =IF($AG29="","",ROUND($AG29*$AH$10,2)) -> 13.5 | AI29: =IF(ISERROR(IF($AF29="","",ROUND(SUM($R29,$AE29,$AH29),2))),"",IF($AF29="","",ROUND(SUM($R29,$AE29,$AH29),2))) -> 63.5 | AJ29: =IF(ISERROR(IF($AF29="","",VLOOKUP(AI29,TRANSMUTATION_TABLE,4,TRUE))),"",IF($AF29="","",VLOOKUP(AI29,TRANSMUTATION_TABLE,4,TRUE))) -> 77
A30: 19 | B30: ='INPUT DATA'!B30 -> VILLANUEVA, NATHANIEL P. | F30: 9 | G30: 12 | H30: 9 | P30: =IF(COUNT($F30:$O30)=0,"",SUM($F30:$O30)) -> 30 | Q30: =IF(ISERROR(IF($P30="","",ROUND(($P30/$P$10)*$Q$10,2))),"",IF($P30="","",ROUND(($P30/$P$10)*$Q$10,2))) -> 85.71 | R30: =IF($Q30="","",ROUND($Q30*$R$10,2)) -> 17.14 | S30: 36 | T30: 41 | U30: 28 | AC30: =IF(COUNT($S30:$AB30)=0,"",SUM($S30:$AB30)) -> 105 | AD30: =IF(ISERROR(IF($AC30="","",ROUND(($AC30/$AC$10)*$AD$10,2))),"",IF($AC30="","",ROUND(($AC30/$AC$10)*$AD$10,2))) -> 87.5 | AE30: =IF($AD30="","",ROUND($AD30*$AE$10,2)) -> 52.5 | AF30: 35 | AG30: =IF(ISERROR(IF($AF30="","",ROUND(($AF30/$AF$10)*$AG$10,2))),"",IF($AF30="","",ROUND(($AF30/$AF$10)*$AG$10,2))) -> 87.5 | AH30: =IF($AG30="","",ROUND($AG30*$AH$10,2)) -> 17.5 | AI30: =IF(ISERROR(IF($AF30="","",ROUND(SUM($R30,$AE30,$AH30),2))),"",IF($AF30="","",ROUND(SUM($R30,$AE30,$AH30),2))) -> 87.14 | AJ30: =IF(ISERROR(IF($AF30="","",VLOOKUP(AI30,TRANSMUTATION_TABLE,4,TRUE))),"",IF($AF30="","",VLOOKUP(AI30,TRANSMUTATION_TABLE,4,TRUE))) -> 91
A31: 20 | B31: ='INPUT DATA'!B31 -> YBANEZ, JOSHUA V. | F31: 7 | G31: 9 | H31: 6 | P31: =IF(COUNT($F31:$O31)=0,"",SUM($F31:$O31)) -> 22 | Q31: =IF(ISERROR(IF($P31="","",ROUND(($P31/$P$10)*$Q$10,2))),"",IF($P31="","",ROUND(($P31/$P$10)*$Q$10,2))) -> 62.86 | R31: =IF($Q31="","",ROUND($Q31*$R$10,2)) -> 12.57 | S31: 28 | T31: 34 | U31: 19 | AC31: =IF(COUNT($S31:$AB31)=0,"",SUM($S31:$AB31)) -> 81 | AD31: =IF(ISERROR(IF($AC31="","",ROUND(($AC31/$AC$10)*$AD$10,2))),"",IF($AC31="","",ROUND(($AC31/$AC$10)*$AD$10,2))) -> 67.5 | AE31: =IF($AD31="","",ROUND($AD31*$AE$10,2)) -> 40.5 | AF31: 26 | AG31: =IF(ISERROR(IF($AF31="","",ROUND(($AF31/$AF$10)*$AG$10,2))),"",IF($AF31="","",ROUND(($AF31/$AF$10)*$AG$10,2))) -> 65 | AH31: =IF($AG31="","",ROUND($AG31*$AH$10,2)) -> 13 | AI31: =IF(ISERROR(IF($AF31="","",ROUND(SUM($R31,$AE31,$AH31),2))),"",IF($AF31="","",ROUND(SUM($R31,$AE31,$AH31),2))) -> 66.07 | AJ31: =IF(ISERROR(IF($AF31="","",VLOOKUP(AI31,TRANSMUTATION_TABLE,4,TRUE))),"",IF($AF31="","",VLOOKUP(AI31,TRANSMUTATION_TABLE,4,TRUE))) -> 78
A32: 21 | B32: ='INPUT DATA'!B32 -> 0 | P32: =IF(COUNT($F32:$O32)=0,"",SUM($F32:$O32)) | Q32: =IF(ISERROR(IF($P32="","",ROUND(($P32/$P$10)*$Q$10,2))),"",IF($P32="","",ROUND(($P32/$P$10)*$Q$10,2))) | R32: =IF($Q32="","",ROUND($Q32*$R$10,2)) | AC32: =IF(COUNT($S32:$AB32)=0,"",SUM($S32:$AB32)) | AD32: =IF(ISERROR(IF($AC32="","",ROUND(($AC32/$AC$10)*$AD$10,2))),"",IF($AC32="","",ROUND(($AC32/$AC$10)*$AD$10,2))) | AE32: =IF($AD32="","",ROUND($AD32*$AE$10,2)) | AG32: =IF(ISERROR(IF($AF32="","",ROUND(($AF32/$AF$10)*$AG$10,2))),"",IF($AF32="","",ROUND(($AF32/$AF$10)*$AG$10,2))) | AH32: =IF($AG32="","",ROUND($AG32*$AH$10,2)) | AI32: =IF(ISERROR(IF($AF32="","",ROUND(SUM($R32,$AE32,$AH32),2))),"",IF($AF32="","",ROUND(SUM($R32,$AE32,$AH32),2))) | AJ32: =IF(ISERROR(IF($AF32="","",VLOOKUP(AI32,TRANSMUTATION_TABLE,4,TRUE))),"",IF($AF32="","",VLOOKUP(AI32,TRANSMUTATION_TABLE,4,TRUE)))
A33: 22 | B33: ='INPUT DATA'!B33 -> 0 | P33: =IF(COUNT($F33:$O33)=0,"",SUM($F33:$O33)) | Q33: =IF(ISERROR(IF($P33="","",ROUND(($P33/$P$10)*$Q$10,2))),"",IF($P33="","",ROUND(($P33/$P$10)*$Q$10,2))) | R33: =IF($Q33="","",ROUND($Q33*$R$10,2)) | AC33: =IF(COUNT($S33:$AB33)=0,"",SUM($S33:$AB33)) | AD33: =IF(ISERROR(IF($AC33="","",ROUND(($AC33/$AC$10)*$AD$10,2))),"",IF($AC33="","",ROUND(($AC33/$AC$10)*$AD$10,2))) | AE33: =IF($AD33="","",ROUND($AD33*$AE$10,2)) | AG33: =IF(ISERROR(IF($AF33="","",ROUND(($AF33/$AF$10)*$AG$10,2))),"",IF($AF33="","",ROUND(($AF33/$AF$10)*$AG$10,2))) | AH33: =IF($AG33="","",ROUND($AG33*$AH$10,2)) | AI33: =IF(ISERROR(IF($AF33="","",ROUND(SUM($R33,$AE33,$AH33),2))),"",IF($AF33="","",ROUND(SUM($R33,$AE33,$AH33),2))) | AJ33: =IF(ISERROR(IF($AF33="","",VLOOKUP(AI33,TRANSMUTATION_TABLE,4,TRUE))),"",IF($AF33="","",VLOOKUP(AI33,TRANSMUTATION_TABLE,4,TRUE)))
A34: 23 | B34: ='INPUT DATA'!B34 -> 0 | P34: =IF(COUNT($F34:$O34)=0,"",SUM($F34:$O34)) | Q34: =IF(ISERROR(IF($P34="","",ROUND(($P34/$P$10)*$Q$10,2))),"",IF($P34="","",ROUND(($P34/$P$10)*$Q$10,2))) | R34: =IF($Q34="","",ROUND($Q34*$R$10,2)) | AC34: =IF(COUNT($S34:$AB34)=0,"",SUM($S34:$AB34)) | AD34: =IF(ISERROR(IF($AC34="","",ROUND(($AC34/$AC$10)*$AD$10,2))),"",IF($AC34="","",ROUND(($AC34/$AC$10)*$AD$10,2))) | AE34: =IF($AD34="","",ROUND($AD34*$AE$10,2)) | AG34: =IF(ISERROR(IF($AF34="","",ROUND(($AF34/$AF$10)*$AG$10,2))),"",IF($AF34="","",ROUND(($AF34/$AF$10)*$AG$10,2))) | AH34: =IF($AG34="","",ROUND($AG34*$AH$10,2)) | AI34: =IF(ISERROR(IF($AF34="","",ROUND(SUM($R34,$AE34,$AH34),2))),"",IF($AF34="","",ROUND(SUM($R34,$AE34,$AH34),2))) | AJ34: =IF(ISERROR(IF($AF34="","",VLOOKUP(AI34,TRANSMUTATION_TABLE,4,TRUE))),"",IF($AF34="","",VLOOKUP(AI34,TRANSMUTATION_TABLE,4,TRUE)))
