Workbook
Name PERFORMANCETASKS: #REF!
Name PT: #REF!
Name QA: #REF!
Name QUARTERLYASSESSMENT: #REF!
Name SUBJECTS: '[1]INPUT DATA'!$A$1002:$A$1005
Name Transmu_Table: #REF!
Name WRITTENWORKS: #REF!
Name WW: #REF!

Sheet INSTRUCTIONS
B3: Instructions: Accomplishing the Electronic Class Record (ECR) for SSHS
B7: 1 | C7: Input the correct data for the following sections. Any details entered here are used throughout the e-Class Record
C10: INPUT DATA
C12: A. | D12: SCHOOL INFO
D13: 1 | E13: REGION | I13: : | J13: Select the Region where the school is located
D14: 2 | E14: DIVISION | I14: : | J14: Input the respective Schools Division Office
D15: 3 | E15: SCHOOL ID | I15: : | J15: Enter the six (6) digit school ID
D16: 4 | E16: SCHOOL NAME | I16: : | J16: Enter the name of the school
D17: 5 | E17: SCHOOL YEAR | I17: : | J17: Enter the current school year
C19: B. | D19: TEACHER, GRADE LEVEL, AND SUBJECT AREA INFO
D20: 1 | E20: TEACHER | J20: Enter the name of teacher's name
D21: 2 | E21: GRADE LEVEL | J21: Input the grade level taught. This field only accepts 11 or 12.
D22: 3 | E22: SECTION NAME | J22: Enter section name.
D23: 4 | E23: SUBJECT TYPE | J23: Select the subject type.
D24: 5 | E24: SUBJECT | J24: The selection for the subjects is dependent on the subject type selected.
E25: 5.1 | F25: Other Elective and Special Curricular Program | J25: If applicable, select “Other Elective and Special Curricular Program”, then enter the new elective or subject in the field provided.
D28: As an additional guide, a note regarding where the computation of the final grade can be found will be displayed, depending on the selected subject type and grade level.
C32: C. | D32: LEARNERS' NAMES
D33: Either manually type learners' names or copy from SF1 and copy onto their respective column (Male or Female).
D37: TIP: Press Control + Shift + V to paste values only. | M37: shift ↑ | P37: Z | Q37: X | R37: C | S37: V
M39: ctrl
B43: 2 | C43: Input the raw scores per quarter to compute for the quarterly grades and the semestral or annual final grades.
C46: QUARTERLY GRADES
U54: Color fills are for visualization purposes only and do not represent the actual sheet layouts.
C55: INSTRUCTIONS | G55: DATA INPUT | I55: Q1 | J55: Q2 | K55: Q3 | L55: Q4 | M55: 1st SEMESTRAL GRADE | P55: 2nd SEMESTRAL GRADE | S55: QUARTERLY
D57: HIGHEST POSSIBLE SCORE | J57: Input the highest possible score for each grading component.
D58: ACTUAL SCORE | J58: For each learner, input the actual score accordingly.
D60: The INITIAL GRADE and QUARTERLY GRADE will be computed when all required grading components have been completed.
C64: ! | D64: The weights of the grading components differ depending on the selected Subject type.
K66: CORE | M66: Academic Electives | Q66: TechPro Electives
M67: All Other Electives | O67: Field Experience / Exposure Sports and Arts | Q67: All Other Electives | S67: Work Immersion
E68: WRITTEN WORK | K68: 0.25 | M68: 0.25 | O68: 0.2 | Q68: 0.15 | S68: 0.2
E69: PERFORMANCE TASK | K69: 0.5 | M69: 0.45 | O69: 0.6 | Q69: 0.65 | S69: 0.8
E70: QUARTERLY ASSESSMENT | K70: 0.25 | M70: 0.3 | O70: 0.2 | Q70: 0.2
K71: =SUM(K68:K70) -> 1 | M71: =SUM(M68:M70) -> 1 | O71: =SUM(O68:O70) -> 1 | Q71: =SUM(Q68:Q70) -> 1 | S71: =SUM(S68:S70) -> 1
B74: 3 | C74: Review final grades. The computation of final grades depends on the selected subject type and grade level.
C77: SUMMARY OF FINAL GRADES SHEETS
C79: Subject Type | H79: Duration | K79: Final Grade Computation | O79: Semester Grade | R79: Summary of Grades
C80: Core Subject (All Tracks) | H80: 4 quarters across 2 semesters | K80: Average of 4 quarterly grades | O80: Not Computed | R80: QUARTERLY AVERAGE
C82: Academic Electives (Grades 11 and 12) | H82: 2 quarters per semester | K82: Average of 2 quarterly grades | O82: Computed per semester | R82: 1st SEMESTRAL GRADE
...

Sheet INPUT DATA
D3: Input Data Sheet for Electronic-Class Record (ECR) for SSHS
B7: SCHOOL INFO | J7: LEARNERS' NAMES
C10: REGION | E10: : | F10: Region XI | K10: MALE | N10: FEMALE | AK10: LRN (male, do not edit) | AL10: LRN (female, do not edit)
C11: DIVISION | E11: : | F11: Panabo City | K11: 1 | L11: ALCANTARA, ALDRIN R. | N11: 1 | O11: BASCO, FAITH U. | AK11: 999912000001 | AL11: 999912000019
K12: 2 | L12: AQUINO, KYLE N. | N12: 2 | O12: BAUTISTA, MAE J. | AK12: 999912000002 | AL12: 999912000020
C13: SCHOOL ID | E13: : | F13: DEMO-ARMS | K13: 3 | L13: BAUTISTA, MARK ANTHONY U. | N13: 3 | O13: CABRERA, RHEA Q. | AK13: 999912000003 | AL13: 999912000021
C14: SCHOOL NAME | E14: : | F14: ARMS DEMO NATIONAL HIGH SCHOOL | K14: 4 | L14: CABRERA, RAFAEL C. | N14: 4 | O14: CUIZON, MAE J. | AK14: 999912000004 | AL14: 999912000022
K15: 5 | L15: CASTILLO, JEROME J. | N15: 5 | O15: DIMACULANGAN, MAE B. | AK15: 999912000005 | AL15: 999912000023
C16: SCHOOL YEAR | E16: : | F16: 2026-2027 | K16: 6 | L16: FLORES, RAFAEL Z. | N16: 6 | O16: FLORES, DANICA T. | AK16: 999912000006 | AL16: 999912000024
K17: 7 | L17: GUTIERREZ, NATHANIEL U. | N17: 7 | O17: LACSON, SOFIA B. | AK17: 999912000007 | AL17: 999912000025
K18: 8 | L18: LACSON, KYLE E. | N18: 8 | O18: LOPEZ, CZARINA M. | AK18: 999912000008 | AL18: 999912000026
B19: TEACHER, GRADE LEVEL, AND SUBJECT AREA INFO | K19: 9 | L19: MACARAEG, KENNETH H. | N19: 9 | O19: LUMAPAS, FAITH G. | AK19: 999912000009 | AL19: 999912000027
K20: 10 | L20: NAVARRO, CHRISTIAN O. | N20: 10 | O20: MACARAEG, ANGELICA M. | AK20: 999912000010 | AL20: 999912000028
K21: 11 | L21: PANGANIBAN, VINCENT H. | N21: 11 | O21: MACARAEG, JILLIAN K. | AK21: 999912000011 | AL21: 999912000029
C22: TEACHER | E22: : | F22: ROBERTO MENDOZA | K22: 12 | L22: REYES, CEDRIC I. | N22: 12 | O22: MENDOZA, DIANE R. | AK22: 999912000012 | AL22: 999912000030
K23: 13 | L23: REYES JR., IVAN Y. | N23: 13 | O23: MENDOZA, NICOLE N. | AK23: 999912000013 | AL23: 999912000031
C24: GRADE LEVEL | E24: : | F24: 12 | G24: ← Accepts 11 or 12 only. | K24: 14 | L24: ROSALES, DANIEL O. | N24: 14 | O24: OCAMPO, HANNAH S. | AK24: 999912000014 | AL24: 999912000032
C25: SECTION NAME | E25: : | F25: STEM-CORPUZ | K25: 15 | L25: SANTOS, JERICHO H. | N25: 15 | O25: OCAMPO, SOFIA S. | AK25: 999912000015 | AL25: 999912000033
C26: SUBJECT TYPE | E26: : | F26: Core Subject (All Tracks) | K26: 16 | L26: SANTOS, KENNETH C. | N26: 16 | O26: REYES, HANNAH G. | AK26: 999912000016 | AL26: 999912000034
K27: 17 | L27: TAMPOS, CHRISTIAN B. | N27: 17 | O27: ROSALES, DIANE E. | AK27: 999912000017 | AL27: 999912000035
C28: SUBJECT | E28: : | K28: 18 | L28: VILLANUEVA, FRANCIS M. | N28: 18 | O28: TAMPOS, JILLIAN Y. | AK28: 999912000018 | AL28: 999912000036
K29: 19 | N29: 19 | O29: VILLANUEVA, ANDREA S. | AL29: 999912000037
C30: Other Elective & Special Curricular Program / Subject | E30: : | F30: Understanding Culture, Society and Politics | K30: 20 | N30: 20 | O30: VILLANUEVA, NICOLE E. | AL30: 999912000038
K31: 21 | N31: 21
K32: 22 | N32: 22
C33: =_xlfn.IFNA("NOTE: Find the Final Grade Computation in the "&INDEX('Helper(IMPORTANT!)'!DE1:DF6,MATCH(F26,'Helper(IMPORTANT!)'!DD1:DD6,0),MATCH(F24,'Helper(IMPORTANT!)'!DE1:DF1,0))&" sheet/s.","") -> NOTE: Find the Final Grade Computation in the sheet/s. | K33: 23 | N33: 23
K34: 24 | N34: 24
C35: =_xlfn.IFNA(IF(INDEX('Helper(IMPORTANT!)'!DE1:DF6,MATCH(F26,'Helper(IMPORTANT!)'!DD1:DD6,0),MATCH(F24,'Helper(IMPORTANT!)'!DE1:DF1,0))="QUARTERLY AVERAGE","QUARTERLY AVERAGE","1st SEMESTRAL GRADE"),"") -> 1st SEMESTRAL GRADE | G35: =_xlfn.IFNA(IF(INDEX('Helper(IMPORTANT!)'!DE1:DF6,MATCH(F26,'Helper(IMPORTANT!)'!DD1:DD6,0),MATCH(F24,'Helper(IMPORTANT!)'!DE1:DF1,0))="QUARTERLY AVERAGE","QUARTERLY AVERAGE","2nd SEMESTRAL GRADE"),"") -> 2nd SEMESTRAL GRADE | K35: 25 | N35: 25
K36: 26 | N36: 26
K37: 27 | N37: 27
K38: 28 | N38: 28
K39: 29 | N39: 29
K40: 30 | N40: 30
K41: 31 | N41: 31
K42: 32 | N42: 32
K43: 33 | N43: 33
K44: 34 | N44: 34
K45: 35 | N45: 35
K46: 36 | N46: 36
K47: 37 | N47: 37
...

Sheet Q1
A1: Strengthened Senior High School Class Record
A3: (Pursuant to Deped Order 8 series of 2015)
F4: REGION | G4: ='INPUT DATA'!F10 -> Region XI | L4: DIVISION | O4: ='INPUT DATA'!F11 -> Panabo City
F5: SCHOOL NAME | G5: ='INPUT DATA'!F14 -> ARMS DEMO NATIONAL HIGH SCHOOL | T5: SCHOOL ID | X5: ='INPUT DATA'!F13 -> DEMO-ARMS | AD5: SCHOOL YEAR | AG5: ='INPUT DATA'!F16 -> 2026-2027
A7: FIRST QUARTER | F7: GRADE & SECTION: | K7: ='INPUT DATA'!F24&" - "&'INPUT DATA'!F25 -> 12 - STEM-CORPUZ | Q7: TEACHER: | S7: ='INPUT DATA'!F22 -> ROBERTO MENDOZA | AC7: SUBJECT: | AE7: =IF('INPUT DATA'!F30<>"",'INPUT DATA'!F30,'INPUT DATA'!F28) -> Understanding Culture, Society and Politics
Q8: SEMESTER: | S8: - - | AC8: SUBJECT TYPE: | AE8: ='INPUT DATA'!F26 -> Core Subject (All Tracks)
A9: LEARNERS' NAMES | F9: =IF('INPUT DATA'!$F$26="","",INDEX('Helper(IMPORTANT!)'!$CI$2:$CI$6,MATCH(AE8,'Helper(IMPORTANT!)'!$CH$2:$CH$6,0))) -> WRITTEN WORK (25%) | S9: =IF('INPUT DATA'!$F$26="","",INDEX('Helper(IMPORTANT!)'!$CJ$2:$CJ$6,MATCH(AE8,'Helper(IMPORTANT!)'!$CH$2:$CH$6,0))) -> PERFORMANCE TASK (50%) | AF9: =IF('INPUT DATA'!$F$26="","",INDEX('Helper(IMPORTANT!)'!$CK$2:$CK$6,MATCH(AE8,'Helper(IMPORTANT!)'!$CH$2:$CH$6,0))) -> QUARTERLY ASSESSMENT (25%) | AI9: Initial Grade | AJ9: Quarterly Grade
F10: 1 | G10: 2 | H10: 3 | I10: 4 | J10: 5 | K10: 6 | L10: 7 | M10: 8 | N10: 9 | O10: 10 | P10: Total | Q10: PS | R10: WS | S10: 1 | T10: 2 | U10: 3 | V10: 4 | W10: 5 | X10: 6 | Y10: 7 | Z10: 8 | AA10: 9 | AB10: 10 | AC10: Total | AD10: PS | AE10: WS | AF10: 1 | AG10: PS | AH10: WS
A11: HIGHEST POSSIBLE SCORE | P11: =IF(COUNT($F11:$O11)=0,"",SUM($F11:$O11)) | Q11: 100 | R11: =IF('INPUT DATA'!$F$26="","",INDEX('Helper(IMPORTANT!)'!$CL$2:$CL$6,MATCH(AE8,'Helper(IMPORTANT!)'!$CH$2:$CH$6,0))) -> 0.25 | AC11: =IF(COUNT($S11:$AB11)=0,"",SUM($S11:$AB11)) | AD11: 100 | AE11: =IF('INPUT DATA'!$F$26="","",INDEX('Helper(IMPORTANT!)'!$CM$2:$CM$6,MATCH(AE8,'Helper(IMPORTANT!)'!$CH$2:$CH$6,0))) -> 0.5 | AG11: 100 | AH11: =IF('INPUT DATA'!$F$26="","",INDEX('Helper(IMPORTANT!)'!$CN$2:$CN$6,MATCH(AE8,'Helper(IMPORTANT!)'!$CH$2:$CH$6,0))) -> 0.25
A12: MALE
A13: 1 | B13: ='INPUT DATA'!L11 -> ALCANTARA, ALDRIN R. | P13: =IF(COUNT($F13:$O13)=0,"",SUM($F13:$O13)) | Q13: =IFERROR(IF(P13="","",ROUND(P13/$P$11*100,2)),"") | R13: =IFERROR(IF(Q13="","",ROUND(Q13*$R$11,2)),"") | AC13: =IF(COUNT($S13:$AB13)=0,"",SUM($S13:$AB13)) | AD13: =IFERROR(IF(AC13="","",ROUND(AC13/$AC$11*100,2)),"") | AE13: =IFERROR(IF(AD13="","",ROUND(AD13*$AE$11,2)),"") | AG13: =IFERROR(IF(AF13="","",ROUND(AF13/$AF$11*100,2)),"") | AH13: =IFERROR(IF(AG13="","",ROUND(AG13*$AH$11,2)),"") | AI13: =IFERROR(R13+AE13+AH13,"") | AJ13: =IFERROR(VLOOKUP(AI13,'Helper(IMPORTANT!)'!$CQ$1:$CR$41,2,TRUE),"")
A14: 2 | B14: ='INPUT DATA'!L12 -> AQUINO, KYLE N. | P14: =IF(COUNT($F14:$O14)=0,"",SUM($F14:$O14)) | Q14: =IFERROR(IF(P14="","",ROUND(P14/$P$11*100,2)),"") | R14: =IFERROR(IF(Q14="","",ROUND(Q14*$R$11,2)),"") | AC14: =IF(COUNT($S14:$AB14)=0,"",SUM($S14:$AB14)) | AD14: =IFERROR(IF(AC14="","",ROUND(AC14/$AC$11*100,2)),"") | AE14: =IFERROR(IF(AD14="","",ROUND(AD14*$AE$11,2)),"") | AG14: =IFERROR(IF(AF14="","",ROUND(AF14/$AF$11*100,2)),"") | AH14: =IFERROR(IF(AG14="","",ROUND(AG14*$AH$11,2)),"") | AI14: =IFERROR(R14+AE14+AH14,"") | AJ14: =IFERROR(VLOOKUP(AI14,'Helper(IMPORTANT!)'!$CQ$1:$CR$41,2,TRUE),"")
A15: 3 | B15: ='INPUT DATA'!L13 -> BAUTISTA, MARK ANTHONY U. | P15: =IF(COUNT($F15:$O15)=0,"",SUM($F15:$O15)) | Q15: =IFERROR(IF(P15="","",ROUND(P15/$P$11*100,2)),"") | R15: =IFERROR(IF(Q15="","",ROUND(Q15*$R$11,2)),"") | AC15: =IF(COUNT($S15:$AB15)=0,"",SUM($S15:$AB15)) | AD15: =IFERROR(IF(AC15="","",ROUND(AC15/$AC$11*100,2)),"") | AE15: =IFERROR(IF(AD15="","",ROUND(AD15*$AE$11,2)),"") | AG15: =IFERROR(IF(AF15="","",ROUND(AF15/$AF$11*100,2)),"") | AH15: =IFERROR(IF(AG15="","",ROUND(AG15*$AH$11,2)),"") | AI15: =IFERROR(R15+AE15+AH15,"") | AJ15: =IFERROR(VLOOKUP(AI15,'Helper(IMPORTANT!)'!$CQ$1:$CR$41,2,TRUE),"")
A16: 4 | B16: ='INPUT DATA'!L14 -> CABRERA, RAFAEL C. | P16: =IF(COUNT($F16:$O16)=0,"",SUM($F16:$O16)) | Q16: =IFERROR(IF(P16="","",ROUND(P16/$P$11*100,2)),"") | R16: =IFERROR(IF(Q16="","",ROUND(Q16*$R$11,2)),"") | AC16: =IF(COUNT($S16:$AB16)=0,"",SUM($S16:$AB16)) | AD16: =IFERROR(IF(AC16="","",ROUND(AC16/$AC$11*100,2)),"") | AE16: =IFERROR(IF(AD16="","",ROUND(AD16*$AE$11,2)),"") | AG16: =IFERROR(IF(AF16="","",ROUND(AF16/$AF$11*100,2)),"") | AH16: =IFERROR(IF(AG16="","",ROUND(AG16*$AH$11,2)),"") | AI16: =IFERROR(R16+AE16+AH16,"") | AJ16: =IFERROR(VLOOKUP(AI16,'Helper(IMPORTANT!)'!$CQ$1:$CR$41,2,TRUE),"")
A17: 5 | B17: ='INPUT DATA'!L15 -> CASTILLO, JEROME J. | P17: =IF(COUNT($F17:$O17)=0,"",SUM($F17:$O17)) | Q17: =IFERROR(IF(P17="","",ROUND(P17/$P$11*100,2)),"") | R17: =IFERROR(IF(Q17="","",ROUND(Q17*$R$11,2)),"") | AC17: =IF(COUNT($S17:$AB17)=0,"",SUM($S17:$AB17)) | AD17: =IFERROR(IF(AC17="","",ROUND(AC17/$AC$11*100,2)),"") | AE17: =IFERROR(IF(AD17="","",ROUND(AD17*$AE$11,2)),"") | AG17: =IFERROR(IF(AF17="","",ROUND(AF17/$AF$11*100,2)),"") | AH17: =IFERROR(IF(AG17="","",ROUND(AG17*$AH$11,2)),"") | AI17: =IFERROR(R17+AE17+AH17,"") | AJ17: =IFERROR(VLOOKUP(AI17,'Helper(IMPORTANT!)'!$CQ$1:$CR$41,2,TRUE),"")
A18: 6 | B18: ='INPUT DATA'!L16 -> FLORES, RAFAEL Z. | P18: =IF(COUNT($F18:$O18)=0,"",SUM($F18:$O18)) | Q18: =IFERROR(IF(P18="","",ROUND(P18/$P$11*100,2)),"") | R18: =IFERROR(IF(Q18="","",ROUND(Q18*$R$11,2)),"") | AC18: =IF(COUNT($S18:$AB18)=0,"",SUM($S18:$AB18)) | AD18: =IFERROR(IF(AC18="","",ROUND(AC18/$AC$11*100,2)),"") | AE18: =IFERROR(IF(AD18="","",ROUND(AD18*$AE$11,2)),"") | AG18: =IFERROR(IF(AF18="","",ROUND(AF18/$AF$11*100,2)),"") | AH18: =IFERROR(IF(AG18="","",ROUND(AG18*$AH$11,2)),"") | AI18: =IFERROR(R18+AE18+AH18,"") | AJ18: =IFERROR(VLOOKUP(AI18,'Helper(IMPORTANT!)'!$CQ$1:$CR$41,2,TRUE),"")
A19: 7 | B19: ='INPUT DATA'!L17 -> GUTIERREZ, NATHANIEL U. | P19: =IF(COUNT($F19:$O19)=0,"",SUM($F19:$O19)) | Q19: =IFERROR(IF(P19="","",ROUND(P19/$P$11*100,2)),"") | R19: =IFERROR(IF(Q19="","",ROUND(Q19*$R$11,2)),"") | AC19: =IF(COUNT($S19:$AB19)=0,"",SUM($S19:$AB19)) | AD19: =IFERROR(IF(AC19="","",ROUND(AC19/$AC$11*100,2)),"") | AE19: =IFERROR(IF(AD19="","",ROUND(AD19*$AE$11,2)),"") | AG19: =IFERROR(IF(AF19="","",ROUND(AF19/$AF$11*100,2)),"") | AH19: =IFERROR(IF(AG19="","",ROUND(AG19*$AH$11,2)),"") | AI19: =IFERROR(R19+AE19+AH19,"") | AJ19: =IFERROR(VLOOKUP(AI19,'Helper(IMPORTANT!)'!$CQ$1:$CR$41,2,TRUE),"")
A20: 8 | B20: ='INPUT DATA'!L18 -> LACSON, KYLE E. | P20: =IF(COUNT($F20:$O20)=0,"",SUM($F20:$O20)) | Q20: =IFERROR(IF(P20="","",ROUND(P20/$P$11*100,2)),"") | R20: =IFERROR(IF(Q20="","",ROUND(Q20*$R$11,2)),"") | AC20: =IF(COUNT($S20:$AB20)=0,"",SUM($S20:$AB20)) | AD20: =IFERROR(IF(AC20="","",ROUND(AC20/$AC$11*100,2)),"") | AE20: =IFERROR(IF(AD20="","",ROUND(AD20*$AE$11,2)),"") | AG20: =IFERROR(IF(AF20="","",ROUND(AF20/$AF$11*100,2)),"") | AH20: =IFERROR(IF(AG20="","",ROUND(AG20*$AH$11,2)),"") | AI20: =IFERROR(R20+AE20+AH20,"") | AJ20: =IFERROR(VLOOKUP(AI20,'Helper(IMPORTANT!)'!$CQ$1:$CR$41,2,TRUE),"")
A21: 9 | B21: ='INPUT DATA'!L19 -> MACARAEG, KENNETH H. | P21: =IF(COUNT($F21:$O21)=0,"",SUM($F21:$O21)) | Q21: =IFERROR(IF(P21="","",ROUND(P21/$P$11*100,2)),"") | R21: =IFERROR(IF(Q21="","",ROUND(Q21*$R$11,2)),"") | AC21: =IF(COUNT($S21:$AB21)=0,"",SUM($S21:$AB21)) | AD21: =IFERROR(IF(AC21="","",ROUND(AC21/$AC$11*100,2)),"") | AE21: =IFERROR(IF(AD21="","",ROUND(AD21*$AE$11,2)),"") | AG21: =IFERROR(IF(AF21="","",ROUND(AF21/$AF$11*100,2)),"") | AH21: =IFERROR(IF(AG21="","",ROUND(AG21*$AH$11,2)),"") | AI21: =IFERROR(R21+AE21+AH21,"") | AJ21: =IFERROR(VLOOKUP(AI21,'Helper(IMPORTANT!)'!$CQ$1:$CR$41,2,TRUE),"")
A22: 10 | B22: ='INPUT DATA'!L20 -> NAVARRO, CHRISTIAN O. | P22: =IF(COUNT($F22:$O22)=0,"",SUM($F22:$O22)) | Q22: =IFERROR(IF(P22="","",ROUND(P22/$P$11*100,2)),"") | R22: =IFERROR(IF(Q22="","",ROUND(Q22*$R$11,2)),"") | AC22: =IF(COUNT($S22:$AB22)=0,"",SUM($S22:$AB22)) | AD22: =IFERROR(IF(AC22="","",ROUND(AC22/$AC$11*100,2)),"") | AE22: =IFERROR(IF(AD22="","",ROUND(AD22*$AE$11,2)),"") | AG22: =IFERROR(IF(AF22="","",ROUND(AF22/$AF$11*100,2)),"") | AH22: =IFERROR(IF(AG22="","",ROUND(AG22*$AH$11,2)),"") | AI22: =IFERROR(R22+AE22+AH22,"") | AJ22: =IFERROR(VLOOKUP(AI22,'Helper(IMPORTANT!)'!$CQ$1:$CR$41,2,TRUE),"")
A23: 11 | B23: ='INPUT DATA'!L21 -> PANGANIBAN, VINCENT H. | P23: =IF(COUNT($F23:$O23)=0,"",SUM($F23:$O23)) | Q23: =IFERROR(IF(P23="","",ROUND(P23/$P$11*100,2)),"") | R23: =IFERROR(IF(Q23="","",ROUND(Q23*$R$11,2)),"") | AC23: =IF(COUNT($S23:$AB23)=0,"",SUM($S23:$AB23)) | AD23: =IFERROR(IF(AC23="","",ROUND(AC23/$AC$11*100,2)),"") | AE23: =IFERROR(IF(AD23="","",ROUND(AD23*$AE$11,2)),"") | AG23: =IFERROR(IF(AF23="","",ROUND(AF23/$AF$11*100,2)),"") | AH23: =IFERROR(IF(AG23="","",ROUND(AG23*$AH$11,2)),"") | AI23: =IFERROR(R23+AE23+AH23,"") | AJ23: =IFERROR(VLOOKUP(AI23,'Helper(IMPORTANT!)'!$CQ$1:$CR$41,2,TRUE),"")
A24: 12 | B24: ='INPUT DATA'!L22 -> REYES, CEDRIC I. | P24: =IF(COUNT($F24:$O24)=0,"",SUM($F24:$O24)) | Q24: =IFERROR(IF(P24="","",ROUND(P24/$P$11*100,2)),"") | R24: =IFERROR(IF(Q24="","",ROUND(Q24*$R$11,2)),"") | AC24: =IF(COUNT($S24:$AB24)=0,"",SUM($S24:$AB24)) | AD24: =IFERROR(IF(AC24="","",ROUND(AC24/$AC$11*100,2)),"") | AE24: =IFERROR(IF(AD24="","",ROUND(AD24*$AE$11,2)),"") | AG24: =IFERROR(IF(AF24="","",ROUND(AF24/$AF$11*100,2)),"") | AH24: =IFERROR(IF(AG24="","",ROUND(AG24*$AH$11,2)),"") | AI24: =IFERROR(R24+AE24+AH24,"") | AJ24: =IFERROR(VLOOKUP(AI24,'Helper(IMPORTANT!)'!$CQ$1:$CR$41,2,TRUE),"")
... A62: 50 | B62: ='INPUT DATA'!L60 -> 0 | P62: =IF(COUNT($F62:$O62)=0,"",SUM($F62:$O62)) | Q62: =IFERROR(IF(P62="","",ROUND(P62/$P$11*100,2)),"") | R62: =IFERROR(IF(Q62="","",ROUND(Q62*$R$11,2)),"") | AC62: =IF(COUNT($S62:$AB62)=0,"",SUM($S62:$AB62)) | AD62: =IFERROR(IF(AC62="","",ROUND(AC62/$AC$11*100,2)),"") | AE62: =IFERROR(IF(AD62="","",ROUND(AD62*$AE$11,2)),"") | AG62: =IFERROR(IF(AF62="","",ROUND(AF62/$AF$11*100,2)),"") | AH62: =IFERROR(IF(AG62="","",ROUND(AG62*$AH$11,2)),"") | AI62: =IFERROR(R62+AE62+AH62,"") | AJ62: =IFERROR(VLOOKUP(AI62,'Helper(IMPORTANT!)'!$CQ$1:$CR$41,2,TRUE),"")
A63: FEMALE
A64: 1 | B64: ='INPUT DATA'!O11 -> BASCO, FAITH U. | P64: =IF(COUNT($F64:$O64)=0,"",SUM($F64:$O64)) | Q64: =IFERROR(IF(P64="","",ROUND(P64/$P$11*100,2)),"") | R64: =IFERROR(IF(Q64="","",ROUND(Q64*$R$11,2)),"") | AC64: =IF(COUNT($S64:$AB64)=0,"",SUM($S64:$AB64)) | AD64: =IFERROR(IF(AC64="","",ROUND(AC64/$AC$11*100,2)),"") | AE64: =IFERROR(IF(AD64="","",ROUND(AD64*$AE$11,2)),"") | AG64: =IFERROR(IF(AF64="","",ROUND(AF64/$AF$11*100,2)),"") | AH64: =IFERROR(IF(AG64="","",ROUND(AG64*$AH$11,2)),"") | AI64: =IFERROR(R64+AE64+AH64,"") | AJ64: =IFERROR(VLOOKUP(AI64,'Helper(IMPORTANT!)'!$CQ$1:$CR$41,2,TRUE),"")
A65: 2 | B65: ='INPUT DATA'!O12 -> BAUTISTA, MAE J. | P65: =IF(COUNT($F65:$O65)=0,"",SUM($F65:$O65)) | Q65: =IFERROR(IF(P65="","",ROUND(P65/$P$11*100,2)),"") | R65: =IFERROR(IF(Q65="","",ROUND(Q65*$R$11,2)),"") | AC65: =IF(COUNT($S65:$AB65)=0,"",SUM($S65:$AB65)) | AD65: =IFERROR(IF(AC65="","",ROUND(AC65/$AC$11*100,2)),"") | AE65: =IFERROR(IF(AD65="","",ROUND(AD65*$AE$11,2)),"") | AG65: =IFERROR(IF(AF65="","",ROUND(AF65/$AF$11*100,2)),"") | AH65: =IFERROR(IF(AG65="","",ROUND(AG65*$AH$11,2)),"") | AI65: =IFERROR(R65+AE65+AH65,"") | AJ65: =IFERROR(VLOOKUP(AI65,'Helper(IMPORTANT!)'!$CQ$1:$CR$41,2,TRUE),"")
A66: 3 | B66: ='INPUT DATA'!O13 -> CABRERA, RHEA Q. | P66: =IF(COUNT($F66:$O66)=0,"",SUM($F66:$O66)) | Q66: =IFERROR(IF(P66="","",ROUND(P66/$P$11*100,2)),"") | R66: =IFERROR(IF(Q66="","",ROUND(Q66*$R$11,2)),"") | AC66: =IF(COUNT($S66:$AB66)=0,"",SUM($S66:$AB66)) | AD66: =IFERROR(IF(AC66="","",ROUND(AC66/$AC$11*100,2)),"") | AE66: =IFERROR(IF(AD66="","",ROUND(AD66*$AE$11,2)),"") | AG66: =IFERROR(IF(AF66="","",ROUND(AF66/$AF$11*100,2)),"") | AH66: =IFERROR(IF(AG66="","",ROUND(AG66*$AH$11,2)),"") | AI66: =IFERROR(R66+AE66+AH66,"") | AJ66: =IFERROR(VLOOKUP(AI66,'Helper(IMPORTANT!)'!$CQ$1:$CR$41,2,TRUE),"")
A67: 4 | B67: ='INPUT DATA'!O14 -> CUIZON, MAE J. | P67: =IF(COUNT($F67:$O67)=0,"",SUM($F67:$O67)) | Q67: =IFERROR(IF(P67="","",ROUND(P67/$P$11*100,2)),"") | R67: =IFERROR(IF(Q67="","",ROUND(Q67*$R$11,2)),"") | AC67: =IF(COUNT($S67:$AB67)=0,"",SUM($S67:$AB67)) | AD67: =IFERROR(IF(AC67="","",ROUND(AC67/$AC$11*100,2)),"") | AE67: =IFERROR(IF(AD67="","",ROUND(AD67*$AE$11,2)),"") | AG67: =IFERROR(IF(AF67="","",ROUND(AF67/$AF$11*100,2)),"") | AH67: =IFERROR(IF(AG67="","",ROUND(AG67*$AH$11,2)),"") | AI67: =IFERROR(R67+AE67+AH67,"") | AJ67: =IFERROR(VLOOKUP(AI67,'Helper(IMPORTANT!)'!$CQ$1:$CR$41,2,TRUE),"")
A68: 5 | B68: ='INPUT DATA'!O15 -> DIMACULANGAN, MAE B. | P68: =IF(COUNT($F68:$O68)=0,"",SUM($F68:$O68)) | Q68: =IFERROR(IF(P68="","",ROUND(P68/$P$11*100,2)),"") | R68: =IFERROR(IF(Q68="","",ROUND(Q68*$R$11,2)),"") | AC68: =IF(COUNT($S68:$AB68)=0,"",SUM($S68:$AB68)) | AD68: =IFERROR(IF(AC68="","",ROUND(AC68/$AC$11*100,2)),"") | AE68: =IFERROR(IF(AD68="","",ROUND(AD68*$AE$11,2)),"") | AG68: =IFERROR(IF(AF68="","",ROUND(AF68/$AF$11*100,2)),"") | AH68: =IFERROR(IF(AG68="","",ROUND(AG68*$AH$11,2)),"") | AI68: =IFERROR(R68+AE68+AH68,"") | AJ68: =IFERROR(VLOOKUP(AI68,'Helper(IMPORTANT!)'!$CQ$1:$CR$41,2,TRUE),"")
A69: 6 | B69: ='INPUT DATA'!O16 -> FLORES, DANICA T. | P69: =IF(COUNT($F69:$O69)=0,"",SUM($F69:$O69)) | Q69: =IFERROR(IF(P69="","",ROUND(P69/$P$11*100,2)),"") | R69: =IFERROR(IF(Q69="","",ROUND(Q69*$R$11,2)),"") | AC69: =IF(COUNT($S69:$AB69)=0,"",SUM($S69:$AB69)) | AD69: =IFERROR(IF(AC69="","",ROUND(AC69/$AC$11*100,2)),"") | AE69: =IFERROR(IF(AD69="","",ROUND(AD69*$AE$11,2)),"") | AG69: =IFERROR(IF(AF69="","",ROUND(AF69/$AF$11*100,2)),"") | AH69: =IFERROR(IF(AG69="","",ROUND(AG69*$AH$11,2)),"") | AI69: =IFERROR(R69+AE69+AH69,"") | AJ69: =IFERROR(VLOOKUP(AI69,'Helper(IMPORTANT!)'!$CQ$1:$CR$41,2,TRUE),"")
A70: 7 | B70: ='INPUT DATA'!O17 -> LACSON, SOFIA B. | P70: =IF(COUNT($F70:$O70)=0,"",SUM($F70:$O70)) | Q70: =IFERROR(IF(P70="","",ROUND(P70/$P$11*100,2)),"") | R70: =IFERROR(IF(Q70="","",ROUND(Q70*$R$11,2)),"") | AC70: =IF(COUNT($S70:$AB70)=0,"",SUM($S70:$AB70)) | AD70: =IFERROR(IF(AC70="","",ROUND(AC70/$AC$11*100,2)),"") | AE70: =IFERROR(IF(AD70="","",ROUND(AD70*$AE$11,2)),"") | AG70: =IFERROR(IF(AF70="","",ROUND(AF70/$AF$11*100,2)),"") | AH70: =IFERROR(IF(AG70="","",ROUND(AG70*$AH$11,2)),"") | AI70: =IFERROR(R70+AE70+AH70,"") | AJ70: =IFERROR(VLOOKUP(AI70,'Helper(IMPORTANT!)'!$CQ$1:$CR$41,2,TRUE),"")
A71: 8 | B71: ='INPUT DATA'!O18 -> LOPEZ, CZARINA M. | P71: =IF(COUNT($F71:$O71)=0,"",SUM($F71:$O71)) | Q71: =IFERROR(IF(P71="","",ROUND(P71/$P$11*100,2)),"") | R71: =IFERROR(IF(Q71="","",ROUND(Q71*$R$11,2)),"") | AC71: =IF(COUNT($S71:$AB71)=0,"",SUM($S71:$AB71)) | AD71: =IFERROR(IF(AC71="","",ROUND(AC71/$AC$11*100,2)),"") | AE71: =IFERROR(IF(AD71="","",ROUND(AD71*$AE$11,2)),"") | AG71: =IFERROR(IF(AF71="","",ROUND(AF71/$AF$11*100,2)),"") | AH71: =IFERROR(IF(AG71="","",ROUND(AG71*$AH$11,2)),"") | AI71: =IFERROR(R71+AE71+AH71,"") | AJ71: =IFERROR(VLOOKUP(AI71,'Helper(IMPORTANT!)'!$CQ$1:$CR$41,2,TRUE),"")
A72: 9 | B72: ='INPUT DATA'!O19 -> LUMAPAS, FAITH G. | P72: =IF(COUNT($F72:$O72)=0,"",SUM($F72:$O72)) | Q72: =IFERROR(IF(P72="","",ROUND(P72/$P$11*100,2)),"") | R72: =IFERROR(IF(Q72="","",ROUND(Q72*$R$11,2)),"") | AC72: =IF(COUNT($S72:$AB72)=0,"",SUM($S72:$AB72)) | AD72: =IFERROR(IF(AC72="","",ROUND(AC72/$AC$11*100,2)),"") | AE72: =IFERROR(IF(AD72="","",ROUND(AD72*$AE$11,2)),"") | AG72: =IFERROR(IF(AF72="","",ROUND(AF72/$AF$11*100,2)),"") | AH72: =IFERROR(IF(AG72="","",ROUND(AG72*$AH$11,2)),"") | AI72: =IFERROR(R72+AE72+AH72,"") | AJ72: =IFERROR(VLOOKUP(AI72,'Helper(IMPORTANT!)'!$CQ$1:$CR$41,2,TRUE),"")
A73: 10 | B73: ='INPUT DATA'!O20 -> MACARAEG, ANGELICA M. | P73: =IF(COUNT($F73:$O73)=0,"",SUM($F73:$O73)) | Q73: =IFERROR(IF(P73="","",ROUND(P73/$P$11*100,2)),"") | R73: =IFERROR(IF(Q73="","",ROUND(Q73*$R$11,2)),"") | AC73: =IF(COUNT($S73:$AB73)=0,"",SUM($S73:$AB73)) | AD73: =IFERROR(IF(AC73="","",ROUND(AC73/$AC$11*100,2)),"") | AE73: =IFERROR(IF(AD73="","",ROUND(AD73*$AE$11,2)),"") | AG73: =IFERROR(IF(AF73="","",ROUND(AF73/$AF$11*100,2)),"") | AH73: =IFERROR(IF(AG73="","",ROUND(AG73*$AH$11,2)),"") | AI73: =IFERROR(R73+AE73+AH73,"") | AJ73: =IFERROR(VLOOKUP(AI73,'Helper(IMPORTANT!)'!$CQ$1:$CR$41,2,TRUE),"")
A74: 11 | B74: ='INPUT DATA'!O21 -> MACARAEG, JILLIAN K. | P74: =IF(COUNT($F74:$O74)=0,"",SUM($F74:$O74)) | Q74: =IFERROR(IF(P74="","",ROUND(P74/$P$11*100,2)),"") | R74: =IFERROR(IF(Q74="","",ROUND(Q74*$R$11,2)),"") | AC74: =IF(COUNT($S74:$AB74)=0,"",SUM($S74:$AB74)) | AD74: =IFERROR(IF(AC74="","",ROUND(AC74/$AC$11*100,2)),"") | AE74: =IFERROR(IF(AD74="","",ROUND(AD74*$AE$11,2)),"") | AG74: =IFERROR(IF(AF74="","",ROUND(AF74/$AF$11*100,2)),"") | AH74: =IFERROR(IF(AG74="","",ROUND(AG74*$AH$11,2)),"") | AI74: =IFERROR(R74+AE74+AH74,"") | AJ74: =IFERROR(VLOOKUP(AI74,'Helper(IMPORTANT!)'!$CQ$1:$CR$41,2,TRUE),"")
A75: 12 | B75: ='INPUT DATA'!O22 -> MENDOZA, DIANE R. | P75: =IF(COUNT($F75:$O75)=0,"",SUM($F75:$O75)) | Q75: =IFERROR(IF(P75="","",ROUND(P75/$P$11*100,2)),"") | R75: =IFERROR(IF(Q75="","",ROUND(Q75*$R$11,2)),"") | AC75: =IF(COUNT($S75:$AB75)=0,"",SUM($S75:$AB75)) | AD75: =IFERROR(IF(AC75="","",ROUND(AC75/$AC$11*100,2)),"") | AE75: =IFERROR(IF(AD75="","",ROUND(AD75*$AE$11,2)),"") | AG75: =IFERROR(IF(AF75="","",ROUND(AF75/$AF$11*100,2)),"") | AH75: =IFERROR(IF(AG75="","",ROUND(AG75*$AH$11,2)),"") | AI75: =IFERROR(R75+AE75+AH75,"") | AJ75: =IFERROR(VLOOKUP(AI75,'Helper(IMPORTANT!)'!$CQ$1:$CR$41,2,TRUE),"")
... A113: 50 | B113: ='INPUT DATA'!O60 -> 0 | P113: =IF(COUNT($F113:$O113)=0,"",SUM($F113:$O113)) | Q113: =IFERROR(IF(P113="","",ROUND(P113/$P$11*100,2)),"") | R113: =IFERROR(IF(Q113="","",ROUND(Q113*$R$11,2)),"") | AC113: =IF(COUNT($S113:$AB113)=0,"",SUM($S113:$AB113)) | AD113: =IFERROR(IF(AC113="","",ROUND(AC113/$AC$11*100,2)),"") | AE113: =IFERROR(IF(AD113="","",ROUND(AD113*$AE$11,2)),"") | AG113: =IFERROR(IF(AF113="","",ROUND(AF113/$AF$11*100,2)),"") | AH113: =IFERROR(IF(AG113="","",ROUND(AG113*$AH$11,2)),"") | AI113: =IFERROR(R113+AE113+AH113,"") | AJ113: =IFERROR(VLOOKUP(AI113,'Helper(IMPORTANT!)'!$CQ$1:$CR$41,2,TRUE),"")

Sheet Q2
A1: Strengthened Senior High School Class Record
A3: (Pursuant to Deped Order 8 series of 2015)
F4: REGION | G4: ='INPUT DATA'!F10 -> Region XI | L4: DIVISION | O4: ='INPUT DATA'!F11 -> Panabo City
F5: SCHOOL NAME | G5: ='INPUT DATA'!F14 -> ARMS DEMO NATIONAL HIGH SCHOOL | T5: SCHOOL ID | X5: ='INPUT DATA'!F13 -> DEMO-ARMS | AD5: SCHOOL YEAR | AG5: ='INPUT DATA'!F16 -> 2026-2027
A7: SECOND QUARTER | F7: GRADE & SECTION: | K7: ='INPUT DATA'!F24&" - "&'INPUT DATA'!F25 -> 12 - STEM-CORPUZ | Q7: TEACHER: | S7: ='INPUT DATA'!F22 -> ROBERTO MENDOZA | AC7: SUBJECT: | AE7: =IF('INPUT DATA'!F30<>"",'INPUT DATA'!F30,'INPUT DATA'!F28) -> Understanding Culture, Society and Politics
Q8: SEMESTER: | S8: - - | AC8: SUBJECT TYPE: | AE8: ='INPUT DATA'!F26 -> Core Subject (All Tracks)
A9: LEARNERS' NAMES | F9: =IF('INPUT DATA'!$F$26="","",INDEX('Helper(IMPORTANT!)'!$CI$2:$CI$6,MATCH(AE8,'Helper(IMPORTANT!)'!$CH$2:$CH$6,0))) -> WRITTEN WORK (25%) | S9: =IF('INPUT DATA'!$F$26="","",INDEX('Helper(IMPORTANT!)'!$CJ$2:$CJ$6,MATCH(AE8,'Helper(IMPORTANT!)'!$CH$2:$CH$6,0))) -> PERFORMANCE TASK (50%) | AF9: =IF('INPUT DATA'!$F$26="","",INDEX('Helper(IMPORTANT!)'!$CK$2:$CK$6,MATCH(AE8,'Helper(IMPORTANT!)'!$CH$2:$CH$6,0))) -> QUARTERLY ASSESSMENT (25%) | AI9: Initial Grade | AJ9: Quarterly Grade
F10: 1 | G10: 2 | H10: 3 | I10: 4 | J10: 5 | K10: 6 | L10: 7 | M10: 8 | N10: 9 | O10: 10 | P10: Total | Q10: PS | R10: WS | S10: 1 | T10: 2 | U10: 3 | V10: 4 | W10: 5 | X10: 6 | Y10: 7 | Z10: 8 | AA10: 9 | AB10: 10 | AC10: Total | AD10: PS | AE10: WS | AF10: 1 | AG10: PS | AH10: WS
A11: HIGHEST POSSIBLE SCORE | F11: 10 | G11: 10 | H11: 10 | I11: 10 | J11: 10 | P11: =IF(COUNT($F11:$O11)=0,"",SUM($F11:$O11)) -> 50 | Q11: 100 | R11: =IF('INPUT DATA'!$F$26="","",INDEX('Helper(IMPORTANT!)'!$CL$2:$CL$6,MATCH(AE8,'Helper(IMPORTANT!)'!$CH$2:$CH$6,0))) -> 0.25 | S11: 50 | AC11: =IF(COUNT($S11:$AB11)=0,"",SUM($S11:$AB11)) -> 50 | AD11: 100 | AE11: =IF('INPUT DATA'!$F$26="","",INDEX('Helper(IMPORTANT!)'!$CM$2:$CM$6,MATCH(AE8,'Helper(IMPORTANT!)'!$CH$2:$CH$6,0))) -> 0.5 | AF11: 50 | AG11: 100 | AH11: =IF('INPUT DATA'!$F$26="","",INDEX('Helper(IMPORTANT!)'!$CN$2:$CN$6,MATCH(AE8,'Helper(IMPORTANT!)'!$CH$2:$CH$6,0))) -> 0.25
A12: MALE
A13: 1 | B13: ='INPUT DATA'!L11 -> ALCANTARA, ALDRIN R. | F13: 9 | G13: 6 | H13: 5 | I13: 9 | J13: 10 | P13: =IF(COUNT($F13:$O13)=0,"",SUM($F13:$O13)) -> 39 | Q13: =IFERROR(IF(P13="","",ROUND(P13/$P$11*100,2)),"") -> 78 | R13: =IFERROR(IF(Q13="","",ROUND(Q13*$R$11,2)),"") -> 19.5 | S13: 50 | AC13: =IF(COUNT($S13:$AB13)=0,"",SUM($S13:$AB13)) -> 50 | AD13: =IFERROR(IF(AC13="","",ROUND(AC13/$AC$11*100,2)),"") -> 100 | AE13: =IFERROR(IF(AD13="","",ROUND(AD13*$AE$11,2)),"") -> 50 | AF13: 50 | AG13: =IFERROR(IF(AF13="","",ROUND(AF13/$AF$11*100,2)),"") -> 100 | AH13: =IFERROR(IF(AG13="","",ROUND(AG13*$AH$11,2)),"") -> 25 | AI13: =IFERROR(R13+AE13+AH13,"") -> 94.5 | AJ13: =IFERROR(VLOOKUP(AI13,'Helper(IMPORTANT!)'!$CQ$1:$CR$41,2,TRUE),"") -> 96
A14: 2 | B14: ='INPUT DATA'!L12 -> AQUINO, KYLE N. | F14: 7 | G14: 7 | H14: 6 | I14: 5 | J14: 10 | P14: =IF(COUNT($F14:$O14)=0,"",SUM($F14:$O14)) -> 35 | Q14: =IFERROR(IF(P14="","",ROUND(P14/$P$11*100,2)),"") -> 70 | R14: =IFERROR(IF(Q14="","",ROUND(Q14*$R$11,2)),"") -> 17.5 | S14: 20 | AC14: =IF(COUNT($S14:$AB14)=0,"",SUM($S14:$AB14)) -> 20 | AD14: =IFERROR(IF(AC14="","",ROUND(AC14/$AC$11*100,2)),"") -> 40 | AE14: =IFERROR(IF(AD14="","",ROUND(AD14*$AE$11,2)),"") -> 20 | AF14: 20 | AG14: =IFERROR(IF(AF14="","",ROUND(AF14/$AF$11*100,2)),"") -> 40 | AH14: =IFERROR(IF(AG14="","",ROUND(AG14*$AH$11,2)),"") -> 10 | AI14: =IFERROR(R14+AE14+AH14,"") -> 47.5 | AJ14: =IFERROR(VLOOKUP(AI14,'Helper(IMPORTANT!)'!$CQ$1:$CR$41,2,TRUE),"") -> 71
A15: 3 | B15: ='INPUT DATA'!L13 -> BAUTISTA, MARK ANTHONY U. | F15: 10 | G15: 9 | H15: 10 | I15: 6 | J15: 6 | P15: =IF(COUNT($F15:$O15)=0,"",SUM($F15:$O15)) -> 41 | Q15: =IFERROR(IF(P15="","",ROUND(P15/$P$11*100,2)),"") -> 82 | R15: =IFERROR(IF(Q15="","",ROUND(Q15*$R$11,2)),"") -> 20.5 | S15: 34 | AC15: =IF(COUNT($S15:$AB15)=0,"",SUM($S15:$AB15)) -> 34 | AD15: =IFERROR(IF(AC15="","",ROUND(AC15/$AC$11*100,2)),"") -> 68 | AE15: =IFERROR(IF(AD15="","",ROUND(AD15*$AE$11,2)),"") -> 34 | AF15: 34 | AG15: =IFERROR(IF(AF15="","",ROUND(AF15/$AF$11*100,2)),"") -> 68 | AH15: =IFERROR(IF(AG15="","",ROUND(AG15*$AH$11,2)),"") -> 17 | AI15: =IFERROR(R15+AE15+AH15,"") -> 71.5 | AJ15: =IFERROR(VLOOKUP(AI15,'Helper(IMPORTANT!)'!$CQ$1:$CR$41,2,TRUE),"") -> 82
A16: 4 | B16: ='INPUT DATA'!L14 -> CABRERA, RAFAEL C. | F16: 9 | G16: 5 | H16: 10 | I16: 7 | J16: 7 | P16: =IF(COUNT($F16:$O16)=0,"",SUM($F16:$O16)) -> 38 | Q16: =IFERROR(IF(P16="","",ROUND(P16/$P$11*100,2)),"") -> 76 | R16: =IFERROR(IF(Q16="","",ROUND(Q16*$R$11,2)),"") -> 19 | S16: 48 | AC16: =IF(COUNT($S16:$AB16)=0,"",SUM($S16:$AB16)) -> 48 | AD16: =IFERROR(IF(AC16="","",ROUND(AC16/$AC$11*100,2)),"") -> 96 | AE16: =IFERROR(IF(AD16="","",ROUND(AD16*$AE$11,2)),"") -> 48 | AF16: 48 | AG16: =IFERROR(IF(AF16="","",ROUND(AF16/$AF$11*100,2)),"") -> 96 | AH16: =IFERROR(IF(AG16="","",ROUND(AG16*$AH$11,2)),"") -> 24 | AI16: =IFERROR(R16+AE16+AH16,"") -> 91 | AJ16: =IFERROR(VLOOKUP(AI16,'Helper(IMPORTANT!)'!$CQ$1:$CR$41,2,TRUE),"") -> 94
A17: 5 | B17: ='INPUT DATA'!L15 -> CASTILLO, JEROME J. | F17: 10 | G17: 6 | H17: 6 | I17: 7 | J17: 7 | P17: =IF(COUNT($F17:$O17)=0,"",SUM($F17:$O17)) -> 36 | Q17: =IFERROR(IF(P17="","",ROUND(P17/$P$11*100,2)),"") -> 72 | R17: =IFERROR(IF(Q17="","",ROUND(Q17*$R$11,2)),"") -> 18 | S17: 48 | AC17: =IF(COUNT($S17:$AB17)=0,"",SUM($S17:$AB17)) -> 48 | AD17: =IFERROR(IF(AC17="","",ROUND(AC17/$AC$11*100,2)),"") -> 96 | AE17: =IFERROR(IF(AD17="","",ROUND(AD17*$AE$11,2)),"") -> 48 | AF17: 48 | AG17: =IFERROR(IF(AF17="","",ROUND(AF17/$AF$11*100,2)),"") -> 96 | AH17: =IFERROR(IF(AG17="","",ROUND(AG17*$AH$11,2)),"") -> 24 | AI17: =IFERROR(R17+AE17+AH17,"") -> 90 | AJ17: =IFERROR(VLOOKUP(AI17,'Helper(IMPORTANT!)'!$CQ$1:$CR$41,2,TRUE),"") -> 93
A18: 6 | B18: ='INPUT DATA'!L16 -> FLORES, RAFAEL Z. | F18: 10 | G18: 7 | H18: 7 | I18: 8 | J18: 8 | P18: =IF(COUNT($F18:$O18)=0,"",SUM($F18:$O18)) -> 40 | Q18: =IFERROR(IF(P18="","",ROUND(P18/$P$11*100,2)),"") -> 80 | R18: =IFERROR(IF(Q18="","",ROUND(Q18*$R$11,2)),"") -> 20 | S18: 50 | AC18: =IF(COUNT($S18:$AB18)=0,"",SUM($S18:$AB18)) -> 50 | AD18: =IFERROR(IF(AC18="","",ROUND(AC18/$AC$11*100,2)),"") -> 100 | AE18: =IFERROR(IF(AD18="","",ROUND(AD18*$AE$11,2)),"") -> 50 | AF18: 50 | AG18: =IFERROR(IF(AF18="","",ROUND(AF18/$AF$11*100,2)),"") -> 100 | AH18: =IFERROR(IF(AG18="","",ROUND(AG18*$AH$11,2)),"") -> 25 | AI18: =IFERROR(R18+AE18+AH18,"") -> 95 | AJ18: =IFERROR(VLOOKUP(AI18,'Helper(IMPORTANT!)'!$CQ$1:$CR$41,2,TRUE),"") -> 96
A19: 7 | B19: ='INPUT DATA'!L17 -> GUTIERREZ, NATHANIEL U. | F19: 0 | G19: 8 | H19: 10 | I19: 9 | J19: 10 | P19: =IF(COUNT($F19:$O19)=0,"",SUM($F19:$O19)) -> 37 | Q19: =IFERROR(IF(P19="","",ROUND(P19/$P$11*100,2)),"") -> 74 | R19: =IFERROR(IF(Q19="","",ROUND(Q19*$R$11,2)),"") -> 18.5 | S19: 20 | AC19: =IF(COUNT($S19:$AB19)=0,"",SUM($S19:$AB19)) -> 20 | AD19: =IFERROR(IF(AC19="","",ROUND(AC19/$AC$11*100,2)),"") -> 40 | AE19: =IFERROR(IF(AD19="","",ROUND(AD19*$AE$11,2)),"") -> 20 | AF19: 20 | AG19: =IFERROR(IF(AF19="","",ROUND(AF19/$AF$11*100,2)),"") -> 40 | AH19: =IFERROR(IF(AG19="","",ROUND(AG19*$AH$11,2)),"") -> 10 | AI19: =IFERROR(R19+AE19+AH19,"") -> 48.5 | AJ19: =IFERROR(VLOOKUP(AI19,'Helper(IMPORTANT!)'!$CQ$1:$CR$41,2,TRUE),"") -> 72
A20: 8 | B20: ='INPUT DATA'!L18 -> LACSON, KYLE E. | F20: 10 | G20: 8 | H20: 0 | I20: 5 | J20: 10 | P20: =IF(COUNT($F20:$O20)=0,"",SUM($F20:$O20)) -> 33 | Q20: =IFERROR(IF(P20="","",ROUND(P20/$P$11*100,2)),"") -> 66 | R20: =IFERROR(IF(Q20="","",ROUND(Q20*$R$11,2)),"") -> 16.5 | S20: 34 | AC20: =IF(COUNT($S20:$AB20)=0,"",SUM($S20:$AB20)) -> 34 | AD20: =IFERROR(IF(AC20="","",ROUND(AC20/$AC$11*100,2)),"") -> 68 | AE20: =IFERROR(IF(AD20="","",ROUND(AD20*$AE$11,2)),"") -> 34 | AF20: 34 | AG20: =IFERROR(IF(AF20="","",ROUND(AF20/$AF$11*100,2)),"") -> 68 | AH20: =IFERROR(IF(AG20="","",ROUND(AG20*$AH$11,2)),"") -> 17 | AI20: =IFERROR(R20+AE20+AH20,"") -> 67.5 | AJ20: =IFERROR(VLOOKUP(AI20,'Helper(IMPORTANT!)'!$CQ$1:$CR$41,2,TRUE),"") -> 79
A21: 9 | B21: ='INPUT DATA'!L19 -> MACARAEG, KENNETH H. | F21: 10 | G21: 6 | H21: 6 | I21: 7 | J21: 7 | P21: =IF(COUNT($F21:$O21)=0,"",SUM($F21:$O21)) -> 36 | Q21: =IFERROR(IF(P21="","",ROUND(P21/$P$11*100,2)),"") -> 72 | R21: =IFERROR(IF(Q21="","",ROUND(Q21*$R$11,2)),"") -> 18 | S21: 48 | AC21: =IF(COUNT($S21:$AB21)=0,"",SUM($S21:$AB21)) -> 48 | AD21: =IFERROR(IF(AC21="","",ROUND(AC21/$AC$11*100,2)),"") -> 96 | AE21: =IFERROR(IF(AD21="","",ROUND(AD21*$AE$11,2)),"") -> 48 | AF21: 48 | AG21: =IFERROR(IF(AF21="","",ROUND(AF21/$AF$11*100,2)),"") -> 96 | AH21: =IFERROR(IF(AG21="","",ROUND(AG21*$AH$11,2)),"") -> 24 | AI21: =IFERROR(R21+AE21+AH21,"") -> 90 | AJ21: =IFERROR(VLOOKUP(AI21,'Helper(IMPORTANT!)'!$CQ$1:$CR$41,2,TRUE),"") -> 93
A22: 10 | B22: ='INPUT DATA'!L20 -> NAVARRO, CHRISTIAN O. | F22: 10 | G22: 7 | H22: 7 | I22: 8 | J22: 8 | P22: =IF(COUNT($F22:$O22)=0,"",SUM($F22:$O22)) -> 40 | Q22: =IFERROR(IF(P22="","",ROUND(P22/$P$11*100,2)),"") -> 80 | R22: =IFERROR(IF(Q22="","",ROUND(Q22*$R$11,2)),"") -> 20 | S22: 48 | AC22: =IF(COUNT($S22:$AB22)=0,"",SUM($S22:$AB22)) -> 48 | AD22: =IFERROR(IF(AC22="","",ROUND(AC22/$AC$11*100,2)),"") -> 96 | AE22: =IFERROR(IF(AD22="","",ROUND(AD22*$AE$11,2)),"") -> 48 | AF22: 48 | AG22: =IFERROR(IF(AF22="","",ROUND(AF22/$AF$11*100,2)),"") -> 96 | AH22: =IFERROR(IF(AG22="","",ROUND(AG22*$AH$11,2)),"") -> 24 | AI22: =IFERROR(R22+AE22+AH22,"") -> 92 | AJ22: =IFERROR(VLOOKUP(AI22,'Helper(IMPORTANT!)'!$CQ$1:$CR$41,2,TRUE),"") -> 95
A23: 11 | B23: ='INPUT DATA'!L21 -> PANGANIBAN, VINCENT H. | F23: 0 | G23: 8 | H23: 10 | I23: 9 | J23: 10 | P23: =IF(COUNT($F23:$O23)=0,"",SUM($F23:$O23)) -> 37 | Q23: =IFERROR(IF(P23="","",ROUND(P23/$P$11*100,2)),"") -> 74 | R23: =IFERROR(IF(Q23="","",ROUND(Q23*$R$11,2)),"") -> 18.5 | S23: 29 | AC23: =IF(COUNT($S23:$AB23)=0,"",SUM($S23:$AB23)) -> 29 | AD23: =IFERROR(IF(AC23="","",ROUND(AC23/$AC$11*100,2)),"") -> 58 | AE23: =IFERROR(IF(AD23="","",ROUND(AD23*$AE$11,2)),"") -> 29 | AF23: 29 | AG23: =IFERROR(IF(AF23="","",ROUND(AF23/$AF$11*100,2)),"") -> 58 | AH23: =IFERROR(IF(AG23="","",ROUND(AG23*$AH$11,2)),"") -> 14.5 | AI23: =IFERROR(R23+AE23+AH23,"") -> 62 | AJ23: =IFERROR(VLOOKUP(AI23,'Helper(IMPORTANT!)'!$CQ$1:$CR$41,2,TRUE),"") -> 76
A24: 12 | B24: ='INPUT DATA'!L22 -> REYES, CEDRIC I. | F24: 10 | G24: 8 | H24: 0 | I24: 5 | J24: 10 | P24: =IF(COUNT($F24:$O24)=0,"",SUM($F24:$O24)) -> 33 | Q24: =IFERROR(IF(P24="","",ROUND(P24/$P$11*100,2)),"") -> 66 | R24: =IFERROR(IF(Q24="","",ROUND(Q24*$R$11,2)),"") -> 16.5 | S24: 20 | AC24: =IF(COUNT($S24:$AB24)=0,"",SUM($S24:$AB24)) -> 20 | AD24: =IFERROR(IF(AC24="","",ROUND(AC24/$AC$11*100,2)),"") -> 40 | AE24: =IFERROR(IF(AD24="","",ROUND(AD24*$AE$11,2)),"") -> 20 | AF24: 20 | AG24: =IFERROR(IF(AF24="","",ROUND(AF24/$AF$11*100,2)),"") -> 40 | AH24: =IFERROR(IF(AG24="","",ROUND(AG24*$AH$11,2)),"") -> 10 | AI24: =IFERROR(R24+AE24+AH24,"") -> 46.5 | AJ24: =IFERROR(VLOOKUP(AI24,'Helper(IMPORTANT!)'!$CQ$1:$CR$41,2,TRUE),"") -> 71
... A30: 18 | B30: ='INPUT DATA'!L28 -> VILLANUEVA, FRANCIS M. | F30: 0 | G30: 8 | H30: 10 | I30: 9 | J30: 10 | P30: =IF(COUNT($F30:$O30)=0,"",SUM($F30:$O30)) -> 37 | Q30: =IFERROR(IF(P30="","",ROUND(P30/$P$11*100,2)),"") -> 74 | R30: =IFERROR(IF(Q30="","",ROUND(Q30*$R$11,2)),"") -> 18.5 | S30: 49 | AC30: =IF(COUNT($S30:$AB30)=0,"",SUM($S30:$AB30)) -> 49 | AD30: =IFERROR(IF(AC30="","",ROUND(AC30/$AC$11*100,2)),"") -> 98 | AE30: =IFERROR(IF(AD30="","",ROUND(AD30*$AE$11,2)),"") -> 49 | AF30: 49 | AG30: =IFERROR(IF(AF30="","",ROUND(AF30/$AF$11*100,2)),"") -> 98 | AH30: =IFERROR(IF(AG30="","",ROUND(AG30*$AH$11,2)),"") -> 24.5 | AI30: =IFERROR(R30+AE30+AH30,"") -> 92 | AJ30: =IFERROR(VLOOKUP(AI30,'Helper(IMPORTANT!)'!$CQ$1:$CR$41,2,TRUE),"") -> 95
A31: 19 | B31: ='INPUT DATA'!L29 -> 0 | P31: =IF(COUNT($F31:$O31)=0,"",SUM($F31:$O31)) | Q31: =IFERROR(IF(P31="","",ROUND(P31/$P$11*100,2)),"") | R31: =IFERROR(IF(Q31="","",ROUND(Q31*$R$11,2)),"") | AC31: =IF(COUNT($S31:$AB31)=0,"",SUM($S31:$AB31)) | AD31: =IFERROR(IF(AC31="","",ROUND(AC31/$AC$11*100,2)),"") | AE31: =IFERROR(IF(AD31="","",ROUND(AD31*$AE$11,2)),"") | AG31: =IFERROR(IF(AF31="","",ROUND(AF31/$AF$11*100,2)),"") | AH31: =IFERROR(IF(AG31="","",ROUND(AG31*$AH$11,2)),"") | AI31: =IFERROR(R31+AE31+AH31,"") | AJ31: =IFERROR(VLOOKUP(AI31,'Helper(IMPORTANT!)'!$CQ$1:$CR$41,2,TRUE),"")
A32: 20 | B32: ='INPUT DATA'!L30 -> 0 | P32: =IF(COUNT($F32:$O32)=0,"",SUM($F32:$O32)) | Q32: =IFERROR(IF(P32="","",ROUND(P32/$P$11*100,2)),"") | R32: =IFERROR(IF(Q32="","",ROUND(Q32*$R$11,2)),"") | AC32: =IF(COUNT($S32:$AB32)=0,"",SUM($S32:$AB32)) | AD32: =IFERROR(IF(AC32="","",ROUND(AC32/$AC$11*100,2)),"") | AE32: =IFERROR(IF(AD32="","",ROUND(AD32*$AE$11,2)),"") | AG32: =IFERROR(IF(AF32="","",ROUND(AF32/$AF$11*100,2)),"") | AH32: =IFERROR(IF(AG32="","",ROUND(AG32*$AH$11,2)),"") | AI32: =IFERROR(R32+AE32+AH32,"") | AJ32: =IFERROR(VLOOKUP(AI32,'Helper(IMPORTANT!)'!$CQ$1:$CR$41,2,TRUE),"")
A33: 21 | B33: ='INPUT DATA'!L31 -> 0 | P33: =IF(COUNT($F33:$O33)=0,"",SUM($F33:$O33)) | Q33: =IFERROR(IF(P33="","",ROUND(P33/$P$11*100,2)),"") | R33: =IFERROR(IF(Q33="","",ROUND(Q33*$R$11,2)),"") | AC33: =IF(COUNT($S33:$AB33)=0,"",SUM($S33:$AB33)) | AD33: =IFERROR(IF(AC33="","",ROUND(AC33/$AC$11*100,2)),"") | AE33: =IFERROR(IF(AD33="","",ROUND(AD33*$AE$11,2)),"") | AG33: =IFERROR(IF(AF33="","",ROUND(AF33/$AF$11*100,2)),"") | AH33: =IFERROR(IF(AG33="","",ROUND(AG33*$AH$11,2)),"") | AI33: =IFERROR(R33+AE33+AH33,"") | AJ33: =IFERROR(VLOOKUP(AI33,'Helper(IMPORTANT!)'!$CQ$1:$CR$41,2,TRUE),"")
A34: 22 | B34: ='INPUT DATA'!L32 -> 0 | P34: =IF(COUNT($F34:$O34)=0,"",SUM($F34:$O34)) | Q34: =IFERROR(IF(P34="","",ROUND(P34/$P$11*100,2)),"") | R34: =IFERROR(IF(Q34="","",ROUND(Q34*$R$11,2)),"") | AC34: =IF(COUNT($S34:$AB34)=0,"",SUM($S34:$AB34)) | AD34: =IFERROR(IF(AC34="","",ROUND(AC34/$AC$11*100,2)),"") | AE34: =IFERROR(IF(AD34="","",ROUND(AD34*$AE$11,2)),"") | AG34: =IFERROR(IF(AF34="","",ROUND(AF34/$AF$11*100,2)),"") | AH34: =IFERROR(IF(AG34="","",ROUND(AG34*$AH$11,2)),"") | AI34: =IFERROR(R34+AE34+AH34,"") | AJ34: =IFERROR(VLOOKUP(AI34,'Helper(IMPORTANT!)'!$CQ$1:$CR$41,2,TRUE),"")
A35: 23 | B35: ='INPUT DATA'!L33 -> 0 | P35: =IF(COUNT($F35:$O35)=0,"",SUM($F35:$O35)) | Q35: =IFERROR(IF(P35="","",ROUND(P35/$P$11*100,2)),"") | R35: =IFERROR(IF(Q35="","",ROUND(Q35*$R$11,2)),"") | AC35: =IF(COUNT($S35:$AB35)=0,"",SUM($S35:$AB35)) | AD35: =IFERROR(IF(AC35="","",ROUND(AC35/$AC$11*100,2)),"") | AE35: =IFERROR(IF(AD35="","",ROUND(AD35*$AE$11,2)),"") | AG35: =IFERROR(IF(AF35="","",ROUND(AF35/$AF$11*100,2)),"") | AH35: =IFERROR(IF(AG35="","",ROUND(AG35*$AH$11,2)),"") | AI35: =IFERROR(R35+AE35+AH35,"") | AJ35: =IFERROR(VLOOKUP(AI35,'Helper(IMPORTANT!)'!$CQ$1:$CR$41,2,TRUE),"")
A36: 24 | B36: ='INPUT DATA'!L34 -> 0 | P36: =IF(COUNT($F36:$O36)=0,"",SUM($F36:$O36)) | Q36: =IFERROR(IF(P36="","",ROUND(P36/$P$11*100,2)),"") | R36: =IFERROR(IF(Q36="","",ROUND(Q36*$R$11,2)),"") | AC36: =IF(COUNT($S36:$AB36)=0,"",SUM($S36:$AB36)) | AD36: =IFERROR(IF(AC36="","",ROUND(AC36/$AC$11*100,2)),"") | AE36: =IFERROR(IF(AD36="","",ROUND(AD36*$AE$11,2)),"") | AG36: =IFERROR(IF(AF36="","",ROUND(AF36/$AF$11*100,2)),"") | AH36: =IFERROR(IF(AG36="","",ROUND(AG36*$AH$11,2)),"") | AI36: =IFERROR(R36+AE36+AH36,"") | AJ36: =IFERROR(VLOOKUP(AI36,'Helper(IMPORTANT!)'!$CQ$1:$CR$41,2,TRUE),"")
A37: 25 | B37: ='INPUT DATA'!L35 -> 0 | P37: =IF(COUNT($F37:$O37)=0,"",SUM($F37:$O37)) | Q37: =IFERROR(IF(P37="","",ROUND(P37/$P$11*100,2)),"") | R37: =IFERROR(IF(Q37="","",ROUND(Q37*$R$11,2)),"") | AC37: =IF(COUNT($S37:$AB37)=0,"",SUM($S37:$AB37)) | AD37: =IFERROR(IF(AC37="","",ROUND(AC37/$AC$11*100,2)),"") | AE37: =IFERROR(IF(AD37="","",ROUND(AD37*$AE$11,2)),"") | AG37: =IFERROR(IF(AF37="","",ROUND(AF37/$AF$11*100,2)),"") | AH37: =IFERROR(IF(AG37="","",ROUND(AG37*$AH$11,2)),"") | AI37: =IFERROR(R37+AE37+AH37,"") | AJ37: =IFERROR(VLOOKUP(AI37,'Helper(IMPORTANT!)'!$CQ$1:$CR$41,2,TRUE),"")
A38: 26 | B38: ='INPUT DATA'!L36 -> 0 | P38: =IF(COUNT($F38:$O38)=0,"",SUM($F38:$O38)) | Q38: =IFERROR(IF(P38="","",ROUND(P38/$P$11*100,2)),"") | R38: =IFERROR(IF(Q38="","",ROUND(Q38*$R$11,2)),"") | AC38: =IF(COUNT($S38:$AB38)=0,"",SUM($S38:$AB38)) | AD38: =IFERROR(IF(AC38="","",ROUND(AC38/$AC$11*100,2)),"") | AE38: =IFERROR(IF(AD38="","",ROUND(AD38*$AE$11,2)),"") | AG38: =IFERROR(IF(AF38="","",ROUND(AF38/$AF$11*100,2)),"") | AH38: =IFERROR(IF(AG38="","",ROUND(AG38*$AH$11,2)),"") | AI38: =IFERROR(R38+AE38+AH38,"") | AJ38: =IFERROR(VLOOKUP(AI38,'Helper(IMPORTANT!)'!$CQ$1:$CR$41,2,TRUE),"")
A39: 27 | B39: ='INPUT DATA'!L37 -> 0 | P39: =IF(COUNT($F39:$O39)=0,"",SUM($F39:$O39)) | Q39: =IFERROR(IF(P39="","",ROUND(P39/$P$11*100,2)),"") | R39: =IFERROR(IF(Q39="","",ROUND(Q39*$R$11,2)),"") | AC39: =IF(COUNT($S39:$AB39)=0,"",SUM($S39:$AB39)) | AD39: =IFERROR(IF(AC39="","",ROUND(AC39/$AC$11*100,2)),"") | AE39: =IFERROR(IF(AD39="","",ROUND(AD39*$AE$11,2)),"") | AG39: =IFERROR(IF(AF39="","",ROUND(AF39/$AF$11*100,2)),"") | AH39: =IFERROR(IF(AG39="","",ROUND(AG39*$AH$11,2)),"") | AI39: =IFERROR(R39+AE39+AH39,"") | AJ39: =IFERROR(VLOOKUP(AI39,'Helper(IMPORTANT!)'!$CQ$1:$CR$41,2,TRUE),"")
A40: 28 | B40: ='INPUT DATA'!L38 -> 0 | P40: =IF(COUNT($F40:$O40)=0,"",SUM($F40:$O40)) | Q40: =IFERROR(IF(P40="","",ROUND(P40/$P$11*100,2)),"") | R40: =IFERROR(IF(Q40="","",ROUND(Q40*$R$11,2)),"") | AC40: =IF(COUNT($S40:$AB40)=0,"",SUM($S40:$AB40)) | AD40: =IFERROR(IF(AC40="","",ROUND(AC40/$AC$11*100,2)),"") | AE40: =IFERROR(IF(AD40="","",ROUND(AD40*$AE$11,2)),"") | AG40: =IFERROR(IF(AF40="","",ROUND(AF40/$AF$11*100,2)),"") | AH40: =IFERROR(IF(AG40="","",ROUND(AG40*$AH$11,2)),"") | AI40: =IFERROR(R40+AE40+AH40,"") | AJ40: =IFERROR(VLOOKUP(AI40,'Helper(IMPORTANT!)'!$CQ$1:$CR$41,2,TRUE),"")
A41: 29 | B41: ='INPUT DATA'!L39 -> 0 | P41: =IF(COUNT($F41:$O41)=0,"",SUM($F41:$O41)) | Q41: =IFERROR(IF(P41="","",ROUND(P41/$P$11*100,2)),"") | R41: =IFERROR(IF(Q41="","",ROUND(Q41*$R$11,2)),"") | AC41: =IF(COUNT($S41:$AB41)=0,"",SUM($S41:$AB41)) | AD41: =IFERROR(IF(AC41="","",ROUND(AC41/$AC$11*100,2)),"") | AE41: =IFERROR(IF(AD41="","",ROUND(AD41*$AE$11,2)),"") | AG41: =IFERROR(IF(AF41="","",ROUND(AF41/$AF$11*100,2)),"") | AH41: =IFERROR(IF(AG41="","",ROUND(AG41*$AH$11,2)),"") | AI41: =IFERROR(R41+AE41+AH41,"") | AJ41: =IFERROR(VLOOKUP(AI41,'Helper(IMPORTANT!)'!$CQ$1:$CR$41,2,TRUE),"")
A42: 30 | B42: ='INPUT DATA'!L40 -> 0 | P42: =IF(COUNT($F42:$O42)=0,"",SUM($F42:$O42)) | Q42: =IFERROR(IF(P42="","",ROUND(P42/$P$11*100,2)),"") | R42: =IFERROR(IF(Q42="","",ROUND(Q42*$R$11,2)),"") | AC42: =IF(COUNT($S42:$AB42)=0,"",SUM($S42:$AB42)) | AD42: =IFERROR(IF(AC42="","",ROUND(AC42/$AC$11*100,2)),"") | AE42: =IFERROR(IF(AD42="","",ROUND(AD42*$AE$11,2)),"") | AG42: =IFERROR(IF(AF42="","",ROUND(AF42/$AF$11*100,2)),"") | AH42: =IFERROR(IF(AG42="","",ROUND(AG42*$AH$11,2)),"") | AI42: =IFERROR(R42+AE42+AH42,"") | AJ42: =IFERROR(VLOOKUP(AI42,'Helper(IMPORTANT!)'!$CQ$1:$CR$41,2,TRUE),"")
... A62: 50 | B62: ='INPUT DATA'!L60 -> 0 | P62: =IF(COUNT($F62:$O62)=0,"",SUM($F62:$O62)) | Q62: =IFERROR(IF(P62="","",ROUND(P62/$P$11*100,2)),"") | R62: =IFERROR(IF(Q62="","",ROUND(Q62*$R$11,2)),"") | AC62: =IF(COUNT($S62:$AB62)=0,"",SUM($S62:$AB62)) | AD62: =IFERROR(IF(AC62="","",ROUND(AC62/$AC$11*100,2)),"") | AE62: =IFERROR(IF(AD62="","",ROUND(AD62*$AE$11,2)),"") | AG62: =IFERROR(IF(AF62="","",ROUND(AF62/$AF$11*100,2)),"") | AH62: =IFERROR(IF(AG62="","",ROUND(AG62*$AH$11,2)),"") | AI62: =IFERROR(R62+AE62+AH62,"") | AJ62: =IFERROR(VLOOKUP(AI62,'Helper(IMPORTANT!)'!$CQ$1:$CR$41,2,TRUE),"")
A63: FEMALE
A64: 1 | B64: ='INPUT DATA'!O11 -> BASCO, FAITH U. | F64: 9 | G64: 6 | H64: 5 | I64: 9 | J64: 10 | P64: =IF(COUNT($F64:$O64)=0,"",SUM($F64:$O64)) -> 39 | Q64: =IFERROR(IF(P64="","",ROUND(P64/$P$11*100,2)),"") -> 78 | R64: =IFERROR(IF(Q64="","",ROUND(Q64*$R$11,2)),"") -> 19.5 | S64: 50 | AC64: =IF(COUNT($S64:$AB64)=0,"",SUM($S64:$AB64)) -> 50 | AD64: =IFERROR(IF(AC64="","",ROUND(AC64/$AC$11*100,2)),"") -> 100 | AE64: =IFERROR(IF(AD64="","",ROUND(AD64*$AE$11,2)),"") -> 50 | AF64: 50 | AG64: =IFERROR(IF(AF64="","",ROUND(AF64/$AF$11*100,2)),"") -> 100 | AH64: =IFERROR(IF(AG64="","",ROUND(AG64*$AH$11,2)),"") -> 25 | AI64: =IFERROR(R64+AE64+AH64,"") -> 94.5 | AJ64: =IFERROR(VLOOKUP(AI64,'Helper(IMPORTANT!)'!$CQ$1:$CR$41,2,TRUE),"") -> 96
A65: 2 | B65: ='INPUT DATA'!O12 -> BAUTISTA, MAE J. | F65: 7 | G65: 7 | H65: 6 | I65: 5 | J65: 10 | P65: =IF(COUNT($F65:$O65)=0,"",SUM($F65:$O65)) -> 35 | Q65: =IFERROR(IF(P65="","",ROUND(P65/$P$11*100,2)),"") -> 70 | R65: =IFERROR(IF(Q65="","",ROUND(Q65*$R$11,2)),"") -> 17.5 | S65: 20 | AC65: =IF(COUNT($S65:$AB65)=0,"",SUM($S65:$AB65)) -> 20 | AD65: =IFERROR(IF(AC65="","",ROUND(AC65/$AC$11*100,2)),"") -> 40 | AE65: =IFERROR(IF(AD65="","",ROUND(AD65*$AE$11,2)),"") -> 20 | AF65: 20 | AG65: =IFERROR(IF(AF65="","",ROUND(AF65/$AF$11*100,2)),"") -> 40 | AH65: =IFERROR(IF(AG65="","",ROUND(AG65*$AH$11,2)),"") -> 10 | AI65: =IFERROR(R65+AE65+AH65,"") -> 47.5 | AJ65: =IFERROR(VLOOKUP(AI65,'Helper(IMPORTANT!)'!$CQ$1:$CR$41,2,TRUE),"") -> 71
A66: 3 | B66: ='INPUT DATA'!O13 -> CABRERA, RHEA Q. | F66: 10 | G66: 9 | H66: 10 | I66: 6 | J66: 6 | P66: =IF(COUNT($F66:$O66)=0,"",SUM($F66:$O66)) -> 41 | Q66: =IFERROR(IF(P66="","",ROUND(P66/$P$11*100,2)),"") -> 82 | R66: =IFERROR(IF(Q66="","",ROUND(Q66*$R$11,2)),"") -> 20.5 | S66: 34 | AC66: =IF(COUNT($S66:$AB66)=0,"",SUM($S66:$AB66)) -> 34 | AD66: =IFERROR(IF(AC66="","",ROUND(AC66/$AC$11*100,2)),"") -> 68 | AE66: =IFERROR(IF(AD66="","",ROUND(AD66*$AE$11,2)),"") -> 34 | AF66: 34 | AG66: =IFERROR(IF(AF66="","",ROUND(AF66/$AF$11*100,2)),"") -> 68 | AH66: =IFERROR(IF(AG66="","",ROUND(AG66*$AH$11,2)),"") -> 17 | AI66: =IFERROR(R66+AE66+AH66,"") -> 71.5 | AJ66: =IFERROR(VLOOKUP(AI66,'Helper(IMPORTANT!)'!$CQ$1:$CR$41,2,TRUE),"") -> 82
...

Sheet Q3
A1: Strengthened Senior High School Class Record
A3: (Pursuant to Deped Order 8 series of 2015)
F4: REGION | G4: ='INPUT DATA'!F10 -> Region XI | L4: DIVISION | O4: ='INPUT DATA'!F11 -> Panabo City
F5: SCHOOL NAME | G5: ='INPUT DATA'!F14 -> ARMS DEMO NATIONAL HIGH SCHOOL | T5: SCHOOL ID | X5: ='INPUT DATA'!F13 -> DEMO-ARMS | AD5: SCHOOL YEAR | AG5: ='INPUT DATA'!F16 -> 2026-2027
A7: THIRD QUARTER | F7: GRADE & SECTION: | K7: ='INPUT DATA'!F24&" - "&'INPUT DATA'!F25 -> 12 - STEM-CORPUZ | Q7: TEACHER: | S7: ='INPUT DATA'!F22 -> ROBERTO MENDOZA | AC7: SUBJECT: | AE7: =IF('INPUT DATA'!F30<>"",'INPUT DATA'!F30,'INPUT DATA'!F28) -> Understanding Culture, Society and Politics
Q8: SEMESTER: | S8: - - | AC8: SUBJECT TYPE: | AE8: ='INPUT DATA'!F26 -> Core Subject (All Tracks)
A9: LEARNERS' NAMES | F9: =IF('INPUT DATA'!$F$26="","",INDEX('Helper(IMPORTANT!)'!$CI$2:$CI$6,MATCH(AE8,'Helper(IMPORTANT!)'!$CH$2:$CH$6,0))) -> WRITTEN WORK (25%) | S9: =IF('INPUT DATA'!$F$26="","",INDEX('Helper(IMPORTANT!)'!$CJ$2:$CJ$6,MATCH(AE8,'Helper(IMPORTANT!)'!$CH$2:$CH$6,0))) -> PERFORMANCE TASK (50%) | AF9: =IF('INPUT DATA'!$F$26="","",INDEX('Helper(IMPORTANT!)'!$CK$2:$CK$6,MATCH(AE8,'Helper(IMPORTANT!)'!$CH$2:$CH$6,0))) -> QUARTERLY ASSESSMENT (25%) | AI9: Initial Grade | AJ9: Quarterly Grade
F10: 1 | G10: 2 | H10: 3 | I10: 4 | J10: 5 | K10: 6 | L10: 7 | M10: 8 | N10: 9 | O10: 10 | P10: Total | Q10: PS | R10: WS | S10: 1 | T10: 2 | U10: 3 | V10: 4 | W10: 5 | X10: 6 | Y10: 7 | Z10: 8 | AA10: 9 | AB10: 10 | AC10: Total | AD10: PS | AE10: WS | AF10: 1 | AG10: PS | AH10: WS
A11: HIGHEST POSSIBLE SCORE | P11: =IF(COUNT($F11:$O11)=0,"",SUM($F11:$O11)) | Q11: 100 | R11: =IF('INPUT DATA'!$F$26="","",INDEX('Helper(IMPORTANT!)'!$CL$2:$CL$6,MATCH(AE8,'Helper(IMPORTANT!)'!$CH$2:$CH$6,0))) -> 0.25 | AC11: =IF(COUNT($S11:$AB11)=0,"",SUM($S11:$AB11)) | AD11: 100 | AE11: =IF('INPUT DATA'!$F$26="","",INDEX('Helper(IMPORTANT!)'!$CM$2:$CM$6,MATCH(AE8,'Helper(IMPORTANT!)'!$CH$2:$CH$6,0))) -> 0.5 | AG11: 100 | AH11: =IF('INPUT DATA'!$F$26="","",INDEX('Helper(IMPORTANT!)'!$CN$2:$CN$6,MATCH(AE8,'Helper(IMPORTANT!)'!$CH$2:$CH$6,0))) -> 0.25
A12: MALE
A13: 1 | B13: ='INPUT DATA'!L11 -> ALCANTARA, ALDRIN R. | P13: =IF(COUNT($F13:$O13)=0,"",SUM($F13:$O13)) | Q13: =IFERROR(IF(P13="","",ROUND(P13/$P$11*100,2)),"") | R13: =IFERROR(IF(Q13="","",ROUND(Q13*$R$11,2)),"") | AC13: =IF(COUNT($S13:$AB13)=0,"",SUM($S13:$AB13)) | AD13: =IFERROR(IF(AC13="","",ROUND(AC13/$AC$11*100,2)),"") | AE13: =IFERROR(IF(AD13="","",ROUND(AD13*$AE$11,2)),"") | AG13: =IFERROR(IF(AF13="","",ROUND(AF13/$AF$11*100,2)),"") | AH13: =IFERROR(IF(AG13="","",ROUND(AG13*$AH$11,2)),"") | AI13: =IFERROR(R13+AE13+AH13,"") | AJ13: =IFERROR(VLOOKUP(AI13,'Helper(IMPORTANT!)'!$CQ$1:$CR$41,2,TRUE),"")
A14: 2 | B14: ='INPUT DATA'!L12 -> AQUINO, KYLE N. | P14: =IF(COUNT($F14:$O14)=0,"",SUM($F14:$O14)) | Q14: =IFERROR(IF(P14="","",ROUND(P14/$P$11*100,2)),"") | R14: =IFERROR(IF(Q14="","",ROUND(Q14*$R$11,2)),"") | AC14: =IF(COUNT($S14:$AB14)=0,"",SUM($S14:$AB14)) | AD14: =IFERROR(IF(AC14="","",ROUND(AC14/$AC$11*100,2)),"") | AE14: =IFERROR(IF(AD14="","",ROUND(AD14*$AE$11,2)),"") | AG14: =IFERROR(IF(AF14="","",ROUND(AF14/$AF$11*100,2)),"") | AH14: =IFERROR(IF(AG14="","",ROUND(AG14*$AH$11,2)),"") | AI14: =IFERROR(R14+AE14+AH14,"") | AJ14: =IFERROR(VLOOKUP(AI14,'Helper(IMPORTANT!)'!$CQ$1:$CR$41,2,TRUE),"")
A15: 3 | B15: ='INPUT DATA'!L13 -> BAUTISTA, MARK ANTHONY U. | P15: =IF(COUNT($F15:$O15)=0,"",SUM($F15:$O15)) | Q15: =IFERROR(IF(P15="","",ROUND(P15/$P$11*100,2)),"") | R15: =IFERROR(IF(Q15="","",ROUND(Q15*$R$11,2)),"") | AC15: =IF(COUNT($S15:$AB15)=0,"",SUM($S15:$AB15)) | AD15: =IFERROR(IF(AC15="","",ROUND(AC15/$AC$11*100,2)),"") | AE15: =IFERROR(IF(AD15="","",ROUND(AD15*$AE$11,2)),"") | AG15: =IFERROR(IF(AF15="","",ROUND(AF15/$AF$11*100,2)),"") | AH15: =IFERROR(IF(AG15="","",ROUND(AG15*$AH$11,2)),"") | AI15: =IFERROR(R15+AE15+AH15,"") | AJ15: =IFERROR(VLOOKUP(AI15,'Helper(IMPORTANT!)'!$CQ$1:$CR$41,2,TRUE),"")
A16: 4 | B16: ='INPUT DATA'!L14 -> CABRERA, RAFAEL C. | P16: =IF(COUNT($F16:$O16)=0,"",SUM($F16:$O16)) | Q16: =IFERROR(IF(P16="","",ROUND(P16/$P$11*100,2)),"") | R16: =IFERROR(IF(Q16="","",ROUND(Q16*$R$11,2)),"") | AC16: =IF(COUNT($S16:$AB16)=0,"",SUM($S16:$AB16)) | AD16: =IFERROR(IF(AC16="","",ROUND(AC16/$AC$11*100,2)),"") | AE16: =IFERROR(IF(AD16="","",ROUND(AD16*$AE$11,2)),"") | AG16: =IFERROR(IF(AF16="","",ROUND(AF16/$AF$11*100,2)),"") | AH16: =IFERROR(IF(AG16="","",ROUND(AG16*$AH$11,2)),"") | AI16: =IFERROR(R16+AE16+AH16,"") | AJ16: =IFERROR(VLOOKUP(AI16,'Helper(IMPORTANT!)'!$CQ$1:$CR$41,2,TRUE),"")
A17: 5 | B17: ='INPUT DATA'!L15 -> CASTILLO, JEROME J. | P17: =IF(COUNT($F17:$O17)=0,"",SUM($F17:$O17)) | Q17: =IFERROR(IF(P17="","",ROUND(P17/$P$11*100,2)),"") | R17: =IFERROR(IF(Q17="","",ROUND(Q17*$R$11,2)),"") | AC17: =IF(COUNT($S17:$AB17)=0,"",SUM($S17:$AB17)) | AD17: =IFERROR(IF(AC17="","",ROUND(AC17/$AC$11*100,2)),"") | AE17: =IFERROR(IF(AD17="","",ROUND(AD17*$AE$11,2)),"") | AG17: =IFERROR(IF(AF17="","",ROUND(AF17/$AF$11*100,2)),"") | AH17: =IFERROR(IF(AG17="","",ROUND(AG17*$AH$11,2)),"") | AI17: =IFERROR(R17+AE17+AH17,"") | AJ17: =IFERROR(VLOOKUP(AI17,'Helper(IMPORTANT!)'!$CQ$1:$CR$41,2,TRUE),"")
A18: 6 | B18: ='INPUT DATA'!L16 -> FLORES, RAFAEL Z. | P18: =IF(COUNT($F18:$O18)=0,"",SUM($F18:$O18)) | Q18: =IFERROR(IF(P18="","",ROUND(P18/$P$11*100,2)),"") | R18: =IFERROR(IF(Q18="","",ROUND(Q18*$R$11,2)),"") | AC18: =IF(COUNT($S18:$AB18)=0,"",SUM($S18:$AB18)) | AD18: =IFERROR(IF(AC18="","",ROUND(AC18/$AC$11*100,2)),"") | AE18: =IFERROR(IF(AD18="","",ROUND(AD18*$AE$11,2)),"") | AG18: =IFERROR(IF(AF18="","",ROUND(AF18/$AF$11*100,2)),"") | AH18: =IFERROR(IF(AG18="","",ROUND(AG18*$AH$11,2)),"") | AI18: =IFERROR(R18+AE18+AH18,"") | AJ18: =IFERROR(VLOOKUP(AI18,'Helper(IMPORTANT!)'!$CQ$1:$CR$41,2,TRUE),"")
A19: 7 | B19: ='INPUT DATA'!L17 -> GUTIERREZ, NATHANIEL U. | P19: =IF(COUNT($F19:$O19)=0,"",SUM($F19:$O19)) | Q19: =IFERROR(IF(P19="","",ROUND(P19/$P$11*100,2)),"") | R19: =IFERROR(IF(Q19="","",ROUND(Q19*$R$11,2)),"") | AC19: =IF(COUNT($S19:$AB19)=0,"",SUM($S19:$AB19)) | AD19: =IFERROR(IF(AC19="","",ROUND(AC19/$AC$11*100,2)),"") | AE19: =IFERROR(IF(AD19="","",ROUND(AD19*$AE$11,2)),"") | AG19: =IFERROR(IF(AF19="","",ROUND(AF19/$AF$11*100,2)),"") | AH19: =IFERROR(IF(AG19="","",ROUND(AG19*$AH$11,2)),"") | AI19: =IFERROR(R19+AE19+AH19,"") | AJ19: =IFERROR(VLOOKUP(AI19,'Helper(IMPORTANT!)'!$CQ$1:$CR$41,2,TRUE),"")
A20: 8 | B20: ='INPUT DATA'!L18 -> LACSON, KYLE E. | P20: =IF(COUNT($F20:$O20)=0,"",SUM($F20:$O20)) | Q20: =IFERROR(IF(P20="","",ROUND(P20/$P$11*100,2)),"") | R20: =IFERROR(IF(Q20="","",ROUND(Q20*$R$11,2)),"") | AC20: =IF(COUNT($S20:$AB20)=0,"",SUM($S20:$AB20)) | AD20: =IFERROR(IF(AC20="","",ROUND(AC20/$AC$11*100,2)),"") | AE20: =IFERROR(IF(AD20="","",ROUND(AD20*$AE$11,2)),"") | AG20: =IFERROR(IF(AF20="","",ROUND(AF20/$AF$11*100,2)),"") | AH20: =IFERROR(IF(AG20="","",ROUND(AG20*$AH$11,2)),"") | AI20: =IFERROR(R20+AE20+AH20,"") | AJ20: =IFERROR(VLOOKUP(AI20,'Helper(IMPORTANT!)'!$CQ$1:$CR$41,2,TRUE),"")
A21: 9 | B21: ='INPUT DATA'!L19 -> MACARAEG, KENNETH H. | P21: =IF(COUNT($F21:$O21)=0,"",SUM($F21:$O21)) | Q21: =IFERROR(IF(P21="","",ROUND(P21/$P$11*100,2)),"") | R21: =IFERROR(IF(Q21="","",ROUND(Q21*$R$11,2)),"") | AC21: =IF(COUNT($S21:$AB21)=0,"",SUM($S21:$AB21)) | AD21: =IFERROR(IF(AC21="","",ROUND(AC21/$AC$11*100,2)),"") | AE21: =IFERROR(IF(AD21="","",ROUND(AD21*$AE$11,2)),"") | AG21: =IFERROR(IF(AF21="","",ROUND(AF21/$AF$11*100,2)),"") | AH21: =IFERROR(IF(AG21="","",ROUND(AG21*$AH$11,2)),"") | AI21: =IFERROR(R21+AE21+AH21,"") | AJ21: =IFERROR(VLOOKUP(AI21,'Helper(IMPORTANT!)'!$CQ$1:$CR$41,2,TRUE),"")
A22: 10 | B22: ='INPUT DATA'!L20 -> NAVARRO, CHRISTIAN O. | P22: =IF(COUNT($F22:$O22)=0,"",SUM($F22:$O22)) | Q22: =IFERROR(IF(P22="","",ROUND(P22/$P$11*100,2)),"") | R22: =IFERROR(IF(Q22="","",ROUND(Q22*$R$11,2)),"") | AC22: =IF(COUNT($S22:$AB22)=0,"",SUM($S22:$AB22)) | AD22: =IFERROR(IF(AC22="","",ROUND(AC22/$AC$11*100,2)),"") | AE22: =IFERROR(IF(AD22="","",ROUND(AD22*$AE$11,2)),"") | AG22: =IFERROR(IF(AF22="","",ROUND(AF22/$AF$11*100,2)),"") | AH22: =IFERROR(IF(AG22="","",ROUND(AG22*$AH$11,2)),"") | AI22: =IFERROR(R22+AE22+AH22,"") | AJ22: =IFERROR(VLOOKUP(AI22,'Helper(IMPORTANT!)'!$CQ$1:$CR$41,2,TRUE),"")
A23: 11 | B23: ='INPUT DATA'!L21 -> PANGANIBAN, VINCENT H. | P23: =IF(COUNT($F23:$O23)=0,"",SUM($F23:$O23)) | Q23: =IFERROR(IF(P23="","",ROUND(P23/$P$11*100,2)),"") | R23: =IFERROR(IF(Q23="","",ROUND(Q23*$R$11,2)),"") | AC23: =IF(COUNT($S23:$AB23)=0,"",SUM($S23:$AB23)) | AD23: =IFERROR(IF(AC23="","",ROUND(AC23/$AC$11*100,2)),"") | AE23: =IFERROR(IF(AD23="","",ROUND(AD23*$AE$11,2)),"") | AG23: =IFERROR(IF(AF23="","",ROUND(AF23/$AF$11*100,2)),"") | AH23: =IFERROR(IF(AG23="","",ROUND(AG23*$AH$11,2)),"") | AI23: =IFERROR(R23+AE23+AH23,"") | AJ23: =IFERROR(VLOOKUP(AI23,'Helper(IMPORTANT!)'!$CQ$1:$CR$41,2,TRUE),"")
A24: 12 | B24: ='INPUT DATA'!L22 -> REYES, CEDRIC I. | P24: =IF(COUNT($F24:$O24)=0,"",SUM($F24:$O24)) | Q24: =IFERROR(IF(P24="","",ROUND(P24/$P$11*100,2)),"") | R24: =IFERROR(IF(Q24="","",ROUND(Q24*$R$11,2)),"") | AC24: =IF(COUNT($S24:$AB24)=0,"",SUM($S24:$AB24)) | AD24: =IFERROR(IF(AC24="","",ROUND(AC24/$AC$11*100,2)),"") | AE24: =IFERROR(IF(AD24="","",ROUND(AD24*$AE$11,2)),"") | AG24: =IFERROR(IF(AF24="","",ROUND(AF24/$AF$11*100,2)),"") | AH24: =IFERROR(IF(AG24="","",ROUND(AG24*$AH$11,2)),"") | AI24: =IFERROR(R24+AE24+AH24,"") | AJ24: =IFERROR(VLOOKUP(AI24,'Helper(IMPORTANT!)'!$CQ$1:$CR$41,2,TRUE),"")
... A62: 50 | B62: ='INPUT DATA'!L60 -> 0 | P62: =IF(COUNT($F62:$O62)=0,"",SUM($F62:$O62)) | Q62: =IFERROR(IF(P62="","",ROUND(P62/$P$11*100,2)),"") | R62: =IFERROR(IF(Q62="","",ROUND(Q62*$R$11,2)),"") | AC62: =IF(COUNT($S62:$AB62)=0,"",SUM($S62:$AB62)) | AD62: =IFERROR(IF(AC62="","",ROUND(AC62/$AC$11*100,2)),"") | AE62: =IFERROR(IF(AD62="","",ROUND(AD62*$AE$11,2)),"") | AG62: =IFERROR(IF(AF62="","",ROUND(AF62/$AF$11*100,2)),"") | AH62: =IFERROR(IF(AG62="","",ROUND(AG62*$AH$11,2)),"") | AI62: =IFERROR(R62+AE62+AH62,"") | AJ62: =IFERROR(VLOOKUP(AI62,'Helper(IMPORTANT!)'!$CQ$1:$CR$41,2,TRUE),"")
A63: FEMALE
A64: 1 | B64: ='INPUT DATA'!O11 -> BASCO, FAITH U. | P64: =IF(COUNT($F64:$O64)=0,"",SUM($F64:$O64)) | Q64: =IFERROR(IF(P64="","",ROUND(P64/$P$11*100,2)),"") | R64: =IFERROR(IF(Q64="","",ROUND(Q64*$R$11,2)),"") | AC64: =IF(COUNT($S64:$AB64)=0,"",SUM($S64:$AB64)) | AD64: =IFERROR(IF(AC64="","",ROUND(AC64/$AC$11*100,2)),"") | AE64: =IFERROR(IF(AD64="","",ROUND(AD64*$AE$11,2)),"") | AG64: =IFERROR(IF(AF64="","",ROUND(AF64/$AF$11*100,2)),"") | AH64: =IFERROR(IF(AG64="","",ROUND(AG64*$AH$11,2)),"") | AI64: =IFERROR(R64+AE64+AH64,"") | AJ64: =IFERROR(VLOOKUP(AI64,'Helper(IMPORTANT!)'!$CQ$1:$CR$41,2,TRUE),"")
A65: 2 | B65: ='INPUT DATA'!O12 -> BAUTISTA, MAE J. | P65: =IF(COUNT($F65:$O65)=0,"",SUM($F65:$O65)) | Q65: =IFERROR(IF(P65="","",ROUND(P65/$P$11*100,2)),"") | R65: =IFERROR(IF(Q65="","",ROUND(Q65*$R$11,2)),"") | AC65: =IF(COUNT($S65:$AB65)=0,"",SUM($S65:$AB65)) | AD65: =IFERROR(IF(AC65="","",ROUND(AC65/$AC$11*100,2)),"") | AE65: =IFERROR(IF(AD65="","",ROUND(AD65*$AE$11,2)),"") | AG65: =IFERROR(IF(AF65="","",ROUND(AF65/$AF$11*100,2)),"") | AH65: =IFERROR(IF(AG65="","",ROUND(AG65*$AH$11,2)),"") | AI65: =IFERROR(R65+AE65+AH65,"") | AJ65: =IFERROR(VLOOKUP(AI65,'Helper(IMPORTANT!)'!$CQ$1:$CR$41,2,TRUE),"")
A66: 3 | B66: ='INPUT DATA'!O13 -> CABRERA, RHEA Q. | P66: =IF(COUNT($F66:$O66)=0,"",SUM($F66:$O66)) | Q66: =IFERROR(IF(P66="","",ROUND(P66/$P$11*100,2)),"") | R66: =IFERROR(IF(Q66="","",ROUND(Q66*$R$11,2)),"") | AC66: =IF(COUNT($S66:$AB66)=0,"",SUM($S66:$AB66)) | AD66: =IFERROR(IF(AC66="","",ROUND(AC66/$AC$11*100,2)),"") | AE66: =IFERROR(IF(AD66="","",ROUND(AD66*$AE$11,2)),"") | AG66: =IFERROR(IF(AF66="","",ROUND(AF66/$AF$11*100,2)),"") | AH66: =IFERROR(IF(AG66="","",ROUND(AG66*$AH$11,2)),"") | AI66: =IFERROR(R66+AE66+AH66,"") | AJ66: =IFERROR(VLOOKUP(AI66,'Helper(IMPORTANT!)'!$CQ$1:$CR$41,2,TRUE),"")
